Workbook
Name ComponentIDs: 'Bausteine'!$A$2:$A$33

Sheet Hinweise
A1: YMCA Modular – Kalibrierung
A2: Referenz | B2: Quellblock-Abgleich: 9d8a9dec (integrierter Game-Stand), siehe reference-audit.md.
A3: Status | B3: Experimentelle Zahlen; keine Spielregeln oder grafische/volle Verhaltensgleichheit.
A4: Eingaben | B4: Parameter und Bausteinwerte sind editierbar. Formeln berechnen Entwuerfe/Vergleich beim Öffnen neu.
A5: Preise | B5: Hardwarekosten minus CP-Anforderung mal globaler CP-Creditwert. Keine Sonderrabatte.
A6: Massenproduktion | B6: Entwuerfe nutzen noch die günstigere Chassisvariante. Prozentfertigung wird nur im Preisfit untersucht.
A7: Arbeitsfluss | B7: catalog.json ist Quelle. export_excel.py erzeugt eine neue Momentaufnahme, kein Excel-Import.
A8: Schutz | B8: Exporter überschreibt keine bestehende Arbeitsmappe; für neue Daten neuen Dateinamen verwenden.
A9: Erweiterung | B9: Neue Bausteine/Designs in JSON eintragen und neu exportieren. Manuelles Zeilenanfügen wird nicht automatisch verdrahtet.
A10: Validierung | B10: Excel prüft nur elektrische/physische Grenzen; Rolle, Fraktion und Montage weiterhin im Python-Rechner prüfen.
A11: Momentaufnahme | B11: Python-Werte und Preisfit sind statisch. Änderungen in Excel aktualisieren nur die Formelspalten.
A12: Genauigkeit | B12: CP/Tier sind unabhängig; 1% Abweichung kann akzeptabel sein. Preisfit ist kein Beweis des CP-Wertes.
A13: Branches | B13: Game modular: tournament-bot integriert in 9d8a9dec; master nicht zusätzlich gemergt.
... A15: Referenzbedingungen | B15: Base states without isotope stability, horde, uranium or veterancy bonuses. Isotope stability now applies 90% received damage as well as death-explosion suppression; not modeled as extra HP.

Sheet Parameter
A1: Parameter | B1: Wert
A2: Credits pro CP | B2: 300
A3: Geschwindigkeitsexponent | B3: 0.5
A4: Katalogbudget | B4: 50

Sheet Bausteine
A1: ID | B1: Rolle | C1: Fraktionen | D1: Katalog-Tier | E1: CP | F1: Tech | G1: Hardwarepreis | H1: Masse kg | I1: Bedarf kWe | J1: Motor kWm | K1: Generator Wirkungsgrad | L1: Generator max kWe | M1: HP Chassis | N1: Panzerung | O1: Chassis Masse % | P1: Chassis HP % | Q1: Chassis Preis % | R1: Referenzmasse kg | S1: Referenzleistung kWm | T1: Referenztempo | U1: Max Tempo | V1: Max Masse kg | W1: Waffentraegerplaetze | X1: Zusatzplaetze | Y1: Salve | Z1: Schussabstand Ticks | AA1: Nachladen Ticks | AB1: Reichweite Zellen | AC1: Rohschaden | AD1: Hinweis | AE1: Quelle | AF1: Kompatibilitaet | AG1: Ausrüstung erlaubt | AH1: Waffen erlaubt | AI1: Munition erlaubt
A2: battlemaster | B2: chassis | C2: ["china"] | D2: 1 | E2: 0 | F2: 1 | G2: 500 | H2: 8000 | I2: 10 | J2: 0 | K2: 0 | L2: 0 | M2: 40000 | O2: 0 | P2: 0 | Q2: 0 | R2: 10000 | S2: 460 | T2: 100 | U2: 125 | V2: 18000 | W2: 1 | X2: 1 | Y2: 0 | Z2: 0 | AA2: 0 | AB2: 0 | AC2: 0 | AF2: {"carrier": ["cannon-turret", "autoloader-turret"], "drive": ["diesel", "diesel-large", "nuclear"]} | AG2: ["pdl"]
A3: battlemaster-mass-produced | B3: chassis | C3: ["china"] | D3: 1 | E3: 1 | F3: 1 | G3: 450 | H3: 8000 | I3: 10 | J3: 0 | K3: 0 | L3: 0 | M3: 40000 | O3: 0 | P3: 0 | Q3: 0 | R3: 10000 | S3: 460 | T3: 100 | U3: 125 | V3: 18000 | W3: 1 | X3: 1 | Y3: 0 | Z3: 0 | AA3: 0 | AB3: 0 | AC3: 0 | AD3: Experimental manufacturing variant of same chassis. 50-credit hardware saving plus global 300/CP fits base 600. No discount to other components. Reuses Battlemaster artwork; not a new physical chassis. | AF3: {"carrier": ["cannon-turret", "autoloader-turret"], "drive": ["diesel", "diesel-large", "nuclear"]} | AG3: ["pdl"]
A4: dragon-chassis | B4: chassis | C4: ["china"] | D4: 1 | E4: 0 | F4: 1 | G4: 250 | H4: 6500 | I4: 10 | J4: 0 | K4: 0 | L4: 0 | M4: 28000 | O4: 0 | P4: 0 | Q4: 0 | R4: 8000 | S4: 460 | T4: 103 | U4: 125 | V4: 14000 | W4: 1 | X4: 1 | Y4: 0 | Z4: 0 | AA4: 0 | AB4: 0 | AC4: 0 | AD4: Base price/HP/speed fitted. Firewall deploy behavior and Black Napalm remain source references, not implemented. | AE4: chdragon | AF4: {"carrier": ["flame-turret"], "drive": ["diesel", "diesel-large"]} | AG4: ["pdl"]
A5: gatling-chassis | B5: chassis | C5: ["china"] | D5: 1 | E5: 0 | F5: 1 | G5: 350 | H5: 7000 | I5: 10 | J5: 0 | K5: 0 | L5: 0 | M5: 30000 | O5: 0 | P5: 0 | Q5: 0 | R5: 9000 | S5: 460 | T5: 108 | U5: 130 | V5: 16000 | W5: 1 | X5: 1 | Y5: 0 | Z5: 0 | AA5: 0 | AB5: 0 | AC5: 0 | AD5: Legacy sight override 6c0; preserve as audit metadata, not a claim of standard sight equivalence. AA/ground spool-up not simulated. | AE5: chgtnk | AF5: {"carrier": ["gatling-turret"], "drive": ["diesel", "diesel-large"]} | AG5: ["pdl"]
A6: flame-turret | B6: carrier | C6: ["china"] | D6: 0 | E6: 0 | F6: 1 | G6: 75 | H6: 400 | I6: 0 | J6: 0 | K6: 0 | L6: 0 | M6: 0 | O6: 0 | P6: 0 | Q6: 0 | R6: 0 | S6: 0 | T6: 0 | U6: 0 | V6: 0 | W6: 0 | X6: 0 | Y6: 8 | Z6: 4 | AA6: 45 | AB6: 0 | AC6: 0 | AD6: Normal attack only; deployed Firewall has additional armaments and state changes. | AE6: CHDragonFlamer | AH6: ["dragon-flamer"]
A7: dragon-flamer | B7: weapon | C7: ["china"] | D7: 0 | E7: 0 | F7: 1 | G7: 125 | H7: 400 | I7: 0 | J7: 0 | K7: 0 | L7: 0 | M7: 0 | O7: 0 | P7: 0 | Q7: 0 | R7: 0 | S7: 0 | T7: 0 | U7: 0 | V7: 0 | W7: 0 | X7: 0 | Y7: 0 | Z7: 0 | AA7: 0 | AB7: 5 | AC7: 0 | AE7: CHDragonFlamer | AI7: ["flame-fuel"]
A8: flame-fuel | B8: ammunition | C8: ["china"] | D8: 0 | E8: 0 | F8: 1 | G8: 50 | H8: 100 | I8: 0 | J8: 0 | K8: 0 | L8: 0 | M8: 0 | O8: 0 | P8: 0 | Q8: 0 | R8: 0 | S8: 0 | T8: 0 | U8: 0 | V8: 0 | W8: 0 | X8: 0 | Y8: 0 | Z8: 0 | AA8: 0 | AB8: 0 | AC8: 2500 | AD8: Raw primary warhead only; fire clusters, heat and garrison damage omitted from calculator.
A9: gatling-turret | B9: carrier | C9: ["china"] | D9: 0 | E9: 0 | F9: 1 | G9: 100 | H9: 500 | I9: 0 | J9: 0 | K9: 0 | L9: 0 | M9: 0 | O9: 0 | P9: 0 | Q9: 0 | R9: 0 | S9: 0 | T9: 0 | U9: 0 | V9: 0 | W9: 0 | X9: 0 | Y9: 1 | Z9: 0 | AA9: 12 | AB9: 0 | AC9: 0 | AD9: Ground cold-state representative only. Reload stages 12/8/4/2 ticks, separate air/ground charge, thresholds 1/3/5, reset delay 40. Full attack-state behavior not modeled. | AE9: ^ChinaGatling | AH9: ["gatling-gun"]
A10: gatling-gun | B10: weapon | C10: ["china"] | D10: 0 | E10: 0 | F10: 1 | G10: 150 | H10: 500 | I10: 0 | J10: 0 | K10: 0 | L10: 0 | M10: 0 | O10: 0 | P10: 0 | Q10: 0 | R10: 0 | S10: 0 | T10: 0 | U10: 0 | V10: 0 | W10: 0 | X10: 0 | Y10: 0 | Z10: 0 | AA10: 0 | AB10: 6 | AC10: 0 | AD10: Ground range 6 cells; AA uses ChinaMGatt.0 with range 9.5. Not a single fixed weapon. | AE10: ChinaMGatt.0G | AI10: ["gatling-rounds"]
A11: gatling-rounds | B11: ammunition | C11: ["china"] | D11: 0 | E11: 0 | F11: 1 | G11: 100 | H11: 400 | I11: 0 | J11: 0 | K11: 0 | L11: 0 | M11: 0 | O11: 0 | P11: 0 | Q11: 0 | R11: 0 | S11: 0 | T11: 0 | U11: 0 | V11: 0 | W11: 0 | X11: 0 | Y11: 0 | Z11: 0 | AA11: 0 | AB11: 0 | AC11: 350 | AD11: Raw ground damage 350; AA raw damage 660. Values are not DPS.
A12: juggernaut | B12: chassis | C12: ["gdi"] | D12: 3 | E12: 0 | F12: 3 | G12: 1100 | H12: 16000 | I12: 10 | J12: 0 | K12: 0 | L12: 0 | M12: 60000 | O12: 0 | P12: 0 | Q12: 0 | R12: 20000 | S12: 460 | T12: 50 | U12: 50 | V12: 30000 | W12: 1 | X12: 3 | Y12: 0 | Z12: 0 | AA12: 0 | AB12: 0 | AC12: 0 | AF12: {"carrier": ["fixed-triple"], "drive": ["diesel"]} | AG12: []
A13: heavy-tesla | B13: chassis | C13: ["soviet"] | D13: 2 | E13: 0 | F13: 2 | G13: 600 | H13: 8000 | I13: 10 | J13: 0 | K13: 0 | L13: 0 | M13: 48000 | O13: 0 | P13: 0 | Q13: 0 | R13: 10000 | S13: 260 | T13: 100 | U13: 110 | V13: 18000 | W13: 1 | X13: 2 | Y13: 0 | Z13: 0 | AA13: 0 | AB13: 0 | AC13: 0 | AF13: {"carrier": ["twin-coil"], "drive": ["diesel", "nuclear"]} | AG13: []
A14: diesel | B14: drive | C14: ["china", "gdi", "soviet"] | D14: 0 | E14: 0 | F14: 1 | G14: 100 | H14: 600 | I14: 0 | J14: 500 | K14: 0 | L14: 0 | M14: 0 | O14: 0 | P14: 0 | Q14: 0 | R14: 0 | S14: 0 | T14: 0 | U14: 0 | V14: 0 | W14: 0 | X14: 0 | Y14: 0 | Z14: 0 | AA14: 0 | AB14: 0 | AC14: 0
A15: diesel-large | B15: drive | C15: ["china", "gdi", "soviet"] | D15: 1 | E15: 0 | F15: 2 | G15: 200 | H15: 600 | I15: 0 | J15: 550 | K15: 0 | L15: 0 | M15: 0 | O15: 0 | P15: 0 | Q15: 0 | R15: 0 | S15: 0 | T15: 0 | U15: 0 | V15: 0 | W15: 0 | X15: 0 | Y15: 0 | Z15: 0 | AA15: 0 | AB15: 0 | AC15: 0
A16: nuclear | B16: drive | C16: ["china", "soviet"] | D16: 1 | E16: 1 | F16: 2 | G16: 400 | H16: 600 | I16: 0 | J16: 758.75 | K16: 0 | L16: 0 | M16: 0 | O16: 0 | P16: 0 | Q16: 0 | R16: 0 | S16: 0 | T16: 0 | U16: 0 | V16: 0 | W16: 0 | X16: 0 | Y16: 0 | Z16: 0 | AA16: 0 | AB16: 0 | AC16: 0
A17: baseline-generator | B17: generator | C17: ["china", "gdi", "soviet"] | D17: 0 | E17: 0 | F17: 1 | G17: 0 | H17: 0 | I17: 0 | J17: 0 | K17: 0.25 | L17: 100 | M17: 0 | O17: 0 | P17: 0 | Q17: 0 | R17: 0 | S17: 0 | T17: 0 | U17: 0 | V17: 0 | W17: 0 | X17: 0 | Y17: 0 | Z17: 0 | AA17: 0 | AB17: 0 | AC17: 0
A18: efficient-generator | B18: generator | C18: ["china", "gdi", "soviet"] | D18: 1 | E18: 0 | F18: 2 | G18: 200 | H18: 0 | I18: 0 | J18: 0 | K18: 0.75 | L18: 120 | M18: 0 | O18: 0 | P18: 0 | Q18: 0 | R18: 0 | S18: 0 | T18: 0 | U18: 0 | V18: 0 | W18: 0 | X18: 0 | Y18: 0 | Z18: 0 | AA18: 0 | AB18: 0 | AC18: 0
A19: heavy | B19: armor | C19: ["china", "gdi", "soviet"] | D19: 0 | E19: 0 | F19: 1 | G19: 0 | H19: 0 | I19: 0 | J19: 0 | K19: 0 | L19: 0 | M19: 0 | N19: Heavy | O19: 100 | P19: 100 | Q19: 100 | R19: 0 | S19: 0 | T19: 0 | U19: 0 | V19: 0 | W19: 0 | X19: 0 | Y19: 0 | Z19: 0 | AA19: 0 | AB19: 0 | AC19: 0
A20: reflector | B20: armor | C20: ["china", "gdi", "soviet"] | D20: 1 | E20: 1 | F20: 3 | G20: 0 | H20: 0 | I20: 57.5 | J20: 0 | K20: 0 | L20: 0 | M20: 0 | N20: Reflector | O20: 100 | P20: 100 | Q20: 100 | R20: 0 | S20: 0 | T20: 0 | U20: 0 | V20: 0 | W20: 0 | X20: 0 | Y20: 0 | Z20: 0 | AA20: 0 | AB20: 0 | AC20: 0
A21: cannon-turret | B21: carrier | C21: ["china"] | D21: 0 | E21: 0 | F21: 1 | G21: 100 | H21: 500 | I21: 0 | J21: 0 | K21: 0 | L21: 0 | M21: 0 | O21: 0 | P21: 0 | Q21: 0 | R21: 0 | S21: 0 | T21: 0 | U21: 0 | V21: 0 | W21: 0 | X21: 0 | Y21: 1 | Z21: 0 | AA21: 50 | AB21: 0 | AC21: 0 | AH21: ["cannon"]
A22: autoloader-turret | B22: carrier | C22: ["china"] | D22: 1 | E22: 1 | F22: 1 | G22: 400 | H22: 500 | I22: 0 | J22: 0 | K22: 0 | L22: 0 | M22: 0 | O22: 0 | P22: 0 | Q22: 0 | R22: 0 | S22: 0 | T22: 0 | U22: 0 | V22: 0 | W22: 0 | X22: 0 | Y22: 3 | Z22: 5 | AA22: 50 | AB22: 0 | AC22: 0 | AD22: Same visible single barrel. Autoloading mechanism changes firing cycle, not barrel count. Baseline mount mass retained; hardware price includes autoloader. Global CP credit value applies. | AE22: CHBattlemasterCannon.Autoloader | AH22: ["cannon"]
A23: fixed-triple | B23: carrier | C23: ["gdi"] | D23: 0 | E23: 0 | F23: 3 | G23: 300 | H23: 1500 | I23: 0 | J23: 0 | K23: 0 | L23: 0 | M23: 0 | O23: 0 | P23: 0 | Q23: 0 | R23: 0 | S23: 0 | T23: 0 | U23: 0 | V23: 0 | W23: 0 | X23: 0 | Y23: 3 | Z23: 1 | AA23: 100 | AB23: 0 | AC23: 0 | AH23: ["artillery"]
A24: twin-coil | B24: carrier | C24: ["soviet"] | D24: 0 | E24: 0 | F24: 2 | G24: 200 | H24: 500 | I24: 0 | J24: 0 | K24: 0 | L24: 0 | M24: 0 | O24: 0 | P24: 0 | Q24: 0 | R24: 0 | S24: 0 | T24: 0 | U24: 0 | V24: 0 | W24: 0 | X24: 0 | Y24: 2 | Z24: 1 | AA24: 100 | AB24: 0 | AC24: 0 | AH24: ["tesla"]
A25: cannon | B25: weapon | C25: ["china"] | D25: 0 | E25: 0 | F25: 1 | G25: 200 | H25: 500 | I25: 0 | J25: 0 | K25: 0 | L25: 0 | M25: 0 | O25: 0 | P25: 0 | Q25: 0 | R25: 0 | S25: 0 | T25: 0 | U25: 0 | V25: 0 | W25: 0 | X25: 0 | Y25: 0 | Z25: 0 | AA25: 0 | AB25: 4 | AC25: 0 | AE25: CHBattlemasterCannon | AI25: ["shell", "nuclear-shell"]
A26: artillery | B26: weapon | C26: ["gdi"] | D26: 0 | E26: 0 | F26: 3 | G26: 300 | H26: 900 | I26: 0 | J26: 0 | K26: 0 | L26: 0 | M26: 0 | O26: 0 | P26: 0 | Q26: 0 | R26: 0 | S26: 0 | T26: 0 | U26: 0 | V26: 0 | W26: 0 | X26: 0 | Y26: 0 | Z26: 0 | AA26: 0 | AB26: 0 | AC26: 0 | AE26: JuggernautGun | AI26: ["artillery-shell", "emp-shell"]
A27: tesla | B27: weapon | C27: ["soviet"] | D27: 1 | E27: 0 | F27: 2 | G27: 350 | H27: 700 | I27: 50 | J27: 0 | K27: 0 | L27: 0 | M27: 0 | O27: 0 | P27: 0 | Q27: 0 | R27: 0 | S27: 0 | T27: 0 | U27: 0 | V27: 0 | W27: 0 | X27: 0 | Y27: 0 | Z27: 0 | AA27: 0 | AB27: 0 | AC27: 0 | AE27: TTankZapMK2 | AI27: ["discharge"]
A28: shell | B28: ammunition | C28: ["china"] | D28: 0 | E28: 0 | F28: 1 | G28: 50 | H28: 400 | I28: 0 | J28: 0 | K28: 0 | L28: 0 | M28: 0 | O28: 0 | P28: 0 | Q28: 0 | R28: 0 | S28: 0 | T28: 0 | U28: 0 | V28: 0 | W28: 0 | X28: 0 | Y28: 0 | Z28: 0 | AA28: 0 | AB28: 0 | AC28: 5000
A29: nuclear-shell | B29: ammunition | C29: ["china"] | D29: 1 | E29: 1 | F29: 1 | G29: 350 | H29: 400 | I29: 0 | J29: 0 | K29: 0 | L29: 0 | M29: 0 | O29: 0 | P29: 0 | Q29: 0 | R29: 0 | S29: 0 | T29: 0 | U29: 0 | V29: 0 | W29: 0 | X29: 0 | Y29: 0 | Z29: 0 | AA29: 0 | AB29: 0 | AC29: 10000 | AD29: First fit: same mass, no additional electric load; +300 hardware offsets 1 CP. Radiation, falloff and recoil need engine composition, not just damage copying. | AE29: CHBattlemasterCannon.Nuclear_Shells
A30: artillery-shell | B30: ammunition | C30: ["gdi"] | D30: 0 | E30: 0 | F30: 3 | G30: 200 | H30: 1000 | I30: 0 | J30: 0 | K30: 0 | L30: 0 | M30: 0 | O30: 0 | P30: 0 | Q30: 0 | R30: 0 | S30: 0 | T30: 0 | U30: 0 | V30: 0 | W30: 0 | X30: 0 | Y30: 0 | Z30: 0 | AA30: 0 | AB30: 0 | AC30: 0
A31: emp-shell | B31: ammunition | C31: ["gdi"] | D31: 1 | E31: 1 | F31: 3 | G31: 300 | H31: 1000 | I31: 20 | J31: 0 | K31: 0 | L31: 0 | M31: 0 | O31: 0 | P31: 0 | Q31: 0 | R31: 0 | S31: 0 | T31: 0 | U31: 0 | V31: 0 | W31: 0 | X31: 0 | Y31: 0 | Z31: 0 | AA31: 0 | AB31: 0 | AC31: 0 | AE31: JuggernautGun.Emp
A32: discharge | B32: ammunition | C32: ["soviet"] | D32: 0 | E32: 0 | F32: 2 | G32: 100 | H32: 200 | I32: 0 | J32: 0 | K32: 0 | L32: 0 | M32: 0 | O32: 0 | P32: 0 | Q32: 0 | R32: 0 | S32: 0 | T32: 0 | U32: 0 | V32: 0 | W32: 0 | X32: 0 | Y32: 0 | Z32: 0 | AA32: 0 | AB32: 0 | AC32: 0 | AD32: Fixed payload-package mass, not physical shells; no duplicate Tesla electrical charge.
A33: pdl | B33: equipment | C33: ["china"] | D33: 1 | E33: 1 | F33: 3 | G33: 650 | H33: 300 | I33: 47 | J33: 0 | K33: 0 | L33: 0 | M33: 0 | O33: 0 | P33: 0 | Q33: 0 | R33: 0 | S33: 0 | T33: 0 | U33: 0 | V33: 0 | W33: 0 | X33: 0 | Y33: 0 | Z33: 0 | AA33: 0 | AB33: 0 | AC33: 0 | AE33: ^PointLaserDefenseSystem

Sheet Entwuerfe
A1: Design | B1: Fraktion | C1: Chassis | D1: Motor | E1: Generator | F1: Panzerung | G1: Traeger | H1: Waffe | I1: Munition | J1: Zusatz 1 | K1: Zusatz 2 | L1: Zusatz 3 | M1: Katalog | N1: CP | O1: Tech | P1: Hardware | Q1: CP-Abzug | R1: Preis | S1: HP | T1: Masse kg | U1: Last kWe | V1: Rest kWm | W1: Tempo | X1: Armor | Y1: Grenzen | Z1: Python Preis | AA1: Python Tempo | AB1: Referenzhinweis
A2: Dragon Tank | B2: china | C2: dragon-chassis | D2: diesel | E2: baseline-generator | F2: heavy | G2: flame-turret | H2: dragon-flamer | I2: flame-fuel | M2: =IF(C2="",0,VLOOKUP(C2,Bausteine!$A$2:$AI$33,4,FALSE))+IF(D2="",0,VLOOKUP(D2,Bausteine!$A$2:$AI$33,4,FALSE))+IF(E2="",0,VLOOKUP(E2,Bausteine!$A$2:$AI$33,4,FALSE))+IF(F2="",0,VLOOKUP(F2,Bausteine!$A$2:$AI$33,4,FALSE))+IF(G2="",0,VLOOKUP(G2,Bausteine!$A$2:$AI$33,4,FALSE))+IF(H2="",0,VLOOKUP(H2,Bausteine!$A$2:$AI$33,4,FALSE))+IF(I2="",0,VLOOKUP(I2,Bausteine!$A$2:$AI$33,4,FALSE))+IF(J2="",0,VLOOKUP(J2,Bausteine!$A$2:$AI$33,4,FALSE))+IF(K2="",0,VLOOKUP(K2,Bausteine!$A$2:$AI$33,4,FALSE))+IF(L2="",0,VLOOKUP(L2,Bausteine!$A$2:$AI$33,4,FALSE)) | N2: =IF(C2="",0,VLOOKUP(C2,Bausteine!$A$2:$AI$33,5,FALSE))+IF(D2="",0,VLOOKUP(D2,Bausteine!$A$2:$AI$33,5,FALSE))+IF(E2="",0,VLOOKUP(E2,Bausteine!$A$2:$AI$33,5,FALSE))+IF(F2="",0,VLOOKUP(F2,Bausteine!$A$2:$AI$33,5,FALSE))+IF(G2="",0,VLOOKUP(G2,Bausteine!$A$2:$AI$33,5,FALSE))+IF(H2="",0,VLOOKUP(H2,Bausteine!$A$2:$AI$33,5,FALSE))+IF(I2="",0,VLOOKUP(I2,Bausteine!$A$2:$AI$33,5,FALSE))+IF(J2="",0,VLOOKUP(J2,Bausteine!$A$2:$AI$33,5,FALSE))+IF(K2="",0,VLOOKUP(K2,Bausteine!$A$2:$AI$33,5,FALSE))+IF(L2="",0,VLOOKUP(L2,Bausteine!$A$2:$AI$33,5,FALSE)) | O2: =MAX(IF(C2="",0,VLOOKUP(C2,Bausteine!$A$2:$AI$33,6,FALSE)),IF(D2="",0,VLOOKUP(D2,Bausteine!$A$2:$AI$33,6,FALSE)),IF(E2="",0,VLOOKUP(E2,Bausteine!$A$2:$AI$33,6,FALSE)),IF(F2="",0,VLOOKUP(F2,Bausteine!$A$2:$AI$33,6,FALSE)),IF(G2="",0,VLOOKUP(G2,Bausteine!$A$2:$AI$33,6,FALSE)),IF(H2="",0,VLOOKUP(H2,Bausteine!$A$2:$AI$33,6,FALSE)),IF(I2="",0,VLOOKUP(I2,Bausteine!$A$2:$AI$33,6,FALSE)),IF(J2="",0,VLOOKUP(J2,Bausteine!$A$2:$AI$33,6,FALSE)),IF(K2="",0,VLOOKUP(K2,Bausteine!$A$2:$AI$33,6,FALSE)),IF(L2="",0,VLOOKUP(L2,Bausteine!$A$2:$AI$33,6,FALSE))) | P2: =IF(C2="",0,VLOOKUP(C2,Bausteine!$A$2:$AI$33,7,FALSE))*IF(F2="",0,VLOOKUP(F2,Bausteine!$A$2:$AI$33,17,FALSE))/100+IF(D2="",0,VLOOKUP(D2,Bausteine!$A$2:$AI$33,7,FALSE))+IF(E2="",0,VLOOKUP(E2,Bausteine!$A$2:$AI$33,7,FALSE))+IF(G2="",0,VLOOKUP(G2,Bausteine!$A$2:$AI$33,7,FALSE))+IF(H2="",0,VLOOKUP(H2,Bausteine!$A$2:$AI$33,7,FALSE))+IF(I2="",0,VLOOKUP(I2,Bausteine!$A$2:$AI$33,7,FALSE))+IF(J2="",0,VLOOKUP(J2,Bausteine!$A$2:$AI$33,7,FALSE))+IF(K2="",0,VLOOKUP(K2,Bausteine!$A$2:$AI$33,7,FALSE))+IF(L2="",0,VLOOKUP(L2,Bausteine!$A$2:$AI$33,7,FALSE)) | Q2: =N2*Parameter!$B$2 | R2: =P2-Q2 | S2: =IF(C2="",0,VLOOKUP(C2,Bausteine!$A$2:$AI$33,13,FALSE))*IF(F2="",0,VLOOKUP(F2,Bausteine!$A$2:$AI$33,16,FALSE))/100 | T2: =IF(C2="",0,VLOOKUP(C2,Bausteine!$A$2:$AI$33,8,FALSE))*IF(F2="",0,VLOOKUP(F2,Bausteine!$A$2:$AI$33,15,FALSE))/100+IF(D2="",0,VLOOKUP(D2,Bausteine!$A$2:$AI$33,8,FALSE))+IF(E2="",0,VLOOKUP(E2,Bausteine!$A$2:$AI$33,8,FALSE))+IF(G2="",0,VLOOKUP(G2,Bausteine!$A$2:$AI$33,8,FALSE))+IF(H2="",0,VLOOKUP(H2,Bausteine!$A$2:$AI$33,8,FALSE))+IF(I2="",0,VLOOKUP(I2,Bausteine!$A$2:$AI$33,8,FALSE))+IF(J2="",0,VLOOKUP(J2,Bausteine!$A$2:$AI$33,8,FALSE))+IF(K2="",0,VLOOKUP(K2,Bausteine!$A$2:$AI$33,8,FALSE))+IF(L2="",0,VLOOKUP(L2,Bausteine!$A$2:$AI$33,8,FALSE)) | U2: =IF(C2="",0,VLOOKUP(C2,Bausteine!$A$2:$AI$33,9,FALSE))+IF(D2="",0,VLOOKUP(D2,Bausteine!$A$2:$AI$33,9,FALSE))+IF(E2="",0,VLOOKUP(E2,Bausteine!$A$2:$AI$33,9,FALSE))+IF(F2="",0,VLOOKUP(F2,Bausteine!$A$2:$AI$33,9,FALSE))+IF(G2="",0,VLOOKUP(G2,Bausteine!$A$2:$AI$33,9,FALSE))+IF(H2="",0,VLOOKUP(H2,Bausteine!$A$2:$AI$33,9,FALSE))+IF(I2="",0,VLOOKUP(I2,Bausteine!$A$2:$AI$33,9,FALSE))+IF(J2="",0,VLOOKUP(J2,Bausteine!$A$2:$AI$33,9,FALSE))+IF(K2="",0,VLOOKUP(K2,Bausteine!$A$2:$AI$33,9,FALSE))+IF(L2="",0,VLOOKUP(L2,Bausteine!$A$2:$AI$33,9,FALSE)) | V2: =IF(D2="",0,VLOOKUP(D2,Bausteine!$A$2:$AI$33,10,FALSE))-U2/IF(E2="",0,VLOOKUP(E2,Bausteine!$A$2:$AI$33,11,FALSE)) | W2: =IF(Y2<>"OK","",ROUND(MIN(IF(C2="",0,VLOOKUP(C2,Bausteine!$A$2:$AI$33,21,FALSE)),IF(C2="",0,VLOOKUP(C2,Bausteine!$A$2:$AI$33,20,FALSE))*(V2/T2/(IF(C2="",0,VLOOKUP(C2,Bausteine!$A$2:$AI$33,19,FALSE))/IF(C2="",0,VLOOKUP(C2,Bausteine!$A$2:$AI$33,18,FALSE))))^Parameter!$B$3),0)) | X2: =IF(F2="",0,VLOOKUP(F2,Bausteine!$A$2:$AI$33,14,FALSE)) | Y2: =IFERROR(IF(OR(R2<=0,T2<=0,V2<=0,U2>IF(E2="",0,VLOOKUP(E2,Bausteine!$A$2:$AI$33,12,FALSE)),T2>IF(C2="",0,VLOOKUP(C2,Bausteine!$A$2:$AI$33,22,FALSE)),IF(E2="",0,VLOOKUP(E2,Bausteine!$A$2:$AI$33,11,FALSE))<=0,IF(E2="",0,VLOOKUP(E2,Bausteine!$A$2:$AI$33,11,FALSE))>1),"UNGUELTIG","OK"),"FEHLER") | Z2: 600 | AA2: 103 | AB2: Normal non-deployed, no Black Napalm. Full Firewall behavior not modeled.
A3: Dragon Tank PDL | B3: china | C3: dragon-chassis | D3: diesel-large | E3: efficient-generator | F3: heavy | G3: flame-turret | H3: dragon-flamer | I3: flame-fuel | J3: pdl | M3: =IF(C3="",0,VLOOKUP(C3,Bausteine!$A$2:$AI$33,4,FALSE))+IF(D3="",0,VLOOKUP(D3,Bausteine!$A$2:$AI$33,4,FALSE))+IF(E3="",0,VLOOKUP(E3,Bausteine!$A$2:$AI$33,4,FALSE))+IF(F3="",0,VLOOKUP(F3,Bausteine!$A$2:$AI$33,4,FALSE))+IF(G3="",0,VLOOKUP(G3,Bausteine!$A$2:$AI$33,4,FALSE))+IF(H3="",0,VLOOKUP(H3,Bausteine!$A$2:$AI$33,4,FALSE))+IF(I3="",0,VLOOKUP(I3,Bausteine!$A$2:$AI$33,4,FALSE))+IF(J3="",0,VLOOKUP(J3,Bausteine!$A$2:$AI$33,4,FALSE))+IF(K3="",0,VLOOKUP(K3,Bausteine!$A$2:$AI$33,4,FALSE))+IF(L3="",0,VLOOKUP(L3,Bausteine!$A$2:$AI$33,4,FALSE)) | N3: =IF(C3="",0,VLOOKUP(C3,Bausteine!$A$2:$AI$33,5,FALSE))+IF(D3="",0,VLOOKUP(D3,Bausteine!$A$2:$AI$33,5,FALSE))+IF(E3="",0,VLOOKUP(E3,Bausteine!$A$2:$AI$33,5,FALSE))+IF(F3="",0,VLOOKUP(F3,Bausteine!$A$2:$AI$33,5,FALSE))+IF(G3="",0,VLOOKUP(G3,Bausteine!$A$2:$AI$33,5,FALSE))+IF(H3="",0,VLOOKUP(H3,Bausteine!$A$2:$AI$33,5,FALSE))+IF(I3="",0,VLOOKUP(I3,Bausteine!$A$2:$AI$33,5,FALSE))+IF(J3="",0,VLOOKUP(J3,Bausteine!$A$2:$AI$33,5,FALSE))+IF(K3="",0,VLOOKUP(K3,Bausteine!$A$2:$AI$33,5,FALSE))+IF(L3="",0,VLOOKUP(L3,Bausteine!$A$2:$AI$33,5,FALSE)) | O3: =MAX(IF(C3="",0,VLOOKUP(C3,Bausteine!$A$2:$AI$33,6,FALSE)),IF(D3="",0,VLOOKUP(D3,Bausteine!$A$2:$AI$33,6,FALSE)),IF(E3="",0,VLOOKUP(E3,Bausteine!$A$2:$AI$33,6,FALSE)),IF(F3="",0,VLOOKUP(F3,Bausteine!$A$2:$AI$33,6,FALSE)),IF(G3="",0,VLOOKUP(G3,Bausteine!$A$2:$AI$33,6,FALSE)),IF(H3="",0,VLOOKUP(H3,Bausteine!$A$2:$AI$33,6,FALSE)),IF(I3="",0,VLOOKUP(I3,Bausteine!$A$2:$AI$33,6,FALSE)),IF(J3="",0,VLOOKUP(J3,Bausteine!$A$2:$AI$33,6,FALSE)),IF(K3="",0,VLOOKUP(K3,Bausteine!$A$2:$AI$33,6,FALSE)),IF(L3="",0,VLOOKUP(L3,Bausteine!$A$2:$AI$33,6,FALSE))) | P3: =IF(C3="",0,VLOOKUP(C3,Bausteine!$A$2:$AI$33,7,FALSE))*IF(F3="",0,VLOOKUP(F3,Bausteine!$A$2:$AI$33,17,FALSE))/100+IF(D3="",0,VLOOKUP(D3,Bausteine!$A$2:$AI$33,7,FALSE))+IF(E3="",0,VLOOKUP(E3,Bausteine!$A$2:$AI$33,7,FALSE))+IF(G3="",0,VLOOKUP(G3,Bausteine!$A$2:$AI$33,7,FALSE))+IF(H3="",0,VLOOKUP(H3,Bausteine!$A$2:$AI$33,7,FALSE))+IF(I3="",0,VLOOKUP(I3,Bausteine!$A$2:$AI$33,7,FALSE))+IF(J3="",0,VLOOKUP(J3,Bausteine!$A$2:$AI$33,7,FALSE))+IF(K3="",0,VLOOKUP(K3,Bausteine!$A$2:$AI$33,7,FALSE))+IF(L3="",0,VLOOKUP(L3,Bausteine!$A$2:$AI$33,7,FALSE)) | Q3: =N3*Parameter!$B$2 | R3: =P3-Q3 | S3: =IF(C3="",0,VLOOKUP(C3,Bausteine!$A$2:$AI$33,13,FALSE))*IF(F3="",0,VLOOKUP(F3,Bausteine!$A$2:$AI$33,16,FALSE))/100 | T3: =IF(C3="",0,VLOOKUP(C3,Bausteine!$A$2:$AI$33,8,FALSE))*IF(F3="",0,VLOOKUP(F3,Bausteine!$A$2:$AI$33,15,FALSE))/100+IF(D3="",0,VLOOKUP(D3,Bausteine!$A$2:$AI$33,8,FALSE))+IF(E3="",0,VLOOKUP(E3,Bausteine!$A$2:$AI$33,8,FALSE))+IF(G3="",0,VLOOKUP(G3,Bausteine!$A$2:$AI$33,8,FALSE))+IF(H3="",0,VLOOKUP(H3,Bausteine!$A$2:$AI$33,8,FALSE))+IF(I3="",0,VLOOKUP(I3,Bausteine!$A$2:$AI$33,8,FALSE))+IF(J3="",0,VLOOKUP(J3,Bausteine!$A$2:$AI$33,8,FALSE))+IF(K3="",0,VLOOKUP(K3,Bausteine!$A$2:$AI$33,8,FALSE))+IF(L3="",0,VLOOKUP(L3,Bausteine!$A$2:$AI$33,8,FALSE)) | U3: =IF(C3="",0,VLOOKUP(C3,Bausteine!$A$2:$AI$33,9,FALSE))+IF(D3="",0,VLOOKUP(D3,Bausteine!$A$2:$AI$33,9,FALSE))+IF(E3="",0,VLOOKUP(E3,Bausteine!$A$2:$AI$33,9,FALSE))+IF(F3="",0,VLOOKUP(F3,Bausteine!$A$2:$AI$33,9,FALSE))+IF(G3="",0,VLOOKUP(G3,Bausteine!$A$2:$AI$33,9,FALSE))+IF(H3="",0,VLOOKUP(H3,Bausteine!$A$2:$AI$33,9,FALSE))+IF(I3="",0,VLOOKUP(I3,Bausteine!$A$2:$AI$33,9,FALSE))+IF(J3="",0,VLOOKUP(J3,Bausteine!$A$2:$AI$33,9,FALSE))+IF(K3="",0,VLOOKUP(K3,Bausteine!$A$2:$AI$33,9,FALSE))+IF(L3="",0,VLOOKUP(L3,Bausteine!$A$2:$AI$33,9,FALSE)) | V3: =IF(D3="",0,VLOOKUP(D3,Bausteine!$A$2:$AI$33,10,FALSE))-U3/IF(E3="",0,VLOOKUP(E3,Bausteine!$A$2:$AI$33,11,FALSE)) | W3: =IF(Y3<>"OK","",ROUND(MIN(IF(C3="",0,VLOOKUP(C3,Bausteine!$A$2:$AI$33,21,FALSE)),IF(C3="",0,VLOOKUP(C3,Bausteine!$A$2:$AI$33,20,FALSE))*(V3/T3/(IF(C3="",0,VLOOKUP(C3,Bausteine!$A$2:$AI$33,19,FALSE))/IF(C3="",0,VLOOKUP(C3,Bausteine!$A$2:$AI$33,18,FALSE))))^Parameter!$B$3),0)) | X3: =IF(F3="",0,VLOOKUP(F3,Bausteine!$A$2:$AI$33,14,FALSE)) | Y3: =IFERROR(IF(OR(R3<=0,T3<=0,V3<=0,U3>IF(E3="",0,VLOOKUP(E3,Bausteine!$A$2:$AI$33,12,FALSE)),T3>IF(C3="",0,VLOOKUP(C3,Bausteine!$A$2:$AI$33,22,FALSE)),IF(E3="",0,VLOOKUP(E3,Bausteine!$A$2:$AI$33,11,FALSE))<=0,IF(E3="",0,VLOOKUP(E3,Bausteine!$A$2:$AI$33,11,FALSE))>1),"UNGUELTIG","OK"),"FEHLER") | Z3: 1250 | AA3: 103 | AB3: Existing shared PDL package; no family-specific discount.
A4: Dragon Tank Reflector | B4: china | C4: dragon-chassis | D4: diesel-large | E4: efficient-generator | F4: reflector | G4: flame-turret | H4: dragon-flamer | I4: flame-fuel | M4: =IF(C4="",0,VLOOKUP(C4,Bausteine!$A$2:$AI$33,4,FALSE))+IF(D4="",0,VLOOKUP(D4,Bausteine!$A$2:$AI$33,4,FALSE))+IF(E4="",0,VLOOKUP(E4,Bausteine!$A$2:$AI$33,4,FALSE))+IF(F4="",0,VLOOKUP(F4,Bausteine!$A$2:$AI$33,4,FALSE))+IF(G4="",0,VLOOKUP(G4,Bausteine!$A$2:$AI$33,4,FALSE))+IF(H4="",0,VLOOKUP(H4,Bausteine!$A$2:$AI$33,4,FALSE))+IF(I4="",0,VLOOKUP(I4,Bausteine!$A$2:$AI$33,4,FALSE))+IF(J4="",0,VLOOKUP(J4,Bausteine!$A$2:$AI$33,4,FALSE))+IF(K4="",0,VLOOKUP(K4,Bausteine!$A$2:$AI$33,4,FALSE))+IF(L4="",0,VLOOKUP(L4,Bausteine!$A$2:$AI$33,4,FALSE)) | N4: =IF(C4="",0,VLOOKUP(C4,Bausteine!$A$2:$AI$33,5,FALSE))+IF(D4="",0,VLOOKUP(D4,Bausteine!$A$2:$AI$33,5,FALSE))+IF(E4="",0,VLOOKUP(E4,Bausteine!$A$2:$AI$33,5,FALSE))+IF(F4="",0,VLOOKUP(F4,Bausteine!$A$2:$AI$33,5,FALSE))+IF(G4="",0,VLOOKUP(G4,Bausteine!$A$2:$AI$33,5,FALSE))+IF(H4="",0,VLOOKUP(H4,Bausteine!$A$2:$AI$33,5,FALSE))+IF(I4="",0,VLOOKUP(I4,Bausteine!$A$2:$AI$33,5,FALSE))+IF(J4="",0,VLOOKUP(J4,Bausteine!$A$2:$AI$33,5,FALSE))+IF(K4="",0,VLOOKUP(K4,Bausteine!$A$2:$AI$33,5,FALSE))+IF(L4="",0,VLOOKUP(L4,Bausteine!$A$2:$AI$33,5,FALSE)) | O4: =MAX(IF(C4="",0,VLOOKUP(C4,Bausteine!$A$2:$AI$33,6,FALSE)),IF(D4="",0,VLOOKUP(D4,Bausteine!$A$2:$AI$33,6,FALSE)),IF(E4="",0,VLOOKUP(E4,Bausteine!$A$2:$AI$33,6,FALSE)),IF(F4="",0,VLOOKUP(F4,Bausteine!$A$2:$AI$33,6,FALSE)),IF(G4="",0,VLOOKUP(G4,Bausteine!$A$2:$AI$33,6,FALSE)),IF(H4="",0,VLOOKUP(H4,Bausteine!$A$2:$AI$33,6,FALSE)),IF(I4="",0,VLOOKUP(I4,Bausteine!$A$2:$AI$33,6,FALSE)),IF(J4="",0,VLOOKUP(J4,Bausteine!$A$2:$AI$33,6,FALSE)),IF(K4="",0,VLOOKUP(K4,Bausteine!$A$2:$AI$33,6,FALSE)),IF(L4="",0,VLOOKUP(L4,Bausteine!$A$2:$AI$33,6,FALSE))) | P4: =IF(C4="",0,VLOOKUP(C4,Bausteine!$A$2:$AI$33,7,FALSE))*IF(F4="",0,VLOOKUP(F4,Bausteine!$A$2:$AI$33,17,FALSE))/100+IF(D4="",0,VLOOKUP(D4,Bausteine!$A$2:$AI$33,7,FALSE))+IF(E4="",0,VLOOKUP(E4,Bausteine!$A$2:$AI$33,7,FALSE))+IF(G4="",0,VLOOKUP(G4,Bausteine!$A$2:$AI$33,7,FALSE))+IF(H4="",0,VLOOKUP(H4,Bausteine!$A$2:$AI$33,7,FALSE))+IF(I4="",0,VLOOKUP(I4,Bausteine!$A$2:$AI$33,7,FALSE))+IF(J4="",0,VLOOKUP(J4,Bausteine!$A$2:$AI$33,7,FALSE))+IF(K4="",0,VLOOKUP(K4,Bausteine!$A$2:$AI$33,7,FALSE))+IF(L4="",0,VLOOKUP(L4,Bausteine!$A$2:$AI$33,7,FALSE)) | Q4: =N4*Parameter!$B$2 | R4: =P4-Q4 | S4: =IF(C4="",0,VLOOKUP(C4,Bausteine!$A$2:$AI$33,13,FALSE))*IF(F4="",0,VLOOKUP(F4,Bausteine!$A$2:$AI$33,16,FALSE))/100 | T4: =IF(C4="",0,VLOOKUP(C4,Bausteine!$A$2:$AI$33,8,FALSE))*IF(F4="",0,VLOOKUP(F4,Bausteine!$A$2:$AI$33,15,FALSE))/100+IF(D4="",0,VLOOKUP(D4,Bausteine!$A$2:$AI$33,8,FALSE))+IF(E4="",0,VLOOKUP(E4,Bausteine!$A$2:$AI$33,8,FALSE))+IF(G4="",0,VLOOKUP(G4,Bausteine!$A$2:$AI$33,8,FALSE))+IF(H4="",0,VLOOKUP(H4,Bausteine!$A$2:$AI$33,8,FALSE))+IF(I4="",0,VLOOKUP(I4,Bausteine!$A$2:$AI$33,8,FALSE))+IF(J4="",0,VLOOKUP(J4,Bausteine!$A$2:$AI$33,8,FALSE))+IF(K4="",0,VLOOKUP(K4,Bausteine!$A$2:$AI$33,8,FALSE))+IF(L4="",0,VLOOKUP(L4,Bausteine!$A$2:$AI$33,8,FALSE)) | U4: =IF(C4="",0,VLOOKUP(C4,Bausteine!$A$2:$AI$33,9,FALSE))+IF(D4="",0,VLOOKUP(D4,Bausteine!$A$2:$AI$33,9,FALSE))+IF(E4="",0,VLOOKUP(E4,Bausteine!$A$2:$AI$33,9,FALSE))+IF(F4="",0,VLOOKUP(F4,Bausteine!$A$2:$AI$33,9,FALSE))+IF(G4="",0,VLOOKUP(G4,Bausteine!$A$2:$AI$33,9,FALSE))+IF(H4="",0,VLOOKUP(H4,Bausteine!$A$2:$AI$33,9,FALSE))+IF(I4="",0,VLOOKUP(I4,Bausteine!$A$2:$AI$33,9,FALSE))+IF(J4="",0,VLOOKUP(J4,Bausteine!$A$2:$AI$33,9,FALSE))+IF(K4="",0,VLOOKUP(K4,Bausteine!$A$2:$AI$33,9,FALSE))+IF(L4="",0,VLOOKUP(L4,Bausteine!$A$2:$AI$33,9,FALSE)) | V4: =IF(D4="",0,VLOOKUP(D4,Bausteine!$A$2:$AI$33,10,FALSE))-U4/IF(E4="",0,VLOOKUP(E4,Bausteine!$A$2:$AI$33,11,FALSE)) | W4: =IF(Y4<>"OK","",ROUND(MIN(IF(C4="",0,VLOOKUP(C4,Bausteine!$A$2:$AI$33,21,FALSE)),IF(C4="",0,VLOOKUP(C4,Bausteine!$A$2:$AI$33,20,FALSE))*(V4/T4/(IF(C4="",0,VLOOKUP(C4,Bausteine!$A$2:$AI$33,19,FALSE))/IF(C4="",0,VLOOKUP(C4,Bausteine!$A$2:$AI$33,18,FALSE))))^Parameter!$B$3),0)) | X4: =IF(F4="",0,VLOOKUP(F4,Bausteine!$A$2:$AI$33,14,FALSE)) | Y4: =IFERROR(IF(OR(R4<=0,T4<=0,V4<=0,U4>IF(E4="",0,VLOOKUP(E4,Bausteine!$A$2:$AI$33,12,FALSE)),T4>IF(C4="",0,VLOOKUP(C4,Bausteine!$A$2:$AI$33,22,FALSE)),IF(E4="",0,VLOOKUP(E4,Bausteine!$A$2:$AI$33,11,FALSE))<=0,IF(E4="",0,VLOOKUP(E4,Bausteine!$A$2:$AI$33,11,FALSE))>1),"UNGUELTIG","OK"),"FEHLER") | Z4: 600 | AA4: 103
A5: Gatling Tank | B5: china | C5: gatling-chassis | D5: diesel | E5: baseline-generator | F5: heavy | G5: gatling-turret | H5: gatling-gun | I5: gatling-rounds | M5: =IF(C5="",0,VLOOKUP(C5,Bausteine!$A$2:$AI$33,4,FALSE))+IF(D5="",0,VLOOKUP(D5,Bausteine!$A$2:$AI$33,4,FALSE))+IF(E5="",0,VLOOKUP(E5,Bausteine!$A$2:$AI$33,4,FALSE))+IF(F5="",0,VLOOKUP(F5,Bausteine!$A$2:$AI$33,4,FALSE))+IF(G5="",0,VLOOKUP(G5,Bausteine!$A$2:$AI$33,4,FALSE))+IF(H5="",0,VLOOKUP(H5,Bausteine!$A$2:$AI$33,4,FALSE))+IF(I5="",0,VLOOKUP(I5,Bausteine!$A$2:$AI$33,4,FALSE))+IF(J5="",0,VLOOKUP(J5,Bausteine!$A$2:$AI$33,4,FALSE))+IF(K5="",0,VLOOKUP(K5,Bausteine!$A$2:$AI$33,4,FALSE))+IF(L5="",0,VLOOKUP(L5,Bausteine!$A$2:$AI$33,4,FALSE)) | N5: =IF(C5="",0,VLOOKUP(C5,Bausteine!$A$2:$AI$33,5,FALSE))+IF(D5="",0,VLOOKUP(D5,Bausteine!$A$2:$AI$33,5,FALSE))+IF(E5="",0,VLOOKUP(E5,Bausteine!$A$2:$AI$33,5,FALSE))+IF(F5="",0,VLOOKUP(F5,Bausteine!$A$2:$AI$33,5,FALSE))+IF(G5="",0,VLOOKUP(G5,Bausteine!$A$2:$AI$33,5,FALSE))+IF(H5="",0,VLOOKUP(H5,Bausteine!$A$2:$AI$33,5,FALSE))+IF(I5="",0,VLOOKUP(I5,Bausteine!$A$2:$AI$33,5,FALSE))+IF(J5="",0,VLOOKUP(J5,Bausteine!$A$2:$AI$33,5,FALSE))+IF(K5="",0,VLOOKUP(K5,Bausteine!$A$2:$AI$33,5,FALSE))+IF(L5="",0,VLOOKUP(L5,Bausteine!$A$2:$AI$33,5,FALSE)) | O5: =MAX(IF(C5="",0,VLOOKUP(C5,Bausteine!$A$2:$AI$33,6,FALSE)),IF(D5="",0,VLOOKUP(D5,Bausteine!$A$2:$AI$33,6,FALSE)),IF(E5="",0,VLOOKUP(E5,Bausteine!$A$2:$AI$33,6,FALSE)),IF(F5="",0,VLOOKUP(F5,Bausteine!$A$2:$AI$33,6,FALSE)),IF(G5="",0,VLOOKUP(G5,Bausteine!$A$2:$AI$33,6,FALSE)),IF(H5="",0,VLOOKUP(H5,Bausteine!$A$2:$AI$33,6,FALSE)),IF(I5="",0,VLOOKUP(I5,Bausteine!$A$2:$AI$33,6,FALSE)),IF(J5="",0,VLOOKUP(J5,Bausteine!$A$2:$AI$33,6,FALSE)),IF(K5="",0,VLOOKUP(K5,Bausteine!$A$2:$AI$33,6,FALSE)),IF(L5="",0,VLOOKUP(L5,Bausteine!$A$2:$AI$33,6,FALSE))) | P5: =IF(C5="",0,VLOOKUP(C5,Bausteine!$A$2:$AI$33,7,FALSE))*IF(F5="",0,VLOOKUP(F5,Bausteine!$A$2:$AI$33,17,FALSE))/100+IF(D5="",0,VLOOKUP(D5,Bausteine!$A$2:$AI$33,7,FALSE))+IF(E5="",0,VLOOKUP(E5,Bausteine!$A$2:$AI$33,7,FALSE))+IF(G5="",0,VLOOKUP(G5,Bausteine!$A$2:$AI$33,7,FALSE))+IF(H5="",0,VLOOKUP(H5,Bausteine!$A$2:$AI$33,7,FALSE))+IF(I5="",0,VLOOKUP(I5,Bausteine!$A$2:$AI$33,7,FALSE))+IF(J5="",0,VLOOKUP(J5,Bausteine!$A$2:$AI$33,7,FALSE))+IF(K5="",0,VLOOKUP(K5,Bausteine!$A$2:$AI$33,7,FALSE))+IF(L5="",0,VLOOKUP(L5,Bausteine!$A$2:$AI$33,7,FALSE)) | Q5: =N5*Parameter!$B$2 | R5: =P5-Q5 | S5: =IF(C5="",0,VLOOKUP(C5,Bausteine!$A$2:$AI$33,13,FALSE))*IF(F5="",0,VLOOKUP(F5,Bausteine!$A$2:$AI$33,16,FALSE))/100 | T5: =IF(C5="",0,VLOOKUP(C5,Bausteine!$A$2:$AI$33,8,FALSE))*IF(F5="",0,VLOOKUP(F5,Bausteine!$A$2:$AI$33,15,FALSE))/100+IF(D5="",0,VLOOKUP(D5,Bausteine!$A$2:$AI$33,8,FALSE))+IF(E5="",0,VLOOKUP(E5,Bausteine!$A$2:$AI$33,8,FALSE))+IF(G5="",0,VLOOKUP(G5,Bausteine!$A$2:$AI$33,8,FALSE))+IF(H5="",0,VLOOKUP(H5,Bausteine!$A$2:$AI$33,8,FALSE))+IF(I5="",0,VLOOKUP(I5,Bausteine!$A$2:$AI$33,8,FALSE))+IF(J5="",0,VLOOKUP(J5,Bausteine!$A$2:$AI$33,8,FALSE))+IF(K5="",0,VLOOKUP(K5,Bausteine!$A$2:$AI$33,8,FALSE))+IF(L5="",0,VLOOKUP(L5,Bausteine!$A$2:$AI$33,8,FALSE)) | U5: =IF(C5="",0,VLOOKUP(C5,Bausteine!$A$2:$AI$33,9,FALSE))+IF(D5="",0,VLOOKUP(D5,Bausteine!$A$2:$AI$33,9,FALSE))+IF(E5="",0,VLOOKUP(E5,Bausteine!$A$2:$AI$33,9,FALSE))+IF(F5="",0,VLOOKUP(F5,Bausteine!$A$2:$AI$33,9,FALSE))+IF(G5="",0,VLOOKUP(G5,Bausteine!$A$2:$AI$33,9,FALSE))+IF(H5="",0,VLOOKUP(H5,Bausteine!$A$2:$AI$33,9,FALSE))+IF(I5="",0,VLOOKUP(I5,Bausteine!$A$2:$AI$33,9,FALSE))+IF(J5="",0,VLOOKUP(J5,Bausteine!$A$2:$AI$33,9,FALSE))+IF(K5="",0,VLOOKUP(K5,Bausteine!$A$2:$AI$33,9,FALSE))+IF(L5="",0,VLOOKUP(L5,Bausteine!$A$2:$AI$33,9,FALSE)) | V5: =IF(D5="",0,VLOOKUP(D5,Bausteine!$A$2:$AI$33,10,FALSE))-U5/IF(E5="",0,VLOOKUP(E5,Bausteine!$A$2:$AI$33,11,FALSE)) | W5: =IF(Y5<>"OK","",ROUND(MIN(IF(C5="",0,VLOOKUP(C5,Bausteine!$A$2:$AI$33,21,FALSE)),IF(C5="",0,VLOOKUP(C5,Bausteine!$A$2:$AI$33,20,FALSE))*(V5/T5/(IF(C5="",0,VLOOKUP(C5,Bausteine!$A$2:$AI$33,19,FALSE))/IF(C5="",0,VLOOKUP(C5,Bausteine!$A$2:$AI$33,18,FALSE))))^Parameter!$B$3),0)) | X5: =IF(F5="",0,VLOOKUP(F5,Bausteine!$A$2:$AI$33,14,FALSE)) | Y5: =IFERROR(IF(OR(R5<=0,T5<=0,V5<=0,U5>IF(E5="",0,VLOOKUP(E5,Bausteine!$A$2:$AI$33,12,FALSE)),T5>IF(C5="",0,VLOOKUP(C5,Bausteine!$A$2:$AI$33,22,FALSE)),IF(E5="",0,VLOOKUP(E5,Bausteine!$A$2:$AI$33,11,FALSE))<=0,IF(E5="",0,VLOOKUP(E5,Bausteine!$A$2:$AI$33,11,FALSE))>1),"UNGUELTIG","OK"),"FEHLER") | Z5: 800 | AA5: 108 | AB5: AA/ground spin-up and 6-cell sight override recorded, not implemented in calculator.
A6: Gatling Tank PDL | B6: china | C6: gatling-chassis | D6: diesel-large | E6: efficient-generator | F6: heavy | G6: gatling-turret | H6: gatling-gun | I6: gatling-rounds | J6: pdl | M6: =IF(C6="",0,VLOOKUP(C6,Bausteine!$A$2:$AI$33,4,FALSE))+IF(D6="",0,VLOOKUP(D6,Bausteine!$A$2:$AI$33,4,FALSE))+IF(E6="",0,VLOOKUP(E6,Bausteine!$A$2:$AI$33,4,FALSE))+IF(F6="",0,VLOOKUP(F6,Bausteine!$A$2:$AI$33,4,FALSE))+IF(G6="",0,VLOOKUP(G6,Bausteine!$A$2:$AI$33,4,FALSE))+IF(H6="",0,VLOOKUP(H6,Bausteine!$A$2:$AI$33,4,FALSE))+IF(I6="",0,VLOOKUP(I6,Bausteine!$A$2:$AI$33,4,FALSE))+IF(J6="",0,VLOOKUP(J6,Bausteine!$A$2:$AI$33,4,FALSE))+IF(K6="",0,VLOOKUP(K6,Bausteine!$A$2:$AI$33,4,FALSE))+IF(L6="",0,VLOOKUP(L6,Bausteine!$A$2:$AI$33,4,FALSE)) | N6: =IF(C6="",0,VLOOKUP(C6,Bausteine!$A$2:$AI$33,5,FALSE))+IF(D6="",0,VLOOKUP(D6,Bausteine!$A$2:$AI$33,5,FALSE))+IF(E6="",0,VLOOKUP(E6,Bausteine!$A$2:$AI$33,5,FALSE))+IF(F6="",0,VLOOKUP(F6,Bausteine!$A$2:$AI$33,5,FALSE))+IF(G6="",0,VLOOKUP(G6,Bausteine!$A$2:$AI$33,5,FALSE))+IF(H6="",0,VLOOKUP(H6,Bausteine!$A$2:$AI$33,5,FALSE))+IF(I6="",0,VLOOKUP(I6,Bausteine!$A$2:$AI$33,5,FALSE))+IF(J6="",0,VLOOKUP(J6,Bausteine!$A$2:$AI$33,5,FALSE))+IF(K6="",0,VLOOKUP(K6,Bausteine!$A$2:$AI$33,5,FALSE))+IF(L6="",0,VLOOKUP(L6,Bausteine!$A$2:$AI$33,5,FALSE)) | O6: =MAX(IF(C6="",0,VLOOKUP(C6,Bausteine!$A$2:$AI$33,6,FALSE)),IF(D6="",0,VLOOKUP(D6,Bausteine!$A$2:$AI$33,6,FALSE)),IF(E6="",0,VLOOKUP(E6,Bausteine!$A$2:$AI$33,6,FALSE)),IF(F6="",0,VLOOKUP(F6,Bausteine!$A$2:$AI$33,6,FALSE)),IF(G6="",0,VLOOKUP(G6,Bausteine!$A$2:$AI$33,6,FALSE)),IF(H6="",0,VLOOKUP(H6,Bausteine!$A$2:$AI$33,6,FALSE)),IF(I6="",0,VLOOKUP(I6,Bausteine!$A$2:$AI$33,6,FALSE)),IF(J6="",0,VLOOKUP(J6,Bausteine!$A$2:$AI$33,6,FALSE)),IF(K6="",0,VLOOKUP(K6,Bausteine!$A$2:$AI$33,6,FALSE)),IF(L6="",0,VLOOKUP(L6,Bausteine!$A$2:$AI$33,6,FALSE))) | P6: =IF(C6="",0,VLOOKUP(C6,Bausteine!$A$2:$AI$33,7,FALSE))*IF(F6="",0,VLOOKUP(F6,Bausteine!$A$2:$AI$33,17,FALSE))/100+IF(D6="",0,VLOOKUP(D6,Bausteine!$A$2:$AI$33,7,FALSE))+IF(E6="",0,VLOOKUP(E6,Bausteine!$A$2:$AI$33,7,FALSE))+IF(G6="",0,VLOOKUP(G6,Bausteine!$A$2:$AI$33,7,FALSE))+IF(H6="",0,VLOOKUP(H6,Bausteine!$A$2:$AI$33,7,FALSE))+IF(I6="",0,VLOOKUP(I6,Bausteine!$A$2:$AI$33,7,FALSE))+IF(J6="",0,VLOOKUP(J6,Bausteine!$A$2:$AI$33,7,FALSE))+IF(K6="",0,VLOOKUP(K6,Bausteine!$A$2:$AI$33,7,FALSE))+IF(L6="",0,VLOOKUP(L6,Bausteine!$A$2:$AI$33,7,FALSE)) | Q6: =N6*Parameter!$B$2 | R6: =P6-Q6 | S6: =IF(C6="",0,VLOOKUP(C6,Bausteine!$A$2:$AI$33,13,FALSE))*IF(F6="",0,VLOOKUP(F6,Bausteine!$A$2:$AI$33,16,FALSE))/100 | T6: =IF(C6="",0,VLOOKUP(C6,Bausteine!$A$2:$AI$33,8,FALSE))*IF(F6="",0,VLOOKUP(F6,Bausteine!$A$2:$AI$33,15,FALSE))/100+IF(D6="",0,VLOOKUP(D6,Bausteine!$A$2:$AI$33,8,FALSE))+IF(E6="",0,VLOOKUP(E6,Bausteine!$A$2:$AI$33,8,FALSE))+IF(G6="",0,VLOOKUP(G6,Bausteine!$A$2:$AI$33,8,FALSE))+IF(H6="",0,VLOOKUP(H6,Bausteine!$A$2:$AI$33,8,FALSE))+IF(I6="",0,VLOOKUP(I6,Bausteine!$A$2:$AI$33,8,FALSE))+IF(J6="",0,VLOOKUP(J6,Bausteine!$A$2:$AI$33,8,FALSE))+IF(K6="",0,VLOOKUP(K6,Bausteine!$A$2:$AI$33,8,FALSE))+IF(L6="",0,VLOOKUP(L6,Bausteine!$A$2:$AI$33,8,FALSE)) | U6: =IF(C6="",0,VLOOKUP(C6,Bausteine!$A$2:$AI$33,9,FALSE))+IF(D6="",0,VLOOKUP(D6,Bausteine!$A$2:$AI$33,9,FALSE))+IF(E6="",0,VLOOKUP(E6,Bausteine!$A$2:$AI$33,9,FALSE))+IF(F6="",0,VLOOKUP(F6,Bausteine!$A$2:$AI$33,9,FALSE))+IF(G6="",0,VLOOKUP(G6,Bausteine!$A$2:$AI$33,9,FALSE))+IF(H6="",0,VLOOKUP(H6,Bausteine!$A$2:$AI$33,9,FALSE))+IF(I6="",0,VLOOKUP(I6,Bausteine!$A$2:$AI$33,9,FALSE))+IF(J6="",0,VLOOKUP(J6,Bausteine!$A$2:$AI$33,9,FALSE))+IF(K6="",0,VLOOKUP(K6,Bausteine!$A$2:$AI$33,9,FALSE))+IF(L6="",0,VLOOKUP(L6,Bausteine!$A$2:$AI$33,9,FALSE)) | V6: =IF(D6="",0,VLOOKUP(D6,Bausteine!$A$2:$AI$33,10,FALSE))-U6/IF(E6="",0,VLOOKUP(E6,Bausteine!$A$2:$AI$33,11,FALSE)) | W6: =IF(Y6<>"OK","",ROUND(MIN(IF(C6="",0,VLOOKUP(C6,Bausteine!$A$2:$AI$33,21,FALSE)),IF(C6="",0,VLOOKUP(C6,Bausteine!$A$2:$AI$33,20,FALSE))*(V6/T6/(IF(C6="",0,VLOOKUP(C6,Bausteine!$A$2:$AI$33,19,FALSE))/IF(C6="",0,VLOOKUP(C6,Bausteine!$A$2:$AI$33,18,FALSE))))^Parameter!$B$3),0)) | X6: =IF(F6="",0,VLOOKUP(F6,Bausteine!$A$2:$AI$33,14,FALSE)) | Y6: =IFERROR(IF(OR(R6<=0,T6<=0,V6<=0,U6>IF(E6="",0,VLOOKUP(E6,Bausteine!$A$2:$AI$33,12,FALSE)),T6>IF(C6="",0,VLOOKUP(C6,Bausteine!$A$2:$AI$33,22,FALSE)),IF(E6="",0,VLOOKUP(E6,Bausteine!$A$2:$AI$33,11,FALSE))<=0,IF(E6="",0,VLOOKUP(E6,Bausteine!$A$2:$AI$33,11,FALSE))>1),"UNGUELTIG","OK"),"FEHLER") | Z6: 1450 | AA6: 108 | AB6: Legacy promotion restricted to Tank General; catalog uses China base faction as agreed.
A7: Gatling Tank Reflector | B7: china | C7: gatling-chassis | D7: diesel-large | E7: efficient-generator | F7: reflector | G7: gatling-turret | H7: gatling-gun | I7: gatling-rounds | M7: =IF(C7="",0,VLOOKUP(C7,Bausteine!$A$2:$AI$33,4,FALSE))+IF(D7="",0,VLOOKUP(D7,Bausteine!$A$2:$AI$33,4,FALSE))+IF(E7="",0,VLOOKUP(E7,Bausteine!$A$2:$AI$33,4,FALSE))+IF(F7="",0,VLOOKUP(F7,Bausteine!$A$2:$AI$33,4,FALSE))+IF(G7="",0,VLOOKUP(G7,Bausteine!$A$2:$AI$33,4,FALSE))+IF(H7="",0,VLOOKUP(H7,Bausteine!$A$2:$AI$33,4,FALSE))+IF(I7="",0,VLOOKUP(I7,Bausteine!$A$2:$AI$33,4,FALSE))+IF(J7="",0,VLOOKUP(J7,Bausteine!$A$2:$AI$33,4,FALSE))+IF(K7="",0,VLOOKUP(K7,Bausteine!$A$2:$AI$33,4,FALSE))+IF(L7="",0,VLOOKUP(L7,Bausteine!$A$2:$AI$33,4,FALSE)) | N7: =IF(C7="",0,VLOOKUP(C7,Bausteine!$A$2:$AI$33,5,FALSE))+IF(D7="",0,VLOOKUP(D7,Bausteine!$A$2:$AI$33,5,FALSE))+IF(E7="",0,VLOOKUP(E7,Bausteine!$A$2:$AI$33,5,FALSE))+IF(F7="",0,VLOOKUP(F7,Bausteine!$A$2:$AI$33,5,FALSE))+IF(G7="",0,VLOOKUP(G7,Bausteine!$A$2:$AI$33,5,FALSE))+IF(H7="",0,VLOOKUP(H7,Bausteine!$A$2:$AI$33,5,FALSE))+IF(I7="",0,VLOOKUP(I7,Bausteine!$A$2:$AI$33,5,FALSE))+IF(J7="",0,VLOOKUP(J7,Bausteine!$A$2:$AI$33,5,FALSE))+IF(K7="",0,VLOOKUP(K7,Bausteine!$A$2:$AI$33,5,FALSE))+IF(L7="",0,VLOOKUP(L7,Bausteine!$A$2:$AI$33,5,FALSE)) | O7: =MAX(IF(C7="",0,VLOOKUP(C7,Bausteine!$A$2:$AI$33,6,FALSE)),IF(D7="",0,VLOOKUP(D7,Bausteine!$A$2:$AI$33,6,FALSE)),IF(E7="",0,VLOOKUP(E7,Bausteine!$A$2:$AI$33,6,FALSE)),IF(F7="",0,VLOOKUP(F7,Bausteine!$A$2:$AI$33,6,FALSE)),IF(G7="",0,VLOOKUP(G7,Bausteine!$A$2:$AI$33,6,FALSE)),IF(H7="",0,VLOOKUP(H7,Bausteine!$A$2:$AI$33,6,FALSE)),IF(I7="",0,VLOOKUP(I7,Bausteine!$A$2:$AI$33,6,FALSE)),IF(J7="",0,VLOOKUP(J7,Bausteine!$A$2:$AI$33,6,FALSE)),IF(K7="",0,VLOOKUP(K7,Bausteine!$A$2:$AI$33,6,FALSE)),IF(L7="",0,VLOOKUP(L7,Bausteine!$A$2:$AI$33,6,FALSE))) | P7: =IF(C7="",0,VLOOKUP(C7,Bausteine!$A$2:$AI$33,7,FALSE))*IF(F7="",0,VLOOKUP(F7,Bausteine!$A$2:$AI$33,17,FALSE))/100+IF(D7="",0,VLOOKUP(D7,Bausteine!$A$2:$AI$33,7,FALSE))+IF(E7="",0,VLOOKUP(E7,Bausteine!$A$2:$AI$33,7,FALSE))+IF(G7="",0,VLOOKUP(G7,Bausteine!$A$2:$AI$33,7,FALSE))+IF(H7="",0,VLOOKUP(H7,Bausteine!$A$2:$AI$33,7,FALSE))+IF(I7="",0,VLOOKUP(I7,Bausteine!$A$2:$AI$33,7,FALSE))+IF(J7="",0,VLOOKUP(J7,Bausteine!$A$2:$AI$33,7,FALSE))+IF(K7="",0,VLOOKUP(K7,Bausteine!$A$2:$AI$33,7,FALSE))+IF(L7="",0,VLOOKUP(L7,Bausteine!$A$2:$AI$33,7,FALSE)) | Q7: =N7*Parameter!$B$2 | R7: =P7-Q7 | S7: =IF(C7="",0,VLOOKUP(C7,Bausteine!$A$2:$AI$33,13,FALSE))*IF(F7="",0,VLOOKUP(F7,Bausteine!$A$2:$AI$33,16,FALSE))/100 | T7: =IF(C7="",0,VLOOKUP(C7,Bausteine!$A$2:$AI$33,8,FALSE))*IF(F7="",0,VLOOKUP(F7,Bausteine!$A$2:$AI$33,15,FALSE))/100+IF(D7="",0,VLOOKUP(D7,Bausteine!$A$2:$AI$33,8,FALSE))+IF(E7="",0,VLOOKUP(E7,Bausteine!$A$2:$AI$33,8,FALSE))+IF(G7="",0,VLOOKUP(G7,Bausteine!$A$2:$AI$33,8,FALSE))+IF(H7="",0,VLOOKUP(H7,Bausteine!$A$2:$AI$33,8,FALSE))+IF(I7="",0,VLOOKUP(I7,Bausteine!$A$2:$AI$33,8,FALSE))+IF(J7="",0,VLOOKUP(J7,Bausteine!$A$2:$AI$33,8,FALSE))+IF(K7="",0,VLOOKUP(K7,Bausteine!$A$2:$AI$33,8,FALSE))+IF(L7="",0,VLOOKUP(L7,Bausteine!$A$2:$AI$33,8,FALSE)) | U7: =IF(C7="",0,VLOOKUP(C7,Bausteine!$A$2:$AI$33,9,FALSE))+IF(D7="",0,VLOOKUP(D7,Bausteine!$A$2:$AI$33,9,FALSE))+IF(E7="",0,VLOOKUP(E7,Bausteine!$A$2:$AI$33,9,FALSE))+IF(F7="",0,VLOOKUP(F7,Bausteine!$A$2:$AI$33,9,FALSE))+IF(G7="",0,VLOOKUP(G7,Bausteine!$A$2:$AI$33,9,FALSE))+IF(H7="",0,VLOOKUP(H7,Bausteine!$A$2:$AI$33,9,FALSE))+IF(I7="",0,VLOOKUP(I7,Bausteine!$A$2:$AI$33,9,FALSE))+IF(J7="",0,VLOOKUP(J7,Bausteine!$A$2:$AI$33,9,FALSE))+IF(K7="",0,VLOOKUP(K7,Bausteine!$A$2:$AI$33,9,FALSE))+IF(L7="",0,VLOOKUP(L7,Bausteine!$A$2:$AI$33,9,FALSE)) | V7: =IF(D7="",0,VLOOKUP(D7,Bausteine!$A$2:$AI$33,10,FALSE))-U7/IF(E7="",0,VLOOKUP(E7,Bausteine!$A$2:$AI$33,11,FALSE)) | W7: =IF(Y7<>"OK","",ROUND(MIN(IF(C7="",0,VLOOKUP(C7,Bausteine!$A$2:$AI$33,21,FALSE)),IF(C7="",0,VLOOKUP(C7,Bausteine!$A$2:$AI$33,20,FALSE))*(V7/T7/(IF(C7="",0,VLOOKUP(C7,Bausteine!$A$2:$AI$33,19,FALSE))/IF(C7="",0,VLOOKUP(C7,Bausteine!$A$2:$AI$33,18,FALSE))))^Parameter!$B$3),0)) | X7: =IF(F7="",0,VLOOKUP(F7,Bausteine!$A$2:$AI$33,14,FALSE)) | Y7: =IFERROR(IF(OR(R7<=0,T7<=0,V7<=0,U7>IF(E7="",0,VLOOKUP(E7,Bausteine!$A$2:$AI$33,12,FALSE)),T7>IF(C7="",0,VLOOKUP(C7,Bausteine!$A$2:$AI$33,22,FALSE)),IF(E7="",0,VLOOKUP(E7,Bausteine!$A$2:$AI$33,11,FALSE))<=0,IF(E7="",0,VLOOKUP(E7,Bausteine!$A$2:$AI$33,11,FALSE))>1),"UNGUELTIG","OK"),"FEHLER") | Z7: 800 | AA7: 108 | AB7: Legacy promotion restricted to Tank General; catalog uses China base faction as agreed.
A8: Battlemaster Nuclear Shells | B8: china | C8: battlemaster | D8: diesel | E8: baseline-generator | F8: heavy | G8: cannon-turret | H8: cannon | I8: nuclear-shell | M8: =IF(C8="",0,VLOOKUP(C8,Bausteine!$A$2:$AI$33,4,FALSE))+IF(D8="",0,VLOOKUP(D8,Bausteine!$A$2:$AI$33,4,FALSE))+IF(E8="",0,VLOOKUP(E8,Bausteine!$A$2:$AI$33,4,FALSE))+IF(F8="",0,VLOOKUP(F8,Bausteine!$A$2:$AI$33,4,FALSE))+IF(G8="",0,VLOOKUP(G8,Bausteine!$A$2:$AI$33,4,FALSE))+IF(H8="",0,VLOOKUP(H8,Bausteine!$A$2:$AI$33,4,FALSE))+IF(I8="",0,VLOOKUP(I8,Bausteine!$A$2:$AI$33,4,FALSE))+IF(J8="",0,VLOOKUP(J8,Bausteine!$A$2:$AI$33,4,FALSE))+IF(K8="",0,VLOOKUP(K8,Bausteine!$A$2:$AI$33,4,FALSE))+IF(L8="",0,VLOOKUP(L8,Bausteine!$A$2:$AI$33,4,FALSE)) | N8: =IF(C8="",0,VLOOKUP(C8,Bausteine!$A$2:$AI$33,5,FALSE))+IF(D8="",0,VLOOKUP(D8,Bausteine!$A$2:$AI$33,5,FALSE))+IF(E8="",0,VLOOKUP(E8,Bausteine!$A$2:$AI$33,5,FALSE))+IF(F8="",0,VLOOKUP(F8,Bausteine!$A$2:$AI$33,5,FALSE))+IF(G8="",0,VLOOKUP(G8,Bausteine!$A$2:$AI$33,5,FALSE))+IF(H8="",0,VLOOKUP(H8,Bausteine!$A$2:$AI$33,5,FALSE))+IF(I8="",0,VLOOKUP(I8,Bausteine!$A$2:$AI$33,5,FALSE))+IF(J8="",0,VLOOKUP(J8,Bausteine!$A$2:$AI$33,5,FALSE))+IF(K8="",0,VLOOKUP(K8,Bausteine!$A$2:$AI$33,5,FALSE))+IF(L8="",0,VLOOKUP(L8,Bausteine!$A$2:$AI$33,5,FALSE)) | O8: =MAX(IF(C8="",0,VLOOKUP(C8,Bausteine!$A$2:$AI$33,6,FALSE)),IF(D8="",0,VLOOKUP(D8,Bausteine!$A$2:$AI$33,6,FALSE)),IF(E8="",0,VLOOKUP(E8,Bausteine!$A$2:$AI$33,6,FALSE)),IF(F8="",0,VLOOKUP(F8,Bausteine!$A$2:$AI$33,6,FALSE)),IF(G8="",0,VLOOKUP(G8,Bausteine!$A$2:$AI$33,6,FALSE)),IF(H8="",0,VLOOKUP(H8,Bausteine!$A$2:$AI$33,6,FALSE)),IF(I8="",0,VLOOKUP(I8,Bausteine!$A$2:$AI$33,6,FALSE)),IF(J8="",0,VLOOKUP(J8,Bausteine!$A$2:$AI$33,6,FALSE)),IF(K8="",0,VLOOKUP(K8,Bausteine!$A$2:$AI$33,6,FALSE)),IF(L8="",0,VLOOKUP(L8,Bausteine!$A$2:$AI$33,6,FALSE))) | P8: =IF(C8="",0,VLOOKUP(C8,Bausteine!$A$2:$AI$33,7,FALSE))*IF(F8="",0,VLOOKUP(F8,Bausteine!$A$2:$AI$33,17,FALSE))/100+IF(D8="",0,VLOOKUP(D8,Bausteine!$A$2:$AI$33,7,FALSE))+IF(E8="",0,VLOOKUP(E8,Bausteine!$A$2:$AI$33,7,FALSE))+IF(G8="",0,VLOOKUP(G8,Bausteine!$A$2:$AI$33,7,FALSE))+IF(H8="",0,VLOOKUP(H8,Bausteine!$A$2:$AI$33,7,FALSE))+IF(I8="",0,VLOOKUP(I8,Bausteine!$A$2:$AI$33,7,FALSE))+IF(J8="",0,VLOOKUP(J8,Bausteine!$A$2:$AI$33,7,FALSE))+IF(K8="",0,VLOOKUP(K8,Bausteine!$A$2:$AI$33,7,FALSE))+IF(L8="",0,VLOOKUP(L8,Bausteine!$A$2:$AI$33,7,FALSE)) | Q8: =N8*Parameter!$B$2 | R8: =P8-Q8 | S8: =IF(C8="",0,VLOOKUP(C8,Bausteine!$A$2:$AI$33,13,FALSE))*IF(F8="",0,VLOOKUP(F8,Bausteine!$A$2:$AI$33,16,FALSE))/100 | T8: =IF(C8="",0,VLOOKUP(C8,Bausteine!$A$2:$AI$33,8,FALSE))*IF(F8="",0,VLOOKUP(F8,Bausteine!$A$2:$AI$33,15,FALSE))/100+IF(D8="",0,VLOOKUP(D8,Bausteine!$A$2:$AI$33,8,FALSE))+IF(E8="",0,VLOOKUP(E8,Bausteine!$A$2:$AI$33,8,FALSE))+IF(G8="",0,VLOOKUP(G8,Bausteine!$A$2:$AI$33,8,FALSE))+IF(H8="",0,VLOOKUP(H8,Bausteine!$A$2:$AI$33,8,FALSE))+IF(I8="",0,VLOOKUP(I8,Bausteine!$A$2:$AI$33,8,FALSE))+IF(J8="",0,VLOOKUP(J8,Bausteine!$A$2:$AI$33,8,FALSE))+IF(K8="",0,VLOOKUP(K8,Bausteine!$A$2:$AI$33,8,FALSE))+IF(L8="",0,VLOOKUP(L8,Bausteine!$A$2:$AI$33,8,FALSE)) | U8: =IF(C8="",0,VLOOKUP(C8,Bausteine!$A$2:$AI$33,9,FALSE))+IF(D8="",0,VLOOKUP(D8,Bausteine!$A$2:$AI$33,9,FALSE))+IF(E8="",0,VLOOKUP(E8,Bausteine!$A$2:$AI$33,9,FALSE))+IF(F8="",0,VLOOKUP(F8,Bausteine!$A$2:$AI$33,9,FALSE))+IF(G8="",0,VLOOKUP(G8,Bausteine!$A$2:$AI$33,9,FALSE))+IF(H8="",0,VLOOKUP(H8,Bausteine!$A$2:$AI$33,9,FALSE))+IF(I8="",0,VLOOKUP(I8,Bausteine!$A$2:$AI$33,9,FALSE))+IF(J8="",0,VLOOKUP(J8,Bausteine!$A$2:$AI$33,9,FALSE))+IF(K8="",0,VLOOKUP(K8,Bausteine!$A$2:$AI$33,9,FALSE))+IF(L8="",0,VLOOKUP(L8,Bausteine!$A$2:$AI$33,9,FALSE)) | V8: =IF(D8="",0,VLOOKUP(D8,Bausteine!$A$2:$AI$33,10,FALSE))-U8/IF(E8="",0,VLOOKUP(E8,Bausteine!$A$2:$AI$33,11,FALSE)) | W8: =IF(Y8<>"OK","",ROUND(MIN(IF(C8="",0,VLOOKUP(C8,Bausteine!$A$2:$AI$33,21,FALSE)),IF(C8="",0,VLOOKUP(C8,Bausteine!$A$2:$AI$33,20,FALSE))*(V8/T8/(IF(C8="",0,VLOOKUP(C8,Bausteine!$A$2:$AI$33,19,FALSE))/IF(C8="",0,VLOOKUP(C8,Bausteine!$A$2:$AI$33,18,FALSE))))^Parameter!$B$3),0)) | X8: =IF(F8="",0,VLOOKUP(F8,Bausteine!$A$2:$AI$33,14,FALSE)) | Y8: =IFERROR(IF(OR(R8<=0,T8<=0,V8<=0,U8>IF(E8="",0,VLOOKUP(E8,Bausteine!$A$2:$AI$33,12,FALSE)),T8>IF(C8="",0,VLOOKUP(C8,Bausteine!$A$2:$AI$33,22,FALSE)),IF(E8="",0,VLOOKUP(E8,Bausteine!$A$2:$AI$33,11,FALSE))<=0,IF(E8="",0,VLOOKUP(E8,Bausteine!$A$2:$AI$33,11,FALSE))>1),"UNGUELTIG","OK"),"FEHLER") | Z8: 950 | AA8: 100
A9: Battlemaster Nuclear Shells PDL | B9: china | C9: battlemaster | D9: diesel-large | E9: efficient-generator | F9: heavy | G9: cannon-turret | H9: cannon | I9: nuclear-shell | J9: pdl | M9: =IF(C9="",0,VLOOKUP(C9,Bausteine!$A$2:$AI$33,4,FALSE))+IF(D9="",0,VLOOKUP(D9,Bausteine!$A$2:$AI$33,4,FALSE))+IF(E9="",0,VLOOKUP(E9,Bausteine!$A$2:$AI$33,4,FALSE))+IF(F9="",0,VLOOKUP(F9,Bausteine!$A$2:$AI$33,4,FALSE))+IF(G9="",0,VLOOKUP(G9,Bausteine!$A$2:$AI$33,4,FALSE))+IF(H9="",0,VLOOKUP(H9,Bausteine!$A$2:$AI$33,4,FALSE))+IF(I9="",0,VLOOKUP(I9,Bausteine!$A$2:$AI$33,4,FALSE))+IF(J9="",0,VLOOKUP(J9,Bausteine!$A$2:$AI$33,4,FALSE))+IF(K9="",0,VLOOKUP(K9,Bausteine!$A$2:$AI$33,4,FALSE))+IF(L9="",0,VLOOKUP(L9,Bausteine!$A$2:$AI$33,4,FALSE)) | N9: =IF(C9="",0,VLOOKUP(C9,Bausteine!$A$2:$AI$33,5,FALSE))+IF(D9="",0,VLOOKUP(D9,Bausteine!$A$2:$AI$33,5,FALSE))+IF(E9="",0,VLOOKUP(E9,Bausteine!$A$2:$AI$33,5,FALSE))+IF(F9="",0,VLOOKUP(F9,Bausteine!$A$2:$AI$33,5,FALSE))+IF(G9="",0,VLOOKUP(G9,Bausteine!$A$2:$AI$33,5,FALSE))+IF(H9="",0,VLOOKUP(H9,Bausteine!$A$2:$AI$33,5,FALSE))+IF(I9="",0,VLOOKUP(I9,Bausteine!$A$2:$AI$33,5,FALSE))+IF(J9="",0,VLOOKUP(J9,Bausteine!$A$2:$AI$33,5,FALSE))+IF(K9="",0,VLOOKUP(K9,Bausteine!$A$2:$AI$33,5,FALSE))+IF(L9="",0,VLOOKUP(L9,Bausteine!$A$2:$AI$33,5,FALSE)) | O9: =MAX(IF(C9="",0,VLOOKUP(C9,Bausteine!$A$2:$AI$33,6,FALSE)),IF(D9="",0,VLOOKUP(D9,Bausteine!$A$2:$AI$33,6,FALSE)),IF(E9="",0,VLOOKUP(E9,Bausteine!$A$2:$AI$33,6,FALSE)),IF(F9="",0,VLOOKUP(F9,Bausteine!$A$2:$AI$33,6,FALSE)),IF(G9="",0,VLOOKUP(G9,Bausteine!$A$2:$AI$33,6,FALSE)),IF(H9="",0,VLOOKUP(H9,Bausteine!$A$2:$AI$33,6,FALSE)),IF(I9="",0,VLOOKUP(I9,Bausteine!$A$2:$AI$33,6,FALSE)),IF(J9="",0,VLOOKUP(J9,Bausteine!$A$2:$AI$33,6,FALSE)),IF(K9="",0,VLOOKUP(K9,Bausteine!$A$2:$AI$33,6,FALSE)),IF(L9="",0,VLOOKUP(L9,Bausteine!$A$2:$AI$33,6,FALSE))) | P9: =IF(C9="",0,VLOOKUP(C9,Bausteine!$A$2:$AI$33,7,FALSE))*IF(F9="",0,VLOOKUP(F9,Bausteine!$A$2:$AI$33,17,FALSE))/100+IF(D9="",0,VLOOKUP(D9,Bausteine!$A$2:$AI$33,7,FALSE))+IF(E9="",0,VLOOKUP(E9,Bausteine!$A$2:$AI$33,7,FALSE))+IF(G9="",0,VLOOKUP(G9,Bausteine!$A$2:$AI$33,7,FALSE))+IF(H9="",0,VLOOKUP(H9,Bausteine!$A$2:$AI$33,7,FALSE))+IF(I9="",0,VLOOKUP(I9,Bausteine!$A$2:$AI$33,7,FALSE))+IF(J9="",0,VLOOKUP(J9,Bausteine!$A$2:$AI$33,7,FALSE))+IF(K9="",0,VLOOKUP(K9,Bausteine!$A$2:$AI$33,7,FALSE))+IF(L9="",0,VLOOKUP(L9,Bausteine!$A$2:$AI$33,7,FALSE)) | Q9: =N9*Parameter!$B$2 | R9: =P9-Q9 | S9: =IF(C9="",0,VLOOKUP(C9,Bausteine!$A$2:$AI$33,13,FALSE))*IF(F9="",0,VLOOKUP(F9,Bausteine!$A$2:$AI$33,16,FALSE))/100 | T9: =IF(C9="",0,VLOOKUP(C9,Bausteine!$A$2:$AI$33,8,FALSE))*IF(F9="",0,VLOOKUP(F9,Bausteine!$A$2:$AI$33,15,FALSE))/100+IF(D9="",0,VLOOKUP(D9,Bausteine!$A$2:$AI$33,8,FALSE))+IF(E9="",0,VLOOKUP(E9,Bausteine!$A$2:$AI$33,8,FALSE))+IF(G9="",0,VLOOKUP(G9,Bausteine!$A$2:$AI$33,8,FALSE))+IF(H9="",0,VLOOKUP(H9,Bausteine!$A$2:$AI$33,8,FALSE))+IF(I9="",0,VLOOKUP(I9,Bausteine!$A$2:$AI$33,8,FALSE))+IF(J9="",0,VLOOKUP(J9,Bausteine!$A$2:$AI$33,8,FALSE))+IF(K9="",0,VLOOKUP(K9,Bausteine!$A$2:$AI$33,8,FALSE))+IF(L9="",0,VLOOKUP(L9,Bausteine!$A$2:$AI$33,8,FALSE)) | U9: =IF(C9="",0,VLOOKUP(C9,Bausteine!$A$2:$AI$33,9,FALSE))+IF(D9="",0,VLOOKUP(D9,Bausteine!$A$2:$AI$33,9,FALSE))+IF(E9="",0,VLOOKUP(E9,Bausteine!$A$2:$AI$33,9,FALSE))+IF(F9="",0,VLOOKUP(F9,Bausteine!$A$2:$AI$33,9,FALSE))+IF(G9="",0,VLOOKUP(G9,Bausteine!$A$2:$AI$33,9,FALSE))+IF(H9="",0,VLOOKUP(H9,Bausteine!$A$2:$AI$33,9,FALSE))+IF(I9="",0,VLOOKUP(I9,Bausteine!$A$2:$AI$33,9,FALSE))+IF(J9="",0,VLOOKUP(J9,Bausteine!$A$2:$AI$33,9,FALSE))+IF(K9="",0,VLOOKUP(K9,Bausteine!$A$2:$AI$33,9,FALSE))+IF(L9="",0,VLOOKUP(L9,Bausteine!$A$2:$AI$33,9,FALSE)) | V9: =IF(D9="",0,VLOOKUP(D9,Bausteine!$A$2:$AI$33,10,FALSE))-U9/IF(E9="",0,VLOOKUP(E9,Bausteine!$A$2:$AI$33,11,FALSE)) | W9: =IF(Y9<>"OK","",ROUND(MIN(IF(C9="",0,VLOOKUP(C9,Bausteine!$A$2:$AI$33,21,FALSE)),IF(C9="",0,VLOOKUP(C9,Bausteine!$A$2:$AI$33,20,FALSE))*(V9/T9/(IF(C9="",0,VLOOKUP(C9,Bausteine!$A$2:$AI$33,19,FALSE))/IF(C9="",0,VLOOKUP(C9,Bausteine!$A$2:$AI$33,18,FALSE))))^Parameter!$B$3),0)) | X9: =IF(F9="",0,VLOOKUP(F9,Bausteine!$A$2:$AI$33,14,FALSE)) | Y9: =IFERROR(IF(OR(R9<=0,T9<=0,V9<=0,U9>IF(E9="",0,VLOOKUP(E9,Bausteine!$A$2:$AI$33,12,FALSE)),T9>IF(C9="",0,VLOOKUP(C9,Bausteine!$A$2:$AI$33,22,FALSE)),IF(E9="",0,VLOOKUP(E9,Bausteine!$A$2:$AI$33,11,FALSE))<=0,IF(E9="",0,VLOOKUP(E9,Bausteine!$A$2:$AI$33,11,FALSE))>1),"UNGUELTIG","OK"),"FEHLER") | Z9: 1600 | AA9: 100
A10: Battlemaster Nuclear Shells Reflector | B10: china | C10: battlemaster | D10: diesel-large | E10: efficient-generator | F10: reflector | G10: cannon-turret | H10: cannon | I10: nuclear-shell | M10: =IF(C10="",0,VLOOKUP(C10,Bausteine!$A$2:$AI$33,4,FALSE))+IF(D10="",0,VLOOKUP(D10,Bausteine!$A$2:$AI$33,4,FALSE))+IF(E10="",0,VLOOKUP(E10,Bausteine!$A$2:$AI$33,4,FALSE))+IF(F10="",0,VLOOKUP(F10,Bausteine!$A$2:$AI$33,4,FALSE))+IF(G10="",0,VLOOKUP(G10,Bausteine!$A$2:$AI$33,4,FALSE))+IF(H10="",0,VLOOKUP(H10,Bausteine!$A$2:$AI$33,4,FALSE))+IF(I10="",0,VLOOKUP(I10,Bausteine!$A$2:$AI$33,4,FALSE))+IF(J10="",0,VLOOKUP(J10,Bausteine!$A$2:$AI$33,4,FALSE))+IF(K10="",0,VLOOKUP(K10,Bausteine!$A$2:$AI$33,4,FALSE))+IF(L10="",0,VLOOKUP(L10,Bausteine!$A$2:$AI$33,4,FALSE)) | N10: =IF(C10="",0,VLOOKUP(C10,Bausteine!$A$2:$AI$33,5,FALSE))+IF(D10="",0,VLOOKUP(D10,Bausteine!$A$2:$AI$33,5,FALSE))+IF(E10="",0,VLOOKUP(E10,Bausteine!$A$2:$AI$33,5,FALSE))+IF(F10="",0,VLOOKUP(F10,Bausteine!$A$2:$AI$33,5,FALSE))+IF(G10="",0,VLOOKUP(G10,Bausteine!$A$2:$AI$33,5,FALSE))+IF(H10="",0,VLOOKUP(H10,Bausteine!$A$2:$AI$33,5,FALSE))+IF(I10="",0,VLOOKUP(I10,Bausteine!$A$2:$AI$33,5,FALSE))+IF(J10="",0,VLOOKUP(J10,Bausteine!$A$2:$AI$33,5,FALSE))+IF(K10="",0,VLOOKUP(K10,Bausteine!$A$2:$AI$33,5,FALSE))+IF(L10="",0,VLOOKUP(L10,Bausteine!$A$2:$AI$33,5,FALSE)) | O10: =MAX(IF(C10="",0,VLOOKUP(C10,Bausteine!$A$2:$AI$33,6,FALSE)),IF(D10="",0,VLOOKUP(D10,Bausteine!$A$2:$AI$33,6,FALSE)),IF(E10="",0,VLOOKUP(E10,Bausteine!$A$2:$AI$33,6,FALSE)),IF(F10="",0,VLOOKUP(F10,Bausteine!$A$2:$AI$33,6,FALSE)),IF(G10="",0,VLOOKUP(G10,Bausteine!$A$2:$AI$33,6,FALSE)),IF(H10="",0,VLOOKUP(H10,Bausteine!$A$2:$AI$33,6,FALSE)),IF(I10="",0,VLOOKUP(I10,Bausteine!$A$2:$AI$33,6,FALSE)),IF(J10="",0,VLOOKUP(J10,Bausteine!$A$2:$AI$33,6,FALSE)),IF(K10="",0,VLOOKUP(K10,Bausteine!$A$2:$AI$33,6,FALSE)),IF(L10="",0,VLOOKUP(L10,Bausteine!$A$2:$AI$33,6,FALSE))) | P10: =IF(C10="",0,VLOOKUP(C10,Bausteine!$A$2:$AI$33,7,FALSE))*IF(F10="",0,VLOOKUP(F10,Bausteine!$A$2:$AI$33,17,FALSE))/100+IF(D10="",0,VLOOKUP(D10,Bausteine!$A$2:$AI$33,7,FALSE))+IF(E10="",0,VLOOKUP(E10,Bausteine!$A$2:$AI$33,7,FALSE))+IF(G10="",0,VLOOKUP(G10,Bausteine!$A$2:$AI$33,7,FALSE))+IF(H10="",0,VLOOKUP(H10,Bausteine!$A$2:$AI$33,7,FALSE))+IF(I10="",0,VLOOKUP(I10,Bausteine!$A$2:$AI$33,7,FALSE))+IF(J10="",0,VLOOKUP(J10,Bausteine!$A$2:$AI$33,7,FALSE))+IF(K10="",0,VLOOKUP(K10,Bausteine!$A$2:$AI$33,7,FALSE))+IF(L10="",0,VLOOKUP(L10,Bausteine!$A$2:$AI$33,7,FALSE)) | Q10: =N10*Parameter!$B$2 | R10: =P10-Q10 | S10: =IF(C10="",0,VLOOKUP(C10,Bausteine!$A$2:$AI$33,13,FALSE))*IF(F10="",0,VLOOKUP(F10,Bausteine!$A$2:$AI$33,16,FALSE))/100 | T10: =IF(C10="",0,VLOOKUP(C10,Bausteine!$A$2:$AI$33,8,FALSE))*IF(F10="",0,VLOOKUP(F10,Bausteine!$A$2:$AI$33,15,FALSE))/100+IF(D10="",0,VLOOKUP(D10,Bausteine!$A$2:$AI$33,8,FALSE))+IF(E10="",0,VLOOKUP(E10,Bausteine!$A$2:$AI$33,8,FALSE))+IF(G10="",0,VLOOKUP(G10,Bausteine!$A$2:$AI$33,8,FALSE))+IF(H10="",0,VLOOKUP(H10,Bausteine!$A$2:$AI$33,8,FALSE))+IF(I10="",0,VLOOKUP(I10,Bausteine!$A$2:$AI$33,8,FALSE))+IF(J10="",0,VLOOKUP(J10,Bausteine!$A$2:$AI$33,8,FALSE))+IF(K10="",0,VLOOKUP(K10,Bausteine!$A$2:$AI$33,8,FALSE))+IF(L10="",0,VLOOKUP(L10,Bausteine!$A$2:$AI$33,8,FALSE)) | U10: =IF(C10="",0,VLOOKUP(C10,Bausteine!$A$2:$AI$33,9,FALSE))+IF(D10="",0,VLOOKUP(D10,Bausteine!$A$2:$AI$33,9,FALSE))+IF(E10="",0,VLOOKUP(E10,Bausteine!$A$2:$AI$33,9,FALSE))+IF(F10="",0,VLOOKUP(F10,Bausteine!$A$2:$AI$33,9,FALSE))+IF(G10="",0,VLOOKUP(G10,Bausteine!$A$2:$AI$33,9,FALSE))+IF(H10="",0,VLOOKUP(H10,Bausteine!$A$2:$AI$33,9,FALSE))+IF(I10="",0,VLOOKUP(I10,Bausteine!$A$2:$AI$33,9,FALSE))+IF(J10="",0,VLOOKUP(J10,Bausteine!$A$2:$AI$33,9,FALSE))+IF(K10="",0,VLOOKUP(K10,Bausteine!$A$2:$AI$33,9,FALSE))+IF(L10="",0,VLOOKUP(L10,Bausteine!$A$2:$AI$33,9,FALSE)) | V10: =IF(D10="",0,VLOOKUP(D10,Bausteine!$A$2:$AI$33,10,FALSE))-U10/IF(E10="",0,VLOOKUP(E10,Bausteine!$A$2:$AI$33,11,FALSE)) | W10: =IF(Y10<>"OK","",ROUND(MIN(IF(C10="",0,VLOOKUP(C10,Bausteine!$A$2:$AI$33,21,FALSE)),IF(C10="",0,VLOOKUP(C10,Bausteine!$A$2:$AI$33,20,FALSE))*(V10/T10/(IF(C10="",0,VLOOKUP(C10,Bausteine!$A$2:$AI$33,19,FALSE))/IF(C10="",0,VLOOKUP(C10,Bausteine!$A$2:$AI$33,18,FALSE))))^Parameter!$B$3),0)) | X10: =IF(F10="",0,VLOOKUP(F10,Bausteine!$A$2:$AI$33,14,FALSE)) | Y10: =IFERROR(IF(OR(R10<=0,T10<=0,V10<=0,U10>IF(E10="",0,VLOOKUP(E10,Bausteine!$A$2:$AI$33,12,FALSE)),T10>IF(C10="",0,VLOOKUP(C10,Bausteine!$A$2:$AI$33,22,FALSE)),IF(E10="",0,VLOOKUP(E10,Bausteine!$A$2:$AI$33,11,FALSE))<=0,IF(E10="",0,VLOOKUP(E10,Bausteine!$A$2:$AI$33,11,FALSE))>1),"UNGUELTIG","OK"),"FEHLER") | Z10: 950 | AA10: 100
A11: Battlemaster Mass Production | B11: china | C11: battlemaster-mass-produced | D11: diesel | E11: baseline-generator | F11: heavy | G11: cannon-turret | H11: cannon | I11: shell | M11: =IF(C11="",0,VLOOKUP(C11,Bausteine!$A$2:$AI$33,4,FALSE))+IF(D11="",0,VLOOKUP(D11,Bausteine!$A$2:$AI$33,4,FALSE))+IF(E11="",0,VLOOKUP(E11,Bausteine!$A$2:$AI$33,4,FALSE))+IF(F11="",0,VLOOKUP(F11,Bausteine!$A$2:$AI$33,4,FALSE))+IF(G11="",0,VLOOKUP(G11,Bausteine!$A$2:$AI$33,4,FALSE))+IF(H11="",0,VLOOKUP(H11,Bausteine!$A$2:$AI$33,4,FALSE))+IF(I11="",0,VLOOKUP(I11,Bausteine!$A$2:$AI$33,4,FALSE))+IF(J11="",0,VLOOKUP(J11,Bausteine!$A$2:$AI$33,4,FALSE))+IF(K11="",0,VLOOKUP(K11,Bausteine!$A$2:$AI$33,4,FALSE))+IF(L11="",0,VLOOKUP(L11,Bausteine!$A$2:$AI$33,4,FALSE)) | N11: =IF(C11="",0,VLOOKUP(C11,Bausteine!$A$2:$AI$33,5,FALSE))+IF(D11="",0,VLOOKUP(D11,Bausteine!$A$2:$AI$33,5,FALSE))+IF(E11="",0,VLOOKUP(E11,Bausteine!$A$2:$AI$33,5,FALSE))+IF(F11="",0,VLOOKUP(F11,Bausteine!$A$2:$AI$33,5,FALSE))+IF(G11="",0,VLOOKUP(G11,Bausteine!$A$2:$AI$33,5,FALSE))+IF(H11="",0,VLOOKUP(H11,Bausteine!$A$2:$AI$33,5,FALSE))+IF(I11="",0,VLOOKUP(I11,Bausteine!$A$2:$AI$33,5,FALSE))+IF(J11="",0,VLOOKUP(J11,Bausteine!$A$2:$AI$33,5,FALSE))+IF(K11="",0,VLOOKUP(K11,Bausteine!$A$2:$AI$33,5,FALSE))+IF(L11="",0,VLOOKUP(L11,Bausteine!$A$2:$AI$33,5,FALSE)) | O11: =MAX(IF(C11="",0,VLOOKUP(C11,Bausteine!$A$2:$AI$33,6,FALSE)),IF(D11="",0,VLOOKUP(D11,Bausteine!$A$2:$AI$33,6,FALSE)),IF(E11="",0,VLOOKUP(E11,Bausteine!$A$2:$AI$33,6,FALSE)),IF(F11="",0,VLOOKUP(F11,Bausteine!$A$2:$AI$33,6,FALSE)),IF(G11="",0,VLOOKUP(G11,Bausteine!$A$2:$AI$33,6,FALSE)),IF(H11="",0,VLOOKUP(H11,Bausteine!$A$2:$AI$33,6,FALSE)),IF(I11="",0,VLOOKUP(I11,Bausteine!$A$2:$AI$33,6,FALSE)),IF(J11="",0,VLOOKUP(J11,Bausteine!$A$2:$AI$33,6,FALSE)),IF(K11="",0,VLOOKUP(K11,Bausteine!$A$2:$AI$33,6,FALSE)),IF(L11="",0,VLOOKUP(L11,Bausteine!$A$2:$AI$33,6,FALSE))) | P11: =IF(C11="",0,VLOOKUP(C11,Bausteine!$A$2:$AI$33,7,FALSE))*IF(F11="",0,VLOOKUP(F11,Bausteine!$A$2:$AI$33,17,FALSE))/100+IF(D11="",0,VLOOKUP(D11,Bausteine!$A$2:$AI$33,7,FALSE))+IF(E11="",0,VLOOKUP(E11,Bausteine!$A$2:$AI$33,7,FALSE))+IF(G11="",0,VLOOKUP(G11,Bausteine!$A$2:$AI$33,7,FALSE))+IF(H11="",0,VLOOKUP(H11,Bausteine!$A$2:$AI$33,7,FALSE))+IF(I11="",0,VLOOKUP(I11,Bausteine!$A$2:$AI$33,7,FALSE))+IF(J11="",0,VLOOKUP(J11,Bausteine!$A$2:$AI$33,7,FALSE))+IF(K11="",0,VLOOKUP(K11,Bausteine!$A$2:$AI$33,7,FALSE))+IF(L11="",0,VLOOKUP(L11,Bausteine!$A$2:$AI$33,7,FALSE)) | Q11: =N11*Parameter!$B$2 | R11: =P11-Q11 | S11: =IF(C11="",0,VLOOKUP(C11,Bausteine!$A$2:$AI$33,13,FALSE))*IF(F11="",0,VLOOKUP(F11,Bausteine!$A$2:$AI$33,16,FALSE))/100 | T11: =IF(C11="",0,VLOOKUP(C11,Bausteine!$A$2:$AI$33,8,FALSE))*IF(F11="",0,VLOOKUP(F11,Bausteine!$A$2:$AI$33,15,FALSE))/100+IF(D11="",0,VLOOKUP(D11,Bausteine!$A$2:$AI$33,8,FALSE))+IF(E11="",0,VLOOKUP(E11,Bausteine!$A$2:$AI$33,8,FALSE))+IF(G11="",0,VLOOKUP(G11,Bausteine!$A$2:$AI$33,8,FALSE))+IF(H11="",0,VLOOKUP(H11,Bausteine!$A$2:$AI$33,8,FALSE))+IF(I11="",0,VLOOKUP(I11,Bausteine!$A$2:$AI$33,8,FALSE))+IF(J11="",0,VLOOKUP(J11,Bausteine!$A$2:$AI$33,8,FALSE))+IF(K11="",0,VLOOKUP(K11,Bausteine!$A$2:$AI$33,8,FALSE))+IF(L11="",0,VLOOKUP(L11,Bausteine!$A$2:$AI$33,8,FALSE)) | U11: =IF(C11="",0,VLOOKUP(C11,Bausteine!$A$2:$AI$33,9,FALSE))+IF(D11="",0,VLOOKUP(D11,Bausteine!$A$2:$AI$33,9,FALSE))+IF(E11="",0,VLOOKUP(E11,Bausteine!$A$2:$AI$33,9,FALSE))+IF(F11="",0,VLOOKUP(F11,Bausteine!$A$2:$AI$33,9,FALSE))+IF(G11="",0,VLOOKUP(G11,Bausteine!$A$2:$AI$33,9,FALSE))+IF(H11="",0,VLOOKUP(H11,Bausteine!$A$2:$AI$33,9,FALSE))+IF(I11="",0,VLOOKUP(I11,Bausteine!$A$2:$AI$33,9,FALSE))+IF(J11="",0,VLOOKUP(J11,Bausteine!$A$2:$AI$33,9,FALSE))+IF(K11="",0,VLOOKUP(K11,Bausteine!$A$2:$AI$33,9,FALSE))+IF(L11="",0,VLOOKUP(L11,Bausteine!$A$2:$AI$33,9,FALSE)) | V11: =IF(D11="",0,VLOOKUP(D11,Bausteine!$A$2:$AI$33,10,FALSE))-U11/IF(E11="",0,VLOOKUP(E11,Bausteine!$A$2:$AI$33,11,FALSE)) | W11: =IF(Y11<>"OK","",ROUND(MIN(IF(C11="",0,VLOOKUP(C11,Bausteine!$A$2:$AI$33,21,FALSE)),IF(C11="",0,VLOOKUP(C11,Bausteine!$A$2:$AI$33,20,FALSE))*(V11/T11/(IF(C11="",0,VLOOKUP(C11,Bausteine!$A$2:$AI$33,19,FALSE))/IF(C11="",0,VLOOKUP(C11,Bausteine!$A$2:$AI$33,18,FALSE))))^Parameter!$B$3),0)) | X11: =IF(F11="",0,VLOOKUP(F11,Bausteine!$A$2:$AI$33,14,FALSE)) | Y11: =IFERROR(IF(OR(R11<=0,T11<=0,V11<=0,U11>IF(E11="",0,VLOOKUP(E11,Bausteine!$A$2:$AI$33,12,FALSE)),T11>IF(C11="",0,VLOOKUP(C11,Bausteine!$A$2:$AI$33,22,FALSE)),IF(E11="",0,VLOOKUP(E11,Bausteine!$A$2:$AI$33,11,FALSE))<=0,IF(E11="",0,VLOOKUP(E11,Bausteine!$A$2:$AI$33,11,FALSE))>1),"UNGUELTIG","OK"),"FEHLER") | Z11: 600 | AA11: 100
