Workbook
Name ComponentIDs: 'Bausteine'!$A$2:$A$76
Name InfantryIDs: 'Infanterie'!$A$2:$A$4

Sheet Hinweise
A1: YMCA Modular – Kalibrierung
A2: Referenz | B2: Quellblock-Abgleich: 9d8a9dec (integrierter Game-Stand), siehe reference-audit.md.
A3: Status | B3: Experimentelle Zahlen; keine Spielregeln oder grafische/volle Verhaltensgleichheit.
A4: Eingaben | B4: Parameter und Bausteinwerte sind editierbar. Formeln berechnen Entwuerfe/Vergleich beim Öffnen neu.
A5: Preise | B5: Hardwarekosten minus CP-Anforderung mal globaler CP-Creditwert. Keine Sonderrabatte.
A6: Massenproduktion | B6: Separates Fertigungsmodul: vorläufig 95% aller Hardwarekosten, danach globaler CP-Abzug. Preisfit ist separate Studie.
A7: Arbeitsfluss | B7: catalog.json ist Quelle. export_excel.py erzeugt eine neue Momentaufnahme, kein Excel-Import.
A8: Schutz | B8: Exporter überschreibt keine bestehende Arbeitsmappe; für neue Daten neuen Dateinamen verwenden.
A9: Erweiterung | B9: Neue Bausteine/Designs in JSON eintragen und neu exportieren. Manuelles Zeilenanfügen wird nicht automatisch verdrahtet.
A10: Validierung | B10: Excel prüft nur elektrische/physische Grenzen; Rolle, Fraktion, Montage und Besatzungskosten-Konsistenz im Python-Rechner prüfen.
A11: Bunkerpreis | B11: Leeres Bunkermodul plus separat gewählte Startbesatzung. Infanteriepreise und Besatzungszeilen sind editierbar; Kosten/Masse werden einmal addiert.
A12: Aufsatzplatz | B12: Gatling, Bunker und Lautsprecher teilen roof. Vollständige Slot-/Fraktions-/Kapazitätsprüfung weiterhin im Python-Rechner.
A13: Grafikentwürfe | B13: Flame/Mortar Roof / draft sind nur Offline-Kalkulation. Sprites geprüft, Montage auf Overlord noch nicht. Kein Originalvergleich oder spielbarer Actor.
... A21: Referenzbedingungen | B21: Base states without isotope stability, horde, uranium or veterancy bonuses. Isotope stability now applies 90% received damage as well as death-explosion suppression; not modeled as extra HP.

Sheet Parameter
A1: Parameter | B1: Wert
A2: Credits pro CP | B2: 300
A3: Geschwindigkeitsexponent | B3: 0.5
A4: Katalogbudget | B4: 50

Sheet Bausteine
A1: ID | B1: Rolle | C1: Fraktionen | D1: Katalog-Tier | E1: CP | F1: Tech | G1: Hardwarepreis | H1: Masse kg | I1: Bedarf kWe | J1: Motor kWm | K1: Generator Wirkungsgrad | L1: Generator max kWe | M1: HP Chassis | N1: Panzerung | O1: Chassis Masse % | P1: Chassis HP % | Q1: Chassis Preis % | R1: Referenzmasse kg | S1: Referenzleistung kWm | T1: Referenztempo | U1: Max Tempo | V1: Max Masse kg | W1: Waffentraegerplaetze | X1: Zusatzplaetze | Y1: Salve | Z1: Schussabstand Ticks | AA1: Nachladen Ticks | AB1: Reichweite Zellen | AC1: Rohschaden | AD1: Hinweis | AE1: Quelle | AF1: Kompatibilitaet | AG1: Ausrüstung erlaubt | AH1: Waffen erlaubt | AI1: Munition erlaubt | AJ1: Anzeigename | AK1: Hardware Fertigung % | AL1: Munition Reichweite Override | AM1: Transportkapazitaet | AN1: Ausschluesse | AO1: Aufsatzplatz | AP1: Zusatztraeger erlaubt | AQ1: Infanterie erlaubt | AR1: Mindestreichweite Zellen | AS1: Feuerverzug Ticks | AT1: Standardfahrwerk | AU1: Fahrwerke erlaubt | AV1: Locomotor | AW1: Fahrwerkstyp | AX1: Fahrwerk Wenderate | AY1: Rumpf Wendelimit
A2: diesel-light | B2: drive | C2: ["gdi", "nod", "allies", "soviet"] | D2: 0 | E2: 0 | F2: 1 | G2: 60 | H2: 250 | I2: 0 | J2: 250 | K2: 0 | L2: 0 | M2: 0 | O2: 0 | P2: 0 | Q2: 0 | R2: 0 | S2: 0 | T2: 0 | U2: 0 | V2: 0 | W2: 0 | X2: 0 | Y2: 0 | Z2: 0 | AA2: 0 | AB2: 0 | AC2: 0 | AD2: New shared scout motor; all physical values experimental. | AJ2: Leichter Dieselmotor | AK2: 0 | AL2: 0 | AM2: 0 | AN2: 0 | AO2: 0 | AP2: 0 | AQ2: 0 | AR2: 0 | AS2: 0 | AT2: 0 | AU2: 0 | AV2: 0 | AW2: 0 | AX2: 0 | AY2: 0
A3: light | B3: armor | C3: ["gdi", "nod", "allies", "soviet"] | D3: 0 | E3: 0 | F3: 1 | G3: 0 | H3: 0 | I3: 0 | J3: 0 | K3: 0 | L3: 0 | M3: 0 | N3: Light | O3: 100 | P3: 100 | Q3: 100 | R3: 0 | S3: 0 | T3: 0 | U3: 0 | V3: 0 | W3: 0 | X3: 0 | Y3: 0 | Z3: 0 | AA3: 0 | AB3: 0 | AC3: 0 | AE3: ^LightArmor | AJ3: Leichte Panzerung | AK3: 0 | AL3: 0 | AM3: 0 | AN3: 0 | AO3: 0 | AP3: 0 | AQ3: 0 | AR3: 0 | AS3: 0 | AT3: 0 | AU3: 0 | AV3: 0 | AW3: 0 | AX3: 0 | AY3: 0
A4: scout-sensors | B4: equipment | C4: ["gdi", "nod"] | D4: 0 | E4: 0 | F4: 1 | G4: 50 | H4: 50 | I4: 5 | J4: 0 | K4: 0 | L4: 0 | M4: 0 | O4: 0 | P4: 0 | Q4: 0 | R4: 0 | S4: 0 | T4: 0 | U4: 0 | V4: 0 | W4: 0 | X4: 0 | Y4: 0 | Z4: 0 | AA4: 0 | AB4: 0 | AC4: 0 | AD4: Shared 50-credit proposal. Reuse detection/shroud traits, not detection simulated by calculator. | AE4: ^SensorEquipment | AJ4: Spähsensoren | AK4: 0 | AL4: 0 | AM4: 0 | AN4: 0 | AO4: 0 | AP4: 0 | AQ4: 0 | AR4: 0 | AS4: 0 | AT4: 0 | AU4: 0 | AV4: 0 | AW4: 0 | AX4: 0 | AY4: 0
A5: scout-mg-mount | B5: carrier | C5: ["gdi", "nod"] | D5: 0 | E5: 0 | F5: 1 | G5: 25 | H5: 100 | I5: 0 | J5: 0 | K5: 0 | L5: 0 | M5: 0 | O5: 0 | P5: 0 | Q5: 0 | R5: 0 | S5: 0 | T5: 0 | U5: 0 | V5: 0 | W5: 0 | X5: 0 | Y5: 5 | Z5: 0 | AA5: 30 | AB5: 0 | AC5: 0 | AE5: M60mgTD; HMMV / BGGY turrets | AH5: ["scout-mg"] | AJ5: Leichte MG-Lafette | AK5: 0 | AL5: 0 | AM5: 0 | AN5: 0 | AO5: 0 | AP5: 0 | AQ5: 0 | AR5: 0 | AS5: 0 | AT5: 0 | AU5: 0 | AV5: 0 | AW5: 0 | AX5: 0 | AY5: 0
A6: scout-mg | B6: weapon | C6: ["gdi", "nod"] | D6: 0 | E6: 0 | F6: 1 | G6: 65 | H6: 100 | I6: 0 | J6: 0 | K6: 0 | L6: 0 | M6: 0 | O6: 0 | P6: 0 | Q6: 0 | R6: 0 | S6: 0 | T6: 0 | U6: 0 | V6: 0 | W6: 0 | X6: 0 | Y6: 0 | Z6: 0 | AA6: 0 | AB6: 4 | AC6: 0 | AE6: M60mgTD | AI6: ["scout-mg-rounds"] | AJ6: Spähfahrzeug-MG | AK6: 0 | AL6: 0 | AM6: 0 | AN6: 0 | AO6: 0 | AP6: 0 | AQ6: 0 | AR6: 0 | AS6: 0 | AT6: 0 | AU6: 0 | AV6: 0 | AW6: 0 | AX6: 0 | AY6: 0
A7: scout-mg-rounds | B7: ammunition | C7: ["gdi", "nod"] | D7: 0 | E7: 0 | F7: 1 | G7: 25 | H7: 100 | I7: 0 | J7: 0 | K7: 0 | L7: 0 | M7: 0 | O7: 0 | P7: 0 | Q7: 0 | R7: 0 | S7: 0 | T7: 0 | U7: 0 | V7: 0 | W7: 0 | X7: 0 | Y7: 0 | Z7: 0 | AA7: 0 | AB7: 0 | AC7: 1000 | AE7: M60mgTD / ^LightMG / ^Bullet | AJ7: MG-Munition | AK7: 0 | AL7: 0 | AM7: 0 | AN7: 0 | AO7: 0 | AP7: 0 | AQ7: 0 | AR7: 0 | AS7: 0 | AT7: 0 | AU7: 0 | AV7: 0 | AW7: 0 | AX7: 0 | AY7: 0
A8: light-cannon-mount | B8: carrier | C8: ["nod", "soviet"] | D8: 0 | E8: 0 | F8: 1 | G8: 75 | H8: 500 | I8: 0 | J8: 0 | K8: 0 | L8: 0 | M8: 0 | O8: 0 | P8: 0 | Q8: 0 | R8: 0 | S8: 0 | T8: 0 | U8: 0 | V8: 0 | W8: 0 | X8: 0 | Y8: 1 | Z8: 0 | AA8: 36 | AB8: 0 | AC8: 0 | AE8: 30mm / LTNK / T-34 / Devil_Tank | AH8: ["light-cannon"] | AJ8: Leichter Kanonenturm | AK8: 0 | AL8: 0 | AM8: 0 | AN8: 0 | AO8: 0 | AP8: 0 | AQ8: 0 | AR8: 0 | AS8: 0 | AT8: 0 | AU8: 0 | AV8: 0 | AW8: 0 | AX8: 0 | AY8: 0
A9: light-cannon | B9: weapon | C9: ["nod", "soviet"] | D9: 0 | E9: 0 | F9: 1 | G9: 175 | H9: 500 | I9: 0 | J9: 0 | K9: 0 | L9: 0 | M9: 0 | O9: 0 | P9: 0 | Q9: 0 | R9: 0 | S9: 0 | T9: 0 | U9: 0 | V9: 0 | W9: 0 | X9: 0 | Y9: 0 | Z9: 0 | AA9: 0 | AB9: 4.75 | AC9: 0 | AE9: 30mm / 25mm / ^Cannon | AI9: ["light-tank-shell"] | AJ9: Leichte Panzerkanone | AK9: 0 | AL9: 0 | AM9: 0 | AN9: 0 | AO9: 0 | AP9: 0 | AQ9: 0 | AR9: 0 | AS9: 0 | AT9: 0 | AU9: 0 | AV9: 0 | AW9: 0 | AX9: 0 | AY9: 0
A10: light-tank-shell | B10: ammunition | C10: ["nod", "soviet"] | D10: 0 | E10: 0 | F10: 1 | G10: 50 | H10: 400 | I10: 0 | J10: 0 | K10: 0 | L10: 0 | M10: 0 | O10: 0 | P10: 0 | Q10: 0 | R10: 0 | S10: 0 | T10: 0 | U10: 0 | V10: 0 | W10: 0 | X10: 0 | Y10: 0 | Z10: 0 | AA10: 0 | AB10: 0 | AC10: 3500 | AD10: Existing versus table is NOT the medium ShellHeavy payload. | AE10: 30mm / ^Shell | AJ10: Leichte Panzergranaten | AK10: 0 | AL10: 0 | AM10: 0 | AN10: 0 | AO10: 0 | AP10: 0 | AQ10: 0 | AR10: 0 | AS10: 0 | AT10: 0 | AU10: 0 | AV10: 0 | AW10: 0 | AX10: 0 | AY10: 0
A11: medium-cannon-mount | B11: carrier | C11: ["gdi", "allies"] | D11: 0 | E11: 0 | F11: 1 | G11: 100 | H11: 500 | I11: 0 | J11: 0 | K11: 0 | L11: 0 | M11: 0 | O11: 0 | P11: 0 | Q11: 0 | R11: 0 | S11: 0 | T11: 0 | U11: 0 | V11: 0 | W11: 0 | X11: 0 | Y11: 1 | Z11: 0 | AA11: 50 | AB11: 0 | AC11: 0 | AE11: 90mm / 120mm | AH11: ["medium-cannon"] | AJ11: Mittlerer Kanonenturm | AK11: 0 | AL11: 0 | AM11: 0 | AN11: 0 | AO11: 0 | AP11: 0 | AQ11: 0 | AR11: 0 | AS11: 0 | AT11: 0 | AU11: 0 | AV11: 0 | AW11: 0 | AX11: 0 | AY11: 0
A12: soviet-twin-mount | B12: carrier | C12: ["soviet"] | D12: 0 | E12: 0 | F12: 2 | G12: 200 | H12: 1000 | I12: 0 | J12: 0 | K12: 0 | L12: 0 | M12: 0 | O12: 0 | P12: 0 | Q12: 0 | R12: 0 | S12: 0 | T12: 0 | U12: 0 | V12: 0 | W12: 0 | X12: 0 | Y12: 2 | Z12: 0 | AA12: 70 | AB12: 0 | AC12: 0 | AE12: 125mm / Heavy_Tank | AH12: ["medium-cannon"] | AJ12: Zwillings-Panzerkanonenturm | AK12: 0 | AL12: 0 | AM12: 0 | AN12: 0 | AO12: 0 | AP12: 0 | AQ12: 0 | AR12: 0 | AS12: 0 | AT12: 0 | AU12: 0 | AV12: 0 | AW12: 0 | AX12: 0 | AY12: 0
A13: medium-cannon | B13: weapon | C13: ["gdi", "allies", "soviet"] | D13: 0 | E13: 0 | F13: 1 | G13: 200 | H13: 500 | I13: 0 | J13: 0 | K13: 0 | L13: 0 | M13: 0 | O13: 0 | P13: 0 | Q13: 0 | R13: 0 | S13: 0 | T13: 0 | U13: 0 | V13: 0 | W13: 0 | X13: 0 | Y13: 0 | Z13: 0 | AA13: 0 | AB13: 4.75 | AC13: 0 | AD13: Shared scalar gun family. Carrier chooses single/twin cadence; full legacy source binding retains different reports and muzzle/recoil behavior. No caliber inferred for new designs. | AE13: 90mm / 120mm / 125mm | AI13: ["medium-tank-shell"] | AJ13: Mittlere Panzerkanone | AK13: 0 | AL13: 0 | AM13: 0 | AN13: 0 | AO13: 0 | AP13: 0 | AQ13: 0 | AR13: 0 | AS13: 0 | AT13: 0 | AU13: 0 | AV13: 0 | AW13: 0 | AX13: 0 | AY13: 0
A14: medium-tank-shell | B14: ammunition | C14: ["gdi", "allies", "soviet"] | D14: 0 | E14: 0 | F14: 1 | G14: 50 | H14: 400 | I14: 0 | J14: 0 | K14: 0 | L14: 0 | M14: 0 | O14: 0 | P14: 0 | Q14: 0 | R14: 0 | S14: 0 | T14: 0 | U14: 0 | V14: 0 | W14: 0 | X14: 0 | Y14: 0 | Z14: 0 | AA14: 0 | AB14: 0 | AC14: 4000 | AD14: Must reuse full existing versus/effect package; raw damage alone is not equivalence. | AE14: ^Cannon / ^ShellHeavy | AJ14: Panzergranaten gegen schwere Ziele | AK14: 0 | AL14: 0 | AM14: 0 | AN14: 0 | AO14: 0 | AP14: 0 | AQ14: 0 | AR14: 0 | AS14: 0 | AT14: 0 | AU14: 0 | AV14: 0 | AW14: 0 | AX14: 0 | AY14: 0
A15: field-artillery-mount | B15: carrier | C15: ["allies"] | D15: 0 | E15: 0 | F15: 1 | G15: 50 | H15: 500 | I15: 0 | J15: 0 | K15: 0 | L15: 0 | M15: 0 | O15: 0 | P15: 0 | Q15: 0 | R15: 0 | S15: 0 | T15: 0 | U15: 0 | V15: 0 | W15: 0 | X15: 0 | Y15: 1 | Z15: 0 | AA15: 60 | AB15: 0 | AC15: 0 | AD15: Fixed assembly, not a freely rotatable roof turret. | AE15: ARTY / AttackFrontal / 155mm | AH15: ["field-artillery"] | AJ15: Festes Artilleriegeschütz | AK15: 0 | AL15: 0 | AM15: 0 | AN15: 0 | AO15: 0 | AP15: 0 | AQ15: 0 | AR15: 0 | AS15: 0 | AT15: 0 | AU15: 0 | AV15: 0 | AW15: 0 | AX15: 0 | AY15: 0
A16: field-artillery | B16: weapon | C16: ["allies"] | D16: 0 | E16: 0 | F16: 1 | G16: 200 | H16: 700 | I16: 0 | J16: 0 | K16: 0 | L16: 0 | M16: 0 | O16: 0 | P16: 0 | Q16: 0 | R16: 0 | S16: 0 | T16: 0 | U16: 0 | V16: 0 | W16: 0 | X16: 0 | Y16: 0 | Z16: 0 | AA16: 0 | AB16: 14 | AC16: 0 | AE16: 155mm / ^Artillery / ^ShellArtillery | AI16: ["field-artillery-he"] | AJ16: Feldartillerie | AK16: 0 | AL16: 0 | AM16: 0 | AN16: 0 | AO16: 0 | AP16: 0 | AQ16: 0 | AR16: 4 | AS16: 0 | AT16: 0 | AU16: 0 | AV16: 0 | AW16: 0 | AX16: 0 | AY16: 0
A17: field-artillery-he | B17: ammunition | C17: ["allies"] | D17: 0 | E17: 0 | F17: 1 | G17: 50 | H17: 500 | I17: 0 | J17: 0 | K17: 0 | L17: 0 | M17: 0 | O17: 0 | P17: 0 | Q17: 0 | R17: 0 | S17: 0 | T17: 0 | U17: 0 | V17: 0 | W17: 0 | X17: 0 | Y17: 0 | Z17: 0 | AA17: 0 | AB17: 0 | AC17: 6500 | AD17: Not Juggernaut or mortar ammunition: preserve full projectile spread/effects and targeting. | AE17: 155mm | AJ17: Artillerie-Sprenggranaten | AK17: 0 | AL17: 0 | AM17: 0 | AN17: 0 | AO17: 0 | AP17: 0 | AQ17: 0 | AR17: 0 | AS17: 0 | AT17: 0 | AU17: 0 | AV17: 0 | AW17: 0 | AX17: 0 | AY17: 0
A18: humvee-hull | B18: chassis | C18: ["gdi"] | D18: 1 | E18: 0 | F18: 1 | G18: 125 | H18: 1600 | I18: 5 | J18: 0 | K18: 0 | L18: 0 | M18: 15000 | O18: 0 | P18: 0 | Q18: 0 | R18: 2500 | S18: 210 | T18: 157 | U18: 180 | V18: 6000 | W18: 1 | X18: 1 | Y18: 0 | Z18: 0 | AA18: 0 | AB18: 0 | AC18: 0 | AE18: HMMV | AF18: {"carrier": ["scout-mg-mount"], "drive": ["diesel-light"]} | AG18: ["scout-sensors"] | AJ18: Hum-Vee Rumpf | AK18: 0 | AL18: 0 | AM18: 0 | AN18: 0 | AO18: 0 | AP18: 0 | AQ18: 0 | AR18: 0 | AS18: 0 | AT18: wheels-light | AU18: ["wheels-light"] | AV18: 0 | AW18: 0 | AX18: 0 | AY18: 80
A19: buggy-hull | B19: chassis | C19: ["nod"] | D19: 1 | E19: 0 | F19: 1 | G19: 75 | H19: 1300 | I19: 5 | J19: 0 | K19: 0 | L19: 0 | M19: 14000 | O19: 0 | P19: 0 | Q19: 0 | R19: 2200 | S19: 210 | T19: 157 | U19: 180 | V19: 6000 | W19: 1 | X19: 1 | Y19: 0 | Z19: 0 | AA19: 0 | AB19: 0 | AC19: 0 | AE19: BGGY | AF19: {"carrier": ["scout-mg-mount"], "drive": ["diesel-light"]} | AG19: ["scout-sensors"] | AJ19: Buggy Rumpf | AK19: 0 | AL19: 0 | AM19: 0 | AN19: 0 | AO19: 0 | AP19: 0 | AQ19: 0 | AR19: 0 | AS19: 0 | AT19: wheels-light | AU19: ["wheels-light"] | AV19: 0 | AW19: 0 | AX19: 0 | AY19: 48
A20: nod-light-hull | B20: chassis | C20: ["nod"] | D20: 1 | E20: 0 | F20: 1 | G20: 125 | H20: 6500 | I20: 10 | J20: 0 | K20: 0 | L20: 0 | M20: 41250 | O20: 0 | P20: 0 | Q20: 0 | R20: 10000 | S20: 460 | T20: 100 | U20: 125 | V20: 18000 | W20: 1 | X20: 1 | Y20: 0 | Z20: 0 | AA20: 0 | AB20: 0 | AC20: 0 | AE20: LTNK | AF20: {"carrier": ["light-cannon-mount"], "drive": ["diesel"]} | AG20: [] | AJ20: Nod Leichtpanzerrumpf | AK20: 0 | AL20: 0 | AM20: 0 | AN20: 0 | AO20: 0 | AP20: 0 | AQ20: 0 | AR20: 0 | AS20: 0 | AT20: tracks-standard | AU20: ["tracks-standard"] | AV20: 0 | AW20: 0 | AX20: 0 | AY20: 48
A21: t34-hull | B21: chassis | C21: ["soviet"] | D21: 1 | E21: 0 | F21: 1 | G21: 100 | H21: 6500 | I21: 10 | J21: 0 | K21: 0 | L21: 0 | M21: 42000 | O21: 0 | P21: 0 | Q21: 0 | R21: 10000 | S21: 460 | T21: 100 | U21: 125 | V21: 18000 | W21: 1 | X21: 1 | Y21: 0 | Z21: 0 | AA21: 0 | AB21: 0 | AC21: 0 | AE21: T-34 | AF21: {"carrier": ["light-cannon-mount"], "drive": ["diesel"]} | AG21: [] | AJ21: T-34 Rumpf | AK21: 0 | AL21: 0 | AM21: 0 | AN21: 0 | AO21: 0 | AP21: 0 | AQ21: 0 | AR21: 0 | AS21: 0 | AT21: tracks-standard | AU21: ["tracks-standard"] | AV21: 0 | AW21: 0 | AX21: 0 | AY21: 48
A22: devil-hull | B22: chassis | C22: ["soviet"] | D22: 1 | E22: 0 | F22: 1 | G22: 200 | H22: 7000 | I22: 10 | J22: 0 | K22: 0 | L22: 0 | M22: 45000 | O22: 0 | P22: 0 | Q22: 0 | R22: 10500 | S22: 460 | T22: 90 | U22: 115 | V22: 18000 | W22: 1 | X22: 1 | Y22: 0 | Z22: 0 | AA22: 0 | AB22: 0 | AC22: 0 | AE22: Devil_Tank | AF22: {"carrier": ["light-cannon-mount"], "drive": ["diesel"]} | AG22: [] | AJ22: Devil-Tank Rumpf | AK22: 0 | AL22: 0 | AM22: 0 | AN22: 0 | AO22: 0 | AP22: 0 | AQ22: 0 | AR22: 0 | AS22: 0 | AT22: tracks-standard | AU22: ["tracks-standard"] | AV22: 0 | AW22: 0 | AX22: 0 | AY22: 48
A23: gdi-battle-hull | B23: chassis | C23: ["gdi"] | D23: 1 | E23: 0 | F23: 1 | G23: 350 | H23: 8000 | I23: 10 | J23: 0 | K23: 0 | L23: 0 | M23: 52000 | O23: 0 | P23: 0 | Q23: 0 | R23: 11500 | S23: 460 | T23: 82 | U23: 110 | V23: 20000 | W23: 1 | X23: 1 | Y23: 0 | Z23: 0 | AA23: 0 | AB23: 0 | AC23: 0 | AE23: MTNK | AF23: {"carrier": ["medium-cannon-mount"], "drive": ["diesel"]} | AG23: [] | AJ23: GDI Kampfpanzer-Rumpf | AK23: 0 | AL23: 0 | AM23: 0 | AN23: 0 | AO23: 0 | AP23: 0 | AQ23: 0 | AR23: 0 | AS23: 0 | AT23: tracks-standard | AU23: ["tracks-standard"] | AV23: 0 | AW23: 0 | AX23: 0 | AY23: 48
A24: allied-medium-hull | B24: chassis | C24: ["allies"] | D24: 1 | E24: 0 | F24: 1 | G24: 250 | H24: 7500 | I24: 10 | J24: 0 | K24: 0 | L24: 0 | M24: 45000 | O24: 0 | P24: 0 | Q24: 0 | R24: 11000 | S24: 460 | T24: 82 | U24: 110 | V24: 20000 | W24: 1 | X24: 1 | Y24: 0 | Z24: 0 | AA24: 0 | AB24: 0 | AC24: 0 | AD24: Shared scalar hull family for Challenger/Leclerc/Leopard; artwork remains bound to complete actor variant. 2TNK itself is not buildable. | AE24: 2TNK | AF24: {"carrier": ["medium-cannon-mount"], "drive": ["diesel"]} | AG24: [] | AJ24: Alliierter Kampfpanzer-Rumpf | AK24: 0 | AL24: 0 | AM24: 0 | AN24: 0 | AO24: 0 | AP24: 0 | AQ24: 0 | AR24: 0 | AS24: 0 | AT24: tracks-standard | AU24: ["tracks-standard"] | AV24: 0 | AW24: 0 | AX24: 0 | AY24: 48
A25: soviet-heavy-hull | B25: chassis | C25: ["soviet"] | D25: 2 | E25: 0 | F25: 2 | G25: 450 | H25: 11000 | I25: 10 | J25: 0 | K25: 0 | L25: 0 | M25: 65000 | O25: 0 | P25: 0 | Q25: 0 | R25: 15000 | S25: 460 | T25: 68 | U25: 95 | V25: 20000 | W25: 1 | X25: 2 | Y25: 0 | Z25: 0 | AA25: 0 | AB25: 0 | AC25: 0 | AE25: Heavy_Tank | AF25: {"carrier": ["soviet-twin-mount"], "drive": ["diesel"]} | AG25: [] | AJ25: Sowjetischer schwerer Panzerrumpf | AK25: 0 | AL25: 0 | AM25: 0 | AN25: 0 | AO25: 0 | AP25: 0 | AQ25: 0 | AR25: 0 | AS25: 0 | AT25: tracks-standard | AU25: ["tracks-standard"] | AV25: 0 | AW25: 0 | AX25: 0 | AY25: 48
A26: field-artillery-hull | B26: chassis | C26: ["allies"] | D26: 1 | E26: 0 | F26: 1 | G26: 75 | H26: 5000 | I26: 10 | J26: 0 | K26: 0 | L26: 0 | M26: 10000 | O26: 0 | P26: 0 | Q26: 0 | R26: 8300 | S26: 460 | T26: 56 | U26: 80 | V26: 14000 | W26: 1 | X26: 1 | Y26: 0 | Z26: 0 | AA26: 0 | AB26: 0 | AC26: 0 | AD26: Light armor despite tracked graphics. Fixed hull/gun artwork, no free turret replacement. | AE26: ARTY | AF26: {"carrier": ["field-artillery-mount"], "drive": ["diesel"]} | AG26: [] | AJ26: Leichter Artillerierumpf | AK26: 0 | AL26: 0 | AM26: 0 | AN26: 0 | AO26: 0 | AP26: 0 | AQ26: 0 | AR26: 0 | AS26: 0 | AT26: tracks-light-artillery | AU26: ["tracks-light-artillery"] | AV26: 0 | AW26: 0 | AX26: 0 | AY26: 16
A27: tracks-standard | B27: running_gear | C27: ["china", "gdi", "nod", "allies", "soviet"] | D27: 0 | E27: 0 | F27: 1 | G27: 100 | H27: 1500 | I27: 0 | J27: 0 | K27: 0 | L27: 0 | M27: 0 | O27: 0 | P27: 0 | Q27: 0 | R27: 0 | S27: 0 | T27: 0 | U27: 150 | V27: 20000 | W27: 0 | X27: 0 | Y27: 0 | Z27: 0 | AA27: 0 | AB27: 0 | AC27: 0 | AD27: Shared provisional mechanical allocation removed from old hull values, not an extra retrofit charge. Engine movement template unchanged; hull limits turning. | AJ27: Standard-Kettenlaufwerk | AK27: 0 | AL27: 0 | AM27: 0 | AN27: 0 | AO27: 0 | AP27: 0 | AQ27: 0 | AR27: 0 | AS27: 0 | AT27: 0 | AU27: 0 | AV27: tracked | AW27: tracks | AX27: 64 | AY27: 0
A28: tracks-superheavy | B28: running_gear | C28: ["china", "gdi", "soviet"] | D28: 0 | E28: 0 | F28: 2 | G28: 250 | H28: 5000 | I28: 0 | J28: 0 | K28: 0 | L28: 0 | M28: 0 | O28: 0 | P28: 0 | Q28: 0 | R28: 0 | S28: 0 | T28: 0 | U28: 90 | V28: 45000 | W28: 0 | X28: 0 | Y28: 0 | Z28: 0 | AA28: 0 | AB28: 0 | AC28: 0 | AJ28: Schwerlast-Kettenlaufwerk | AK28: 0 | AL28: 0 | AM28: 0 | AN28: 0 | AO28: 0 | AP28: 0 | AQ28: 0 | AR28: 0 | AS28: 0 | AT28: 0 | AU28: 0 | AV28: sheavytracked | AW28: tracks | AX28: 16 | AY28: 0
A29: walker-heavy | B29: running_gear | C29: ["gdi"] | D29: 0 | E29: 0 | F29: 3 | G29: 300 | H29: 3500 | I29: 0 | J29: 0 | K29: 0 | L29: 0 | M29: 0 | O29: 0 | P29: 0 | Q29: 0 | R29: 0 | S29: 0 | T29: 0 | U29: 50 | V29: 30000 | W29: 0 | X29: 0 | Y29: 0 | Z29: 0 | AA29: 0 | AB29: 0 | AC29: 0 | AD29: Juggernaut physically walks, but its existing engine Locomotor is sheavytracked. Artwork does not determine locomotor semantics. | AJ29: Schweres Schreitwerk | AK29: 0 | AL29: 0 | AM29: 0 | AN29: 0 | AO29: 0 | AP29: 0 | AQ29: 0 | AR29: 0 | AS29: 0 | AT29: 0 | AU29: 0 | AV29: sheavytracked | AW29: walker | AX29: 16 | AY29: 0
A30: wheels-light | B30: running_gear | C30: ["gdi", "nod", "allies", "soviet"] | D30: 0 | E30: 0 | F30: 1 | G30: 50 | H30: 300 | I30: 0 | J30: 0 | K30: 0 | L30: 0 | M30: 0 | O30: 0 | P30: 0 | Q30: 0 | R30: 0 | S30: 0 | T30: 0 | U30: 180 | V30: 6000 | W30: 0 | X30: 0 | Y30: 0 | Z30: 0 | AA30: 0 | AB30: 0 | AC30: 0 | AJ30: Leichtes Radfahrwerk | AK30: 0 | AL30: 0 | AM30: 0 | AN30: 0 | AO30: 0 | AP30: 0 | AQ30: 0 | AR30: 0 | AS30: 0 | AT30: 0 | AU30: 0 | AV30: wheeled | AW30: wheels | AX30: 80 | AY30: 0
A31: tracks-light-artillery | B31: running_gear | C31: ["allies"] | D31: 0 | E31: 0 | F31: 1 | G31: 75 | H31: 1000 | I31: 0 | J31: 0 | K31: 0 | L31: 0 | M31: 0 | O31: 0 | P31: 0 | Q31: 0 | R31: 0 | S31: 0 | T31: 0 | U31: 130 | V31: 14000 | W31: 0 | X31: 0 | Y31: 0 | Z31: 0 | AA31: 0 | AB31: 0 | AC31: 0 | AD31: No infantry crush: exact existing lighttracked locomotor, not ordinary tracked. | AJ31: Leichtes Kettenlaufwerk | AK31: 0 | AL31: 0 | AM31: 0 | AN31: 0 | AO31: 0 | AP31: 0 | AQ31: 0 | AR31: 0 | AS31: 0 | AT31: 0 | AU31: 0 | AV31: lighttracked | AW31: tracks | AX31: 64 | AY31: 0
A32: mortar-roof-carrier | B32: carrier | C32: ["china"] | D32: 1 | E32: 0 | F32: 3 | G32: 200 | H32: 400 | I32: 2 | J32: 0 | K32: 0 | L32: 0 | M32: 0 | O32: 0 | P32: 0 | Q32: 0 | R32: 0 | S32: 0 | T32: 0 | U32: 0 | V32: 0 | W32: 0 | X32: 0 | Y32: 1 | Z32: 0 | AA32: 60 | AB32: 0 | AC32: 0 | AD32: Experimental China gameplay carrier using existing artillery artwork, not Allied weapon access. Proposed 200-credit mount, 12 turn speed. Offset, scale, recoil and muzzle on Overlord not live-tested; infantry Mortar FireDelay 15 retained as a trial. | AE32: batf.artillery.turret / artytur.shp | AH32: ["roof-mortar"] | AJ32: Leichter Artillerie-Aufsatzturm | AK32: 0 | AL32: 0 | AM32: 0 | AN32: 0 | AO32: 0 | AP32: 0 | AQ32: 0 | AR32: 0 | AS32: 15 | AT32: 0 | AU32: 0 | AV32: 0 | AW32: 0 | AX32: 0 | AY32: 0
A33: roof-mortar | B33: weapon | C33: ["china"] | D33: 1 | E33: 0 | F33: 3 | G33: 350 | H33: 600 | I33: 3 | J33: 0 | K33: 0 | L33: 0 | M33: 0 | O33: 0 | P33: 0 | Q33: 0 | R33: 0 | S33: 0 | T33: 0 | U33: 0 | V33: 0 | W33: 0 | X33: 0 | Y33: 0 | Z33: 0 | AA33: 0 | AB33: 11 | AC33: 0 | AD33: Existing BulletCA: speed 166, launch angle 92, inaccuracy 768, BOMB image. New vehicle price, mass and power are proposals, not inferred from 150-credit infantry. | AE33: Mortar / MortarPrototype | AI33: ["mortar-he"] | AJ33: Leichter Fahrzeugmoerser | AK33: 0 | AL33: 0 | AM33: 0 | AN33: 0 | AO33: 0 | AP33: 0 | AQ33: 0 | AR33: 1 | AS33: 0 | AT33: 0 | AU33: 0 | AV33: 0 | AW33: 0 | AX33: 0 | AY33: 0
A34: mortar-he | B34: ammunition | C34: ["china"] | D34: 0 | E34: 0 | F34: 3 | G34: 100 | H34: 300 | I34: 0 | J34: 0 | K34: 0 | L34: 0 | M34: 0 | O34: 0 | P34: 0 | Q34: 0 | R34: 0 | S34: 0 | T34: 0 | U34: 0 | V34: 0 | W34: 0 | X34: 0 | Y34: 0 | Z34: 0 | AA34: 0 | AB34: 0 | AC34: 5500 | AD34: Raw primary damage only, not DPS. Full impact/smudge/water effects belong to existing payload template; no compiler yet. | AE34: MortarPrototype | AJ34: Moerser-Sprenggranaten | AK34: 0 | AL34: 0 | AM34: 0 | AN34: 0 | AO34: 0 | AP34: 0 | AQ34: 0 | AR34: 0 | AS34: 0 | AT34: 0 | AU34: 0 | AV34: 0 | AW34: 0 | AX34: 0 | AY34: 0
A35: overlord-chassis | B35: chassis | C35: ["china"] | D35: 3 | E35: 0 | F35: 2 | G35: 750 | H35: 20000 | I35: 10 | J35: 0 | K35: 0 | L35: 0 | M35: 95000 | O35: 0 | P35: 0 | Q35: 0 | R35: 32000 | S35: 960 | T35: 56 | U35: 70 | V35: 45000 | W35: 2 | X35: 3 | Y35: 0 | Z35: 0 | AA35: 0 | AB35: 0 | AC35: 0 | AD35: Main heavy carrier plus shared roof slot for an approved auxiliary carrier, bunker or speaker. Emperor 80% received-damage modifier is excluded from base state. | AE35: choverlord | AF35: {"carrier": ["heavy-twin-turret"], "drive": ["diesel-heavy", "diesel-heavy-boost"]} | AG35: ["pdl", "propaganda-speaker", "firing-bunker"] | AJ35: Schwerer Rumpf (Overlord) | AK35: 0 | AL35: 0 | AM35: 0 | AN35: 0 | AO35: 0 | AP35: {"slot": "roof", "carriers": ["gatling-roof-carrier"], "experimental_carriers": ["flame-turret", "mortar-roof-carrier"]} | AQ35: 0 | AR35: 0 | AS35: 0 | AT35: tracks-superheavy | AU35: ["tracks-superheavy"] | AV35: 0 | AW35: 0 | AX35: 0 | AY35: 8
A36: diesel-heavy | B36: drive | C36: ["china", "gdi", "soviet"] | D36: 1 | E36: 0 | F36: 2 | G36: 300 | H36: 2000 | I36: 0 | J36: 1000 | K36: 0 | L36: 0 | M36: 0 | O36: 0 | P36: 0 | Q36: 0 | R36: 0 | S36: 0 | T36: 0 | U36: 0 | V36: 0 | W36: 0 | X36: 0 | Y36: 0 | Z36: 0 | AA36: 0 | AB36: 0 | AC36: 0 | AD36: New provisional heavy family, not a formula derived from engine size. | AJ36: Schwerer Dieselmotor | AK36: 0 | AL36: 0 | AM36: 0 | AN36: 0 | AO36: 0 | AP36: 0 | AQ36: 0 | AR36: 0 | AS36: 0 | AT36: 0 | AU36: 0 | AV36: 0 | AW36: 0 | AX36: 0 | AY36: 0
A37: diesel-heavy-boost | B37: drive | C37: ["china", "gdi", "soviet"] | D37: 2 | E37: 0 | F37: 2 | G37: 400 | H37: 2000 | I37: 0 | J37: 1045 | K37: 0 | L37: 0 | M37: 0 | O37: 0 | P37: 0 | Q37: 0 | R37: 0 | S37: 0 | T37: 0 | U37: 0 | V37: 0 | W37: 0 | X37: 0 | Y37: 0 | Z37: 0 | AA37: 0 | AB37: 0 | AC37: 0 | AJ37: Leistungsgesteigerter schwerer Dieselmotor | AK37: 0 | AL37: 0 | AM37: 0 | AN37: 0 | AO37: 0 | AP37: 0 | AQ37: 0 | AR37: 0 | AS37: 0 | AT37: 0 | AU37: 0 | AV37: 0 | AW37: 0 | AX37: 0 | AY37: 0
A38: heavy-twin-turret | B38: carrier | C38: ["china"] | D38: 0 | E38: 0 | F38: 2 | G38: 250 | H38: 2000 | I38: 0 | J38: 0 | K38: 0 | L38: 0 | M38: 0 | O38: 0 | P38: 0 | Q38: 0 | R38: 0 | S38: 0 | T38: 0 | U38: 0 | V38: 0 | W38: 0 | X38: 0 | Y38: 2 | Z38: 6 | AA38: 90 | AB38: 0 | AC38: 0 | AD38: Normal, nuclear and speaker artwork bindings must select appropriate existing turret sequences; no claim of arbitrary visual interchangeability. | AE38: OverlordCannon | AH38: ["overlord-cannon"] | AJ38: Schwerer Zwillingsgeschützturm | AK38: 0 | AL38: 0 | AM38: 0 | AN38: 0 | AO38: 0 | AP38: 0 | AQ38: 0 | AR38: 0 | AS38: 0 | AT38: 0 | AU38: 0 | AV38: 0 | AW38: 0 | AX38: 0 | AY38: 0
A39: overlord-cannon | B39: weapon | C39: ["china"] | D39: 0 | E39: 0 | F39: 2 | G39: 300 | H39: 1500 | I39: 0 | J39: 0 | K39: 0 | L39: 0 | M39: 0 | O39: 0 | P39: 0 | Q39: 0 | R39: 0 | S39: 0 | T39: 0 | U39: 0 | V39: 0 | W39: 0 | X39: 0 | Y39: 0 | Z39: 0 | AA39: 0 | AB39: 5 | AC39: 0 | AE39: OverlordCannon | AI39: ["heavy-shell", "heavy-nuclear-shell"] | AJ39: Schwere Panzerkanone | AK39: 0 | AL39: 0 | AM39: 0 | AN39: 0 | AO39: 0 | AP39: 0 | AQ39: 0 | AR39: 0 | AS39: 0 | AT39: 0 | AU39: 0 | AV39: 0 | AW39: 0 | AX39: 0 | AY39: 0
A40: heavy-shell | B40: ammunition | C40: ["china"] | D40: 0 | E40: 0 | F40: 2 | G40: 150 | H40: 1500 | I40: 0 | J40: 0 | K40: 0 | L40: 0 | M40: 0 | O40: 0 | P40: 0 | Q40: 0 | R40: 0 | S40: 0 | T40: 0 | U40: 0 | V40: 0 | W40: 0 | X40: 0 | Y40: 0 | Z40: 0 | AA40: 0 | AB40: 0 | AC40: 8000 | AE40: OverlordCannon | AJ40: Schwere Panzergranaten | AK40: 0 | AL40: 0 | AM40: 0 | AN40: 0 | AO40: 0 | AP40: 0 | AQ40: 0 | AR40: 0 | AS40: 0 | AT40: 0 | AU40: 0 | AV40: 0 | AW40: 0 | AX40: 0 | AY40: 0
...

Sheet Infanterie
A1: ID | B1: Name | C1: Fraktionen | D1: Preis | E1: Masse kg | F1: Transportgewicht | G1: Tech
A2: che3 | B2: Tank Hunter | C2: china | D2: 300 | E2: 100 | F2: 1 | G2: 1
A3: che1 | B3: Red Guard | C3: china | D3: 80 | E3: 100 | F3: 1 | G3: 1
A4: minigunner | B4: Minigunner | C4: china | D4: 200 | E4: 100 | F4: 1 | G4: 1

Sheet Startbesatzung
A1: Design | B1: Infanterie | C1: Anzahl | D1: Preis | E1: Masse kg | F1: Transportgewicht | G1: Tech
A2: Overlord Bunker / mixed crew | B2: che3 | C2: 2 | D2: =C2*VLOOKUP(B2,Infanterie!$A$2:$G$4,4,FALSE) | E2: =C2*VLOOKUP(B2,Infanterie!$A$2:$G$4,5,FALSE) | F2: =C2*VLOOKUP(B2,Infanterie!$A$2:$G$4,6,FALSE) | G2: =IF(C2>0,VLOOKUP(B2,Infanterie!$A$2:$G$4,7,FALSE),0)
A3: Overlord Bunker / mixed crew | B3: che1 | C3: 2 | D3: =C3*VLOOKUP(B3,Infanterie!$A$2:$G$4,4,FALSE) | E3: =C3*VLOOKUP(B3,Infanterie!$A$2:$G$4,5,FALSE) | F3: =C3*VLOOKUP(B3,Infanterie!$A$2:$G$4,6,FALSE) | G3: =IF(C3>0,VLOOKUP(B3,Infanterie!$A$2:$G$4,7,FALSE),0)
A4: Overlord Bunker / partial crew | B4: minigunner | C4: 2 | D4: =C4*VLOOKUP(B4,Infanterie!$A$2:$G$4,4,FALSE) | E4: =C4*VLOOKUP(B4,Infanterie!$A$2:$G$4,5,FALSE) | F4: =C4*VLOOKUP(B4,Infanterie!$A$2:$G$4,6,FALSE) | G4: =IF(C4>0,VLOOKUP(B4,Infanterie!$A$2:$G$4,7,FALSE),0)
A5: Overlord Bunker | B5: che3 | C5: 4 | D5: =C5*VLOOKUP(B5,Infanterie!$A$2:$G$4,4,FALSE) | E5: =C5*VLOOKUP(B5,Infanterie!$A$2:$G$4,5,FALSE) | F5: =C5*VLOOKUP(B5,Infanterie!$A$2:$G$4,6,FALSE) | G5: =IF(C5>0,VLOOKUP(B5,Infanterie!$A$2:$G$4,7,FALSE),0)
A6: Overlord Bunker PDL | B6: che3 | C6: 4 | D6: =C6*VLOOKUP(B6,Infanterie!$A$2:$G$4,4,FALSE) | E6: =C6*VLOOKUP(B6,Infanterie!$A$2:$G$4,5,FALSE) | F6: =C6*VLOOKUP(B6,Infanterie!$A$2:$G$4,6,FALSE) | G6: =IF(C6>0,VLOOKUP(B6,Infanterie!$A$2:$G$4,7,FALSE),0)
A7: Overlord Bunker Reflector | B7: che3 | C7: 4 | D7: =C7*VLOOKUP(B7,Infanterie!$A$2:$G$4,4,FALSE) | E7: =C7*VLOOKUP(B7,Infanterie!$A$2:$G$4,5,FALSE) | F7: =C7*VLOOKUP(B7,Infanterie!$A$2:$G$4,6,FALSE) | G7: =IF(C7>0,VLOOKUP(B7,Infanterie!$A$2:$G$4,7,FALSE),0)

Sheet Entwuerfe
A1: Design | B1: Fraktion | C1: Chassis | D1: Motor | E1: Generator | F1: Panzerung | G1: Traeger | H1: Waffe | I1: Munition | J1: Zusatz 1 | K1: Zusatz 2 | L1: Zusatz 3 | M1: Katalog | N1: CP | O1: Tech | P1: Hardware | Q1: CP-Abzug | R1: Preis | S1: HP | T1: Masse kg | U1: Last kWe | V1: Rest kWm | W1: Tempo | X1: Armor | Y1: Grenzen | Z1: Python Preis | AA1: Python Tempo | AB1: Referenzhinweis | AC1: Fertigungsmodul | AD1: Fertigungsfaktor | AE1: Hardware nach Fertigung | AF1: Aufsatztraeger | AG1: Aufsatzwaffe | AH1: Aufsatzmunition | AI1: Besatzungspreis | AJ1: Besatzungsmasse | AK1: Besatzungstech | AL1: Aufsatz Reichweite | AM1: Aufsatz Mindestreichweite | AN1: Aufsatz Reload Ticks | AO1: Aufsatz Salve | AP1: Aufsatz Rohschaden | AQ1: Fahrwerk | AR1: Locomotor | AS1: Wenderate
A2: Hum-Vee baseline | B2: gdi | C2: humvee-hull | D2: diesel-light | E2: baseline-generator | F2: light | G2: scout-mg-mount | H2: scout-mg | I2: scout-mg-rounds | J2: scout-sensors | M2: =IF(C2="",0,VLOOKUP(C2,Bausteine!$A$2:$AY$76,4,FALSE))+IF(D2="",0,VLOOKUP(D2,Bausteine!$A$2:$AY$76,4,FALSE))+IF(E2="",0,VLOOKUP(E2,Bausteine!$A$2:$AY$76,4,FALSE))+IF(F2="",0,VLOOKUP(F2,Bausteine!$A$2:$AY$76,4,FALSE))+IF(G2="",0,VLOOKUP(G2,Bausteine!$A$2:$AY$76,4,FALSE))+IF(H2="",0,VLOOKUP(H2,Bausteine!$A$2:$AY$76,4,FALSE))+IF(I2="",0,VLOOKUP(I2,Bausteine!$A$2:$AY$76,4,FALSE))+IF(J2="",0,VLOOKUP(J2,Bausteine!$A$2:$AY$76,4,FALSE))+IF(K2="",0,VLOOKUP(K2,Bausteine!$A$2:$AY$76,4,FALSE))+IF(L2="",0,VLOOKUP(L2,Bausteine!$A$2:$AY$76,4,FALSE))+IF(AC2="",0,VLOOKUP(AC2,Bausteine!$A$2:$AY$76,4,FALSE))+IF(AF2="",0,VLOOKUP(AF2,Bausteine!$A$2:$AY$76,4,FALSE))+IF(AG2="",0,VLOOKUP(AG2,Bausteine!$A$2:$AY$76,4,FALSE))+IF(AH2="",0,VLOOKUP(AH2,Bausteine!$A$2:$AY$76,4,FALSE))+IF(AQ2="",0,VLOOKUP(AQ2,Bausteine!$A$2:$AY$76,4,FALSE)) | N2: =IF(C2="",0,VLOOKUP(C2,Bausteine!$A$2:$AY$76,5,FALSE))+IF(D2="",0,VLOOKUP(D2,Bausteine!$A$2:$AY$76,5,FALSE))+IF(E2="",0,VLOOKUP(E2,Bausteine!$A$2:$AY$76,5,FALSE))+IF(F2="",0,VLOOKUP(F2,Bausteine!$A$2:$AY$76,5,FALSE))+IF(G2="",0,VLOOKUP(G2,Bausteine!$A$2:$AY$76,5,FALSE))+IF(H2="",0,VLOOKUP(H2,Bausteine!$A$2:$AY$76,5,FALSE))+IF(I2="",0,VLOOKUP(I2,Bausteine!$A$2:$AY$76,5,FALSE))+IF(J2="",0,VLOOKUP(J2,Bausteine!$A$2:$AY$76,5,FALSE))+IF(K2="",0,VLOOKUP(K2,Bausteine!$A$2:$AY$76,5,FALSE))+IF(L2="",0,VLOOKUP(L2,Bausteine!$A$2:$AY$76,5,FALSE))+IF(AC2="",0,VLOOKUP(AC2,Bausteine!$A$2:$AY$76,5,FALSE))+IF(AF2="",0,VLOOKUP(AF2,Bausteine!$A$2:$AY$76,5,FALSE))+IF(AG2="",0,VLOOKUP(AG2,Bausteine!$A$2:$AY$76,5,FALSE))+IF(AH2="",0,VLOOKUP(AH2,Bausteine!$A$2:$AY$76,5,FALSE))+IF(AQ2="",0,VLOOKUP(AQ2,Bausteine!$A$2:$AY$76,5,FALSE)) | O2: =MAX(IF(C2="",0,VLOOKUP(C2,Bausteine!$A$2:$AY$76,6,FALSE)),IF(D2="",0,VLOOKUP(D2,Bausteine!$A$2:$AY$76,6,FALSE)),IF(E2="",0,VLOOKUP(E2,Bausteine!$A$2:$AY$76,6,FALSE)),IF(F2="",0,VLOOKUP(F2,Bausteine!$A$2:$AY$76,6,FALSE)),IF(G2="",0,VLOOKUP(G2,Bausteine!$A$2:$AY$76,6,FALSE)),IF(H2="",0,VLOOKUP(H2,Bausteine!$A$2:$AY$76,6,FALSE)),IF(I2="",0,VLOOKUP(I2,Bausteine!$A$2:$AY$76,6,FALSE)),IF(J2="",0,VLOOKUP(J2,Bausteine!$A$2:$AY$76,6,FALSE)),IF(K2="",0,VLOOKUP(K2,Bausteine!$A$2:$AY$76,6,FALSE)),IF(L2="",0,VLOOKUP(L2,Bausteine!$A$2:$AY$76,6,FALSE)),IF(AC2="",0,VLOOKUP(AC2,Bausteine!$A$2:$AY$76,6,FALSE)),IF(AF2="",0,VLOOKUP(AF2,Bausteine!$A$2:$AY$76,6,FALSE)),IF(AG2="",0,VLOOKUP(AG2,Bausteine!$A$2:$AY$76,6,FALSE)),IF(AH2="",0,VLOOKUP(AH2,Bausteine!$A$2:$AY$76,6,FALSE)),IF(AQ2="",0,VLOOKUP(AQ2,Bausteine!$A$2:$AY$76,6,FALSE)),AK2) | P2: =IF(C2="",0,VLOOKUP(C2,Bausteine!$A$2:$AY$76,7,FALSE))*IF(F2="",0,VLOOKUP(F2,Bausteine!$A$2:$AY$76,17,FALSE))/100+IF(D2="",0,VLOOKUP(D2,Bausteine!$A$2:$AY$76,7,FALSE))+IF(E2="",0,VLOOKUP(E2,Bausteine!$A$2:$AY$76,7,FALSE))+IF(G2="",0,VLOOKUP(G2,Bausteine!$A$2:$AY$76,7,FALSE))+IF(H2="",0,VLOOKUP(H2,Bausteine!$A$2:$AY$76,7,FALSE))+IF(I2="",0,VLOOKUP(I2,Bausteine!$A$2:$AY$76,7,FALSE))+IF(J2="",0,VLOOKUP(J2,Bausteine!$A$2:$AY$76,7,FALSE))+IF(K2="",0,VLOOKUP(K2,Bausteine!$A$2:$AY$76,7,FALSE))+IF(L2="",0,VLOOKUP(L2,Bausteine!$A$2:$AY$76,7,FALSE))+IF(AC2="",0,VLOOKUP(AC2,Bausteine!$A$2:$AY$76,7,FALSE))+IF(AF2="",0,VLOOKUP(AF2,Bausteine!$A$2:$AY$76,7,FALSE))+IF(AG2="",0,VLOOKUP(AG2,Bausteine!$A$2:$AY$76,7,FALSE))+IF(AH2="",0,VLOOKUP(AH2,Bausteine!$A$2:$AY$76,7,FALSE))+IF(AQ2="",0,VLOOKUP(AQ2,Bausteine!$A$2:$AY$76,7,FALSE))+AI2 | Q2: =N2*Parameter!$B$2 | R2: =AE2-Q2 | S2: =IF(C2="",0,VLOOKUP(C2,Bausteine!$A$2:$AY$76,13,FALSE))*IF(F2="",0,VLOOKUP(F2,Bausteine!$A$2:$AY$76,16,FALSE))/100 | T2: =IF(C2="",0,VLOOKUP(C2,Bausteine!$A$2:$AY$76,8,FALSE))*IF(F2="",0,VLOOKUP(F2,Bausteine!$A$2:$AY$76,15,FALSE))/100+IF(D2="",0,VLOOKUP(D2,Bausteine!$A$2:$AY$76,8,FALSE))+IF(E2="",0,VLOOKUP(E2,Bausteine!$A$2:$AY$76,8,FALSE))+IF(G2="",0,VLOOKUP(G2,Bausteine!$A$2:$AY$76,8,FALSE))+IF(H2="",0,VLOOKUP(H2,Bausteine!$A$2:$AY$76,8,FALSE))+IF(I2="",0,VLOOKUP(I2,Bausteine!$A$2:$AY$76,8,FALSE))+IF(J2="",0,VLOOKUP(J2,Bausteine!$A$2:$AY$76,8,FALSE))+IF(K2="",0,VLOOKUP(K2,Bausteine!$A$2:$AY$76,8,FALSE))+IF(L2="",0,VLOOKUP(L2,Bausteine!$A$2:$AY$76,8,FALSE))+IF(AC2="",0,VLOOKUP(AC2,Bausteine!$A$2:$AY$76,8,FALSE))+IF(AF2="",0,VLOOKUP(AF2,Bausteine!$A$2:$AY$76,8,FALSE))+IF(AG2="",0,VLOOKUP(AG2,Bausteine!$A$2:$AY$76,8,FALSE))+IF(AH2="",0,VLOOKUP(AH2,Bausteine!$A$2:$AY$76,8,FALSE))+IF(AQ2="",0,VLOOKUP(AQ2,Bausteine!$A$2:$AY$76,8,FALSE))+AJ2 | U2: =IF(C2="",0,VLOOKUP(C2,Bausteine!$A$2:$AY$76,9,FALSE))+IF(D2="",0,VLOOKUP(D2,Bausteine!$A$2:$AY$76,9,FALSE))+IF(E2="",0,VLOOKUP(E2,Bausteine!$A$2:$AY$76,9,FALSE))+IF(F2="",0,VLOOKUP(F2,Bausteine!$A$2:$AY$76,9,FALSE))+IF(G2="",0,VLOOKUP(G2,Bausteine!$A$2:$AY$76,9,FALSE))+IF(H2="",0,VLOOKUP(H2,Bausteine!$A$2:$AY$76,9,FALSE))+IF(I2="",0,VLOOKUP(I2,Bausteine!$A$2:$AY$76,9,FALSE))+IF(J2="",0,VLOOKUP(J2,Bausteine!$A$2:$AY$76,9,FALSE))+IF(K2="",0,VLOOKUP(K2,Bausteine!$A$2:$AY$76,9,FALSE))+IF(L2="",0,VLOOKUP(L2,Bausteine!$A$2:$AY$76,9,FALSE))+IF(AC2="",0,VLOOKUP(AC2,Bausteine!$A$2:$AY$76,9,FALSE))+IF(AF2="",0,VLOOKUP(AF2,Bausteine!$A$2:$AY$76,9,FALSE))+IF(AG2="",0,VLOOKUP(AG2,Bausteine!$A$2:$AY$76,9,FALSE))+IF(AH2="",0,VLOOKUP(AH2,Bausteine!$A$2:$AY$76,9,FALSE))+IF(AQ2="",0,VLOOKUP(AQ2,Bausteine!$A$2:$AY$76,9,FALSE)) | V2: =IF(D2="",0,VLOOKUP(D2,Bausteine!$A$2:$AY$76,10,FALSE))-U2/IF(E2="",0,VLOOKUP(E2,Bausteine!$A$2:$AY$76,11,FALSE)) | W2: =IF(Y2<>"OK","",ROUND(MIN(IF(C2="",0,VLOOKUP(C2,Bausteine!$A$2:$AY$76,21,FALSE)),IF(AQ2="",0,VLOOKUP(AQ2,Bausteine!$A$2:$AY$76,21,FALSE)),IF(C2="",0,VLOOKUP(C2,Bausteine!$A$2:$AY$76,20,FALSE))*(V2/T2/(IF(C2="",0,VLOOKUP(C2,Bausteine!$A$2:$AY$76,19,FALSE))/IF(C2="",0,VLOOKUP(C2,Bausteine!$A$2:$AY$76,18,FALSE))))^Parameter!$B$3),0)) | X2: =IF(F2="",0,VLOOKUP(F2,Bausteine!$A$2:$AY$76,14,FALSE)) | Y2: =IFERROR(IF(OR(AD2<=0,AD2>1,R2<=0,T2<=0,V2<=0,U2>IF(E2="",0,VLOOKUP(E2,Bausteine!$A$2:$AY$76,12,FALSE)),T2>MIN(IF(C2="",0,VLOOKUP(C2,Bausteine!$A$2:$AY$76,22,FALSE)),IF(AQ2="",0,VLOOKUP(AQ2,Bausteine!$A$2:$AY$76,22,FALSE))),IF(E2="",0,VLOOKUP(E2,Bausteine!$A$2:$AY$76,11,FALSE))<=0,IF(E2="",0,VLOOKUP(E2,Bausteine!$A$2:$AY$76,11,FALSE))>1),"UNGUELTIG","OK"),"FEHLER") | Z2: 400 | AA2: 157 | AB2: Shared MG/sensors/wheels. Scalar baseline only; sensor and biological-driver traits not compiled. Hull price is an explicit initial baseline fit. | AD2: =IF(AC2="",1,IF(AC2="",0,VLOOKUP(AC2,Bausteine!$A$2:$AY$76,37,FALSE))/100) | AE2: =P2*AD2 | AI2: =SUMIF(Startbesatzung!$A$2:$A$7,A2,Startbesatzung!$D$2:$D$7) | AJ2: =SUMIF(Startbesatzung!$A$2:$A$7,A2,Startbesatzung!$E$2:$E$7) | AK2: =MAX(0,IF(Startbesatzung!A2=A2,Startbesatzung!G2,0),IF(Startbesatzung!A3=A2,Startbesatzung!G3,0),IF(Startbesatzung!A4=A2,Startbesatzung!G4,0),IF(Startbesatzung!A5=A2,Startbesatzung!G5,0),IF(Startbesatzung!A6=A2,Startbesatzung!G6,0),IF(Startbesatzung!A7=A2,Startbesatzung!G7,0)) | AL2: =IF(AF2="","",IF(IF(AH2="",0,VLOOKUP(AH2,Bausteine!$A$2:$AY$76,38,FALSE))>0,IF(AH2="",0,VLOOKUP(AH2,Bausteine!$A$2:$AY$76,38,FALSE)),IF(AG2="",0,VLOOKUP(AG2,Bausteine!$A$2:$AY$76,28,FALSE)))) | AM2: =IF(AF2="","",IF(AG2="",0,VLOOKUP(AG2,Bausteine!$A$2:$AY$76,44,FALSE))) | AN2: =IF(AF2="","",IF(AF2="",0,VLOOKUP(AF2,Bausteine!$A$2:$AY$76,27,FALSE))) | AO2: =IF(AF2="","",IF(AF2="",0,VLOOKUP(AF2,Bausteine!$A$2:$AY$76,25,FALSE))) | AP2: =IF(AF2="","",IF(AH2="",0,VLOOKUP(AH2,Bausteine!$A$2:$AY$76,29,FALSE))) | AQ2: wheels-light | AR2: =IF(AQ2="",0,VLOOKUP(AQ2,Bausteine!$A$2:$AY$76,48,FALSE)) | AS2: =MIN(IF(AQ2="",0,VLOOKUP(AQ2,Bausteine!$A$2:$AY$76,50,FALSE)),IF(C2="",0,VLOOKUP(C2,Bausteine!$A$2:$AY$76,51,FALSE)))
A3: Buggy baseline | B3: nod | C3: buggy-hull | D3: diesel-light | E3: baseline-generator | F3: light | G3: scout-mg-mount | H3: scout-mg | I3: scout-mg-rounds | J3: scout-sensors | M3: =IF(C3="",0,VLOOKUP(C3,Bausteine!$A$2:$AY$76,4,FALSE))+IF(D3="",0,VLOOKUP(D3,Bausteine!$A$2:$AY$76,4,FALSE))+IF(E3="",0,VLOOKUP(E3,Bausteine!$A$2:$AY$76,4,FALSE))+IF(F3="",0,VLOOKUP(F3,Bausteine!$A$2:$AY$76,4,FALSE))+IF(G3="",0,VLOOKUP(G3,Bausteine!$A$2:$AY$76,4,FALSE))+IF(H3="",0,VLOOKUP(H3,Bausteine!$A$2:$AY$76,4,FALSE))+IF(I3="",0,VLOOKUP(I3,Bausteine!$A$2:$AY$76,4,FALSE))+IF(J3="",0,VLOOKUP(J3,Bausteine!$A$2:$AY$76,4,FALSE))+IF(K3="",0,VLOOKUP(K3,Bausteine!$A$2:$AY$76,4,FALSE))+IF(L3="",0,VLOOKUP(L3,Bausteine!$A$2:$AY$76,4,FALSE))+IF(AC3="",0,VLOOKUP(AC3,Bausteine!$A$2:$AY$76,4,FALSE))+IF(AF3="",0,VLOOKUP(AF3,Bausteine!$A$2:$AY$76,4,FALSE))+IF(AG3="",0,VLOOKUP(AG3,Bausteine!$A$2:$AY$76,4,FALSE))+IF(AH3="",0,VLOOKUP(AH3,Bausteine!$A$2:$AY$76,4,FALSE))+IF(AQ3="",0,VLOOKUP(AQ3,Bausteine!$A$2:$AY$76,4,FALSE)) | N3: =IF(C3="",0,VLOOKUP(C3,Bausteine!$A$2:$AY$76,5,FALSE))+IF(D3="",0,VLOOKUP(D3,Bausteine!$A$2:$AY$76,5,FALSE))+IF(E3="",0,VLOOKUP(E3,Bausteine!$A$2:$AY$76,5,FALSE))+IF(F3="",0,VLOOKUP(F3,Bausteine!$A$2:$AY$76,5,FALSE))+IF(G3="",0,VLOOKUP(G3,Bausteine!$A$2:$AY$76,5,FALSE))+IF(H3="",0,VLOOKUP(H3,Bausteine!$A$2:$AY$76,5,FALSE))+IF(I3="",0,VLOOKUP(I3,Bausteine!$A$2:$AY$76,5,FALSE))+IF(J3="",0,VLOOKUP(J3,Bausteine!$A$2:$AY$76,5,FALSE))+IF(K3="",0,VLOOKUP(K3,Bausteine!$A$2:$AY$76,5,FALSE))+IF(L3="",0,VLOOKUP(L3,Bausteine!$A$2:$AY$76,5,FALSE))+IF(AC3="",0,VLOOKUP(AC3,Bausteine!$A$2:$AY$76,5,FALSE))+IF(AF3="",0,VLOOKUP(AF3,Bausteine!$A$2:$AY$76,5,FALSE))+IF(AG3="",0,VLOOKUP(AG3,Bausteine!$A$2:$AY$76,5,FALSE))+IF(AH3="",0,VLOOKUP(AH3,Bausteine!$A$2:$AY$76,5,FALSE))+IF(AQ3="",0,VLOOKUP(AQ3,Bausteine!$A$2:$AY$76,5,FALSE)) | O3: =MAX(IF(C3="",0,VLOOKUP(C3,Bausteine!$A$2:$AY$76,6,FALSE)),IF(D3="",0,VLOOKUP(D3,Bausteine!$A$2:$AY$76,6,FALSE)),IF(E3="",0,VLOOKUP(E3,Bausteine!$A$2:$AY$76,6,FALSE)),IF(F3="",0,VLOOKUP(F3,Bausteine!$A$2:$AY$76,6,FALSE)),IF(G3="",0,VLOOKUP(G3,Bausteine!$A$2:$AY$76,6,FALSE)),IF(H3="",0,VLOOKUP(H3,Bausteine!$A$2:$AY$76,6,FALSE)),IF(I3="",0,VLOOKUP(I3,Bausteine!$A$2:$AY$76,6,FALSE)),IF(J3="",0,VLOOKUP(J3,Bausteine!$A$2:$AY$76,6,FALSE)),IF(K3="",0,VLOOKUP(K3,Bausteine!$A$2:$AY$76,6,FALSE)),IF(L3="",0,VLOOKUP(L3,Bausteine!$A$2:$AY$76,6,FALSE)),IF(AC3="",0,VLOOKUP(AC3,Bausteine!$A$2:$AY$76,6,FALSE)),IF(AF3="",0,VLOOKUP(AF3,Bausteine!$A$2:$AY$76,6,FALSE)),IF(AG3="",0,VLOOKUP(AG3,Bausteine!$A$2:$AY$76,6,FALSE)),IF(AH3="",0,VLOOKUP(AH3,Bausteine!$A$2:$AY$76,6,FALSE)),IF(AQ3="",0,VLOOKUP(AQ3,Bausteine!$A$2:$AY$76,6,FALSE)),AK3) | P3: =IF(C3="",0,VLOOKUP(C3,Bausteine!$A$2:$AY$76,7,FALSE))*IF(F3="",0,VLOOKUP(F3,Bausteine!$A$2:$AY$76,17,FALSE))/100+IF(D3="",0,VLOOKUP(D3,Bausteine!$A$2:$AY$76,7,FALSE))+IF(E3="",0,VLOOKUP(E3,Bausteine!$A$2:$AY$76,7,FALSE))+IF(G3="",0,VLOOKUP(G3,Bausteine!$A$2:$AY$76,7,FALSE))+IF(H3="",0,VLOOKUP(H3,Bausteine!$A$2:$AY$76,7,FALSE))+IF(I3="",0,VLOOKUP(I3,Bausteine!$A$2:$AY$76,7,FALSE))+IF(J3="",0,VLOOKUP(J3,Bausteine!$A$2:$AY$76,7,FALSE))+IF(K3="",0,VLOOKUP(K3,Bausteine!$A$2:$AY$76,7,FALSE))+IF(L3="",0,VLOOKUP(L3,Bausteine!$A$2:$AY$76,7,FALSE))+IF(AC3="",0,VLOOKUP(AC3,Bausteine!$A$2:$AY$76,7,FALSE))+IF(AF3="",0,VLOOKUP(AF3,Bausteine!$A$2:$AY$76,7,FALSE))+IF(AG3="",0,VLOOKUP(AG3,Bausteine!$A$2:$AY$76,7,FALSE))+IF(AH3="",0,VLOOKUP(AH3,Bausteine!$A$2:$AY$76,7,FALSE))+IF(AQ3="",0,VLOOKUP(AQ3,Bausteine!$A$2:$AY$76,7,FALSE))+AI3 | Q3: =N3*Parameter!$B$2 | R3: =AE3-Q3 | S3: =IF(C3="",0,VLOOKUP(C3,Bausteine!$A$2:$AY$76,13,FALSE))*IF(F3="",0,VLOOKUP(F3,Bausteine!$A$2:$AY$76,16,FALSE))/100 | T3: =IF(C3="",0,VLOOKUP(C3,Bausteine!$A$2:$AY$76,8,FALSE))*IF(F3="",0,VLOOKUP(F3,Bausteine!$A$2:$AY$76,15,FALSE))/100+IF(D3="",0,VLOOKUP(D3,Bausteine!$A$2:$AY$76,8,FALSE))+IF(E3="",0,VLOOKUP(E3,Bausteine!$A$2:$AY$76,8,FALSE))+IF(G3="",0,VLOOKUP(G3,Bausteine!$A$2:$AY$76,8,FALSE))+IF(H3="",0,VLOOKUP(H3,Bausteine!$A$2:$AY$76,8,FALSE))+IF(I3="",0,VLOOKUP(I3,Bausteine!$A$2:$AY$76,8,FALSE))+IF(J3="",0,VLOOKUP(J3,Bausteine!$A$2:$AY$76,8,FALSE))+IF(K3="",0,VLOOKUP(K3,Bausteine!$A$2:$AY$76,8,FALSE))+IF(L3="",0,VLOOKUP(L3,Bausteine!$A$2:$AY$76,8,FALSE))+IF(AC3="",0,VLOOKUP(AC3,Bausteine!$A$2:$AY$76,8,FALSE))+IF(AF3="",0,VLOOKUP(AF3,Bausteine!$A$2:$AY$76,8,FALSE))+IF(AG3="",0,VLOOKUP(AG3,Bausteine!$A$2:$AY$76,8,FALSE))+IF(AH3="",0,VLOOKUP(AH3,Bausteine!$A$2:$AY$76,8,FALSE))+IF(AQ3="",0,VLOOKUP(AQ3,Bausteine!$A$2:$AY$76,8,FALSE))+AJ3 | U3: =IF(C3="",0,VLOOKUP(C3,Bausteine!$A$2:$AY$76,9,FALSE))+IF(D3="",0,VLOOKUP(D3,Bausteine!$A$2:$AY$76,9,FALSE))+IF(E3="",0,VLOOKUP(E3,Bausteine!$A$2:$AY$76,9,FALSE))+IF(F3="",0,VLOOKUP(F3,Bausteine!$A$2:$AY$76,9,FALSE))+IF(G3="",0,VLOOKUP(G3,Bausteine!$A$2:$AY$76,9,FALSE))+IF(H3="",0,VLOOKUP(H3,Bausteine!$A$2:$AY$76,9,FALSE))+IF(I3="",0,VLOOKUP(I3,Bausteine!$A$2:$AY$76,9,FALSE))+IF(J3="",0,VLOOKUP(J3,Bausteine!$A$2:$AY$76,9,FALSE))+IF(K3="",0,VLOOKUP(K3,Bausteine!$A$2:$AY$76,9,FALSE))+IF(L3="",0,VLOOKUP(L3,Bausteine!$A$2:$AY$76,9,FALSE))+IF(AC3="",0,VLOOKUP(AC3,Bausteine!$A$2:$AY$76,9,FALSE))+IF(AF3="",0,VLOOKUP(AF3,Bausteine!$A$2:$AY$76,9,FALSE))+IF(AG3="",0,VLOOKUP(AG3,Bausteine!$A$2:$AY$76,9,FALSE))+IF(AH3="",0,VLOOKUP(AH3,Bausteine!$A$2:$AY$76,9,FALSE))+IF(AQ3="",0,VLOOKUP(AQ3,Bausteine!$A$2:$AY$76,9,FALSE)) | V3: =IF(D3="",0,VLOOKUP(D3,Bausteine!$A$2:$AY$76,10,FALSE))-U3/IF(E3="",0,VLOOKUP(E3,Bausteine!$A$2:$AY$76,11,FALSE)) | W3: =IF(Y3<>"OK","",ROUND(MIN(IF(C3="",0,VLOOKUP(C3,Bausteine!$A$2:$AY$76,21,FALSE)),IF(AQ3="",0,VLOOKUP(AQ3,Bausteine!$A$2:$AY$76,21,FALSE)),IF(C3="",0,VLOOKUP(C3,Bausteine!$A$2:$AY$76,20,FALSE))*(V3/T3/(IF(C3="",0,VLOOKUP(C3,Bausteine!$A$2:$AY$76,19,FALSE))/IF(C3="",0,VLOOKUP(C3,Bausteine!$A$2:$AY$76,18,FALSE))))^Parameter!$B$3),0)) | X3: =IF(F3="",0,VLOOKUP(F3,Bausteine!$A$2:$AY$76,14,FALSE)) | Y3: =IFERROR(IF(OR(AD3<=0,AD3>1,R3<=0,T3<=0,V3<=0,U3>IF(E3="",0,VLOOKUP(E3,Bausteine!$A$2:$AY$76,12,FALSE)),T3>MIN(IF(C3="",0,VLOOKUP(C3,Bausteine!$A$2:$AY$76,22,FALSE)),IF(AQ3="",0,VLOOKUP(AQ3,Bausteine!$A$2:$AY$76,22,FALSE))),IF(E3="",0,VLOOKUP(E3,Bausteine!$A$2:$AY$76,11,FALSE))<=0,IF(E3="",0,VLOOKUP(E3,Bausteine!$A$2:$AY$76,11,FALSE))>1),"UNGUELTIG","OK"),"FEHLER") | Z3: 350 | AA3: 157 | AB3: Same MG, wheels, motor and sensors as Hum-Vee. Different hull HP/mass/price; no per-design rebate. | AD3: =IF(AC3="",1,IF(AC3="",0,VLOOKUP(AC3,Bausteine!$A$2:$AY$76,37,FALSE))/100) | AE3: =P3*AD3 | AI3: =SUMIF(Startbesatzung!$A$2:$A$7,A3,Startbesatzung!$D$2:$D$7) | AJ3: =SUMIF(Startbesatzung!$A$2:$A$7,A3,Startbesatzung!$E$2:$E$7) | AK3: =MAX(0,IF(Startbesatzung!A2=A3,Startbesatzung!G2,0),IF(Startbesatzung!A3=A3,Startbesatzung!G3,0),IF(Startbesatzung!A4=A3,Startbesatzung!G4,0),IF(Startbesatzung!A5=A3,Startbesatzung!G5,0),IF(Startbesatzung!A6=A3,Startbesatzung!G6,0),IF(Startbesatzung!A7=A3,Startbesatzung!G7,0)) | AL3: =IF(AF3="","",IF(IF(AH3="",0,VLOOKUP(AH3,Bausteine!$A$2:$AY$76,38,FALSE))>0,IF(AH3="",0,VLOOKUP(AH3,Bausteine!$A$2:$AY$76,38,FALSE)),IF(AG3="",0,VLOOKUP(AG3,Bausteine!$A$2:$AY$76,28,FALSE)))) | AM3: =IF(AF3="","",IF(AG3="",0,VLOOKUP(AG3,Bausteine!$A$2:$AY$76,44,FALSE))) | AN3: =IF(AF3="","",IF(AF3="",0,VLOOKUP(AF3,Bausteine!$A$2:$AY$76,27,FALSE))) | AO3: =IF(AF3="","",IF(AF3="",0,VLOOKUP(AF3,Bausteine!$A$2:$AY$76,25,FALSE))) | AP3: =IF(AF3="","",IF(AH3="",0,VLOOKUP(AH3,Bausteine!$A$2:$AY$76,29,FALSE))) | AQ3: wheels-light | AR3: =IF(AQ3="",0,VLOOKUP(AQ3,Bausteine!$A$2:$AY$76,48,FALSE)) | AS3: =MIN(IF(AQ3="",0,VLOOKUP(AQ3,Bausteine!$A$2:$AY$76,50,FALSE)),IF(C3="",0,VLOOKUP(C3,Bausteine!$A$2:$AY$76,51,FALSE)))
A4: Nod Light Tank baseline | B4: nod | C4: nod-light-hull | D4: diesel | E4: baseline-generator | F4: heavy | G4: light-cannon-mount | H4: light-cannon | I4: light-tank-shell | M4: =IF(C4="",0,VLOOKUP(C4,Bausteine!$A$2:$AY$76,4,FALSE))+IF(D4="",0,VLOOKUP(D4,Bausteine!$A$2:$AY$76,4,FALSE))+IF(E4="",0,VLOOKUP(E4,Bausteine!$A$2:$AY$76,4,FALSE))+IF(F4="",0,VLOOKUP(F4,Bausteine!$A$2:$AY$76,4,FALSE))+IF(G4="",0,VLOOKUP(G4,Bausteine!$A$2:$AY$76,4,FALSE))+IF(H4="",0,VLOOKUP(H4,Bausteine!$A$2:$AY$76,4,FALSE))+IF(I4="",0,VLOOKUP(I4,Bausteine!$A$2:$AY$76,4,FALSE))+IF(J4="",0,VLOOKUP(J4,Bausteine!$A$2:$AY$76,4,FALSE))+IF(K4="",0,VLOOKUP(K4,Bausteine!$A$2:$AY$76,4,FALSE))+IF(L4="",0,VLOOKUP(L4,Bausteine!$A$2:$AY$76,4,FALSE))+IF(AC4="",0,VLOOKUP(AC4,Bausteine!$A$2:$AY$76,4,FALSE))+IF(AF4="",0,VLOOKUP(AF4,Bausteine!$A$2:$AY$76,4,FALSE))+IF(AG4="",0,VLOOKUP(AG4,Bausteine!$A$2:$AY$76,4,FALSE))+IF(AH4="",0,VLOOKUP(AH4,Bausteine!$A$2:$AY$76,4,FALSE))+IF(AQ4="",0,VLOOKUP(AQ4,Bausteine!$A$2:$AY$76,4,FALSE)) | N4: =IF(C4="",0,VLOOKUP(C4,Bausteine!$A$2:$AY$76,5,FALSE))+IF(D4="",0,VLOOKUP(D4,Bausteine!$A$2:$AY$76,5,FALSE))+IF(E4="",0,VLOOKUP(E4,Bausteine!$A$2:$AY$76,5,FALSE))+IF(F4="",0,VLOOKUP(F4,Bausteine!$A$2:$AY$76,5,FALSE))+IF(G4="",0,VLOOKUP(G4,Bausteine!$A$2:$AY$76,5,FALSE))+IF(H4="",0,VLOOKUP(H4,Bausteine!$A$2:$AY$76,5,FALSE))+IF(I4="",0,VLOOKUP(I4,Bausteine!$A$2:$AY$76,5,FALSE))+IF(J4="",0,VLOOKUP(J4,Bausteine!$A$2:$AY$76,5,FALSE))+IF(K4="",0,VLOOKUP(K4,Bausteine!$A$2:$AY$76,5,FALSE))+IF(L4="",0,VLOOKUP(L4,Bausteine!$A$2:$AY$76,5,FALSE))+IF(AC4="",0,VLOOKUP(AC4,Bausteine!$A$2:$AY$76,5,FALSE))+IF(AF4="",0,VLOOKUP(AF4,Bausteine!$A$2:$AY$76,5,FALSE))+IF(AG4="",0,VLOOKUP(AG4,Bausteine!$A$2:$AY$76,5,FALSE))+IF(AH4="",0,VLOOKUP(AH4,Bausteine!$A$2:$AY$76,5,FALSE))+IF(AQ4="",0,VLOOKUP(AQ4,Bausteine!$A$2:$AY$76,5,FALSE)) | O4: =MAX(IF(C4="",0,VLOOKUP(C4,Bausteine!$A$2:$AY$76,6,FALSE)),IF(D4="",0,VLOOKUP(D4,Bausteine!$A$2:$AY$76,6,FALSE)),IF(E4="",0,VLOOKUP(E4,Bausteine!$A$2:$AY$76,6,FALSE)),IF(F4="",0,VLOOKUP(F4,Bausteine!$A$2:$AY$76,6,FALSE)),IF(G4="",0,VLOOKUP(G4,Bausteine!$A$2:$AY$76,6,FALSE)),IF(H4="",0,VLOOKUP(H4,Bausteine!$A$2:$AY$76,6,FALSE)),IF(I4="",0,VLOOKUP(I4,Bausteine!$A$2:$AY$76,6,FALSE)),IF(J4="",0,VLOOKUP(J4,Bausteine!$A$2:$AY$76,6,FALSE)),IF(K4="",0,VLOOKUP(K4,Bausteine!$A$2:$AY$76,6,FALSE)),IF(L4="",0,VLOOKUP(L4,Bausteine!$A$2:$AY$76,6,FALSE)),IF(AC4="",0,VLOOKUP(AC4,Bausteine!$A$2:$AY$76,6,FALSE)),IF(AF4="",0,VLOOKUP(AF4,Bausteine!$A$2:$AY$76,6,FALSE)),IF(AG4="",0,VLOOKUP(AG4,Bausteine!$A$2:$AY$76,6,FALSE)),IF(AH4="",0,VLOOKUP(AH4,Bausteine!$A$2:$AY$76,6,FALSE)),IF(AQ4="",0,VLOOKUP(AQ4,Bausteine!$A$2:$AY$76,6,FALSE)),AK4) | P4: =IF(C4="",0,VLOOKUP(C4,Bausteine!$A$2:$AY$76,7,FALSE))*IF(F4="",0,VLOOKUP(F4,Bausteine!$A$2:$AY$76,17,FALSE))/100+IF(D4="",0,VLOOKUP(D4,Bausteine!$A$2:$AY$76,7,FALSE))+IF(E4="",0,VLOOKUP(E4,Bausteine!$A$2:$AY$76,7,FALSE))+IF(G4="",0,VLOOKUP(G4,Bausteine!$A$2:$AY$76,7,FALSE))+IF(H4="",0,VLOOKUP(H4,Bausteine!$A$2:$AY$76,7,FALSE))+IF(I4="",0,VLOOKUP(I4,Bausteine!$A$2:$AY$76,7,FALSE))+IF(J4="",0,VLOOKUP(J4,Bausteine!$A$2:$AY$76,7,FALSE))+IF(K4="",0,VLOOKUP(K4,Bausteine!$A$2:$AY$76,7,FALSE))+IF(L4="",0,VLOOKUP(L4,Bausteine!$A$2:$AY$76,7,FALSE))+IF(AC4="",0,VLOOKUP(AC4,Bausteine!$A$2:$AY$76,7,FALSE))+IF(AF4="",0,VLOOKUP(AF4,Bausteine!$A$2:$AY$76,7,FALSE))+IF(AG4="",0,VLOOKUP(AG4,Bausteine!$A$2:$AY$76,7,FALSE))+IF(AH4="",0,VLOOKUP(AH4,Bausteine!$A$2:$AY$76,7,FALSE))+IF(AQ4="",0,VLOOKUP(AQ4,Bausteine!$A$2:$AY$76,7,FALSE))+AI4 | Q4: =N4*Parameter!$B$2 | R4: =AE4-Q4 | S4: =IF(C4="",0,VLOOKUP(C4,Bausteine!$A$2:$AY$76,13,FALSE))*IF(F4="",0,VLOOKUP(F4,Bausteine!$A$2:$AY$76,16,FALSE))/100 | T4: =IF(C4="",0,VLOOKUP(C4,Bausteine!$A$2:$AY$76,8,FALSE))*IF(F4="",0,VLOOKUP(F4,Bausteine!$A$2:$AY$76,15,FALSE))/100+IF(D4="",0,VLOOKUP(D4,Bausteine!$A$2:$AY$76,8,FALSE))+IF(E4="",0,VLOOKUP(E4,Bausteine!$A$2:$AY$76,8,FALSE))+IF(G4="",0,VLOOKUP(G4,Bausteine!$A$2:$AY$76,8,FALSE))+IF(H4="",0,VLOOKUP(H4,Bausteine!$A$2:$AY$76,8,FALSE))+IF(I4="",0,VLOOKUP(I4,Bausteine!$A$2:$AY$76,8,FALSE))+IF(J4="",0,VLOOKUP(J4,Bausteine!$A$2:$AY$76,8,FALSE))+IF(K4="",0,VLOOKUP(K4,Bausteine!$A$2:$AY$76,8,FALSE))+IF(L4="",0,VLOOKUP(L4,Bausteine!$A$2:$AY$76,8,FALSE))+IF(AC4="",0,VLOOKUP(AC4,Bausteine!$A$2:$AY$76,8,FALSE))+IF(AF4="",0,VLOOKUP(AF4,Bausteine!$A$2:$AY$76,8,FALSE))+IF(AG4="",0,VLOOKUP(AG4,Bausteine!$A$2:$AY$76,8,FALSE))+IF(AH4="",0,VLOOKUP(AH4,Bausteine!$A$2:$AY$76,8,FALSE))+IF(AQ4="",0,VLOOKUP(AQ4,Bausteine!$A$2:$AY$76,8,FALSE))+AJ4 | U4: =IF(C4="",0,VLOOKUP(C4,Bausteine!$A$2:$AY$76,9,FALSE))+IF(D4="",0,VLOOKUP(D4,Bausteine!$A$2:$AY$76,9,FALSE))+IF(E4="",0,VLOOKUP(E4,Bausteine!$A$2:$AY$76,9,FALSE))+IF(F4="",0,VLOOKUP(F4,Bausteine!$A$2:$AY$76,9,FALSE))+IF(G4="",0,VLOOKUP(G4,Bausteine!$A$2:$AY$76,9,FALSE))+IF(H4="",0,VLOOKUP(H4,Bausteine!$A$2:$AY$76,9,FALSE))+IF(I4="",0,VLOOKUP(I4,Bausteine!$A$2:$AY$76,9,FALSE))+IF(J4="",0,VLOOKUP(J4,Bausteine!$A$2:$AY$76,9,FALSE))+IF(K4="",0,VLOOKUP(K4,Bausteine!$A$2:$AY$76,9,FALSE))+IF(L4="",0,VLOOKUP(L4,Bausteine!$A$2:$AY$76,9,FALSE))+IF(AC4="",0,VLOOKUP(AC4,Bausteine!$A$2:$AY$76,9,FALSE))+IF(AF4="",0,VLOOKUP(AF4,Bausteine!$A$2:$AY$76,9,FALSE))+IF(AG4="",0,VLOOKUP(AG4,Bausteine!$A$2:$AY$76,9,FALSE))+IF(AH4="",0,VLOOKUP(AH4,Bausteine!$A$2:$AY$76,9,FALSE))+IF(AQ4="",0,VLOOKUP(AQ4,Bausteine!$A$2:$AY$76,9,FALSE)) | V4: =IF(D4="",0,VLOOKUP(D4,Bausteine!$A$2:$AY$76,10,FALSE))-U4/IF(E4="",0,VLOOKUP(E4,Bausteine!$A$2:$AY$76,11,FALSE)) | W4: =IF(Y4<>"OK","",ROUND(MIN(IF(C4="",0,VLOOKUP(C4,Bausteine!$A$2:$AY$76,21,FALSE)),IF(AQ4="",0,VLOOKUP(AQ4,Bausteine!$A$2:$AY$76,21,FALSE)),IF(C4="",0,VLOOKUP(C4,Bausteine!$A$2:$AY$76,20,FALSE))*(V4/T4/(IF(C4="",0,VLOOKUP(C4,Bausteine!$A$2:$AY$76,19,FALSE))/IF(C4="",0,VLOOKUP(C4,Bausteine!$A$2:$AY$76,18,FALSE))))^Parameter!$B$3),0)) | X4: =IF(F4="",0,VLOOKUP(F4,Bausteine!$A$2:$AY$76,14,FALSE)) | Y4: =IFERROR(IF(OR(AD4<=0,AD4>1,R4<=0,T4<=0,V4<=0,U4>IF(E4="",0,VLOOKUP(E4,Bausteine!$A$2:$AY$76,12,FALSE)),T4>MIN(IF(C4="",0,VLOOKUP(C4,Bausteine!$A$2:$AY$76,22,FALSE)),IF(AQ4="",0,VLOOKUP(AQ4,Bausteine!$A$2:$AY$76,22,FALSE))),IF(E4="",0,VLOOKUP(E4,Bausteine!$A$2:$AY$76,11,FALSE))<=0,IF(E4="",0,VLOOKUP(E4,Bausteine!$A$2:$AY$76,11,FALSE))>1),"UNGUELTIG","OK"),"FEHLER") | Z4: 625 | AA4: 100 | AB4: Shared 30mm assembly with Devil/T-34. No laser upgrades or drone/driver behavior compiled. | AD4: =IF(AC4="",1,IF(AC4="",0,VLOOKUP(AC4,Bausteine!$A$2:$AY$76,37,FALSE))/100) | AE4: =P4*AD4 | AI4: =SUMIF(Startbesatzung!$A$2:$A$7,A4,Startbesatzung!$D$2:$D$7) | AJ4: =SUMIF(Startbesatzung!$A$2:$A$7,A4,Startbesatzung!$E$2:$E$7) | AK4: =MAX(0,IF(Startbesatzung!A2=A4,Startbesatzung!G2,0),IF(Startbesatzung!A3=A4,Startbesatzung!G3,0),IF(Startbesatzung!A4=A4,Startbesatzung!G4,0),IF(Startbesatzung!A5=A4,Startbesatzung!G5,0),IF(Startbesatzung!A6=A4,Startbesatzung!G6,0),IF(Startbesatzung!A7=A4,Startbesatzung!G7,0)) | AL4: =IF(AF4="","",IF(IF(AH4="",0,VLOOKUP(AH4,Bausteine!$A$2:$AY$76,38,FALSE))>0,IF(AH4="",0,VLOOKUP(AH4,Bausteine!$A$2:$AY$76,38,FALSE)),IF(AG4="",0,VLOOKUP(AG4,Bausteine!$A$2:$AY$76,28,FALSE)))) | AM4: =IF(AF4="","",IF(AG4="",0,VLOOKUP(AG4,Bausteine!$A$2:$AY$76,44,FALSE))) | AN4: =IF(AF4="","",IF(AF4="",0,VLOOKUP(AF4,Bausteine!$A$2:$AY$76,27,FALSE))) | AO4: =IF(AF4="","",IF(AF4="",0,VLOOKUP(AF4,Bausteine!$A$2:$AY$76,25,FALSE))) | AP4: =IF(AF4="","",IF(AH4="",0,VLOOKUP(AH4,Bausteine!$A$2:$AY$76,29,FALSE))) | AQ4: tracks-standard | AR4: =IF(AQ4="",0,VLOOKUP(AQ4,Bausteine!$A$2:$AY$76,48,FALSE)) | AS4: =MIN(IF(AQ4="",0,VLOOKUP(AQ4,Bausteine!$A$2:$AY$76,50,FALSE)),IF(C4="",0,VLOOKUP(C4,Bausteine!$A$2:$AY$76,51,FALSE)))
A5: T-34 baseline | B5: soviet | C5: t34-hull | D5: diesel | E5: baseline-generator | F5: heavy | G5: light-cannon-mount | H5: light-cannon | I5: light-tank-shell | M5: =IF(C5="",0,VLOOKUP(C5,Bausteine!$A$2:$AY$76,4,FALSE))+IF(D5="",0,VLOOKUP(D5,Bausteine!$A$2:$AY$76,4,FALSE))+IF(E5="",0,VLOOKUP(E5,Bausteine!$A$2:$AY$76,4,FALSE))+IF(F5="",0,VLOOKUP(F5,Bausteine!$A$2:$AY$76,4,FALSE))+IF(G5="",0,VLOOKUP(G5,Bausteine!$A$2:$AY$76,4,FALSE))+IF(H5="",0,VLOOKUP(H5,Bausteine!$A$2:$AY$76,4,FALSE))+IF(I5="",0,VLOOKUP(I5,Bausteine!$A$2:$AY$76,4,FALSE))+IF(J5="",0,VLOOKUP(J5,Bausteine!$A$2:$AY$76,4,FALSE))+IF(K5="",0,VLOOKUP(K5,Bausteine!$A$2:$AY$76,4,FALSE))+IF(L5="",0,VLOOKUP(L5,Bausteine!$A$2:$AY$76,4,FALSE))+IF(AC5="",0,VLOOKUP(AC5,Bausteine!$A$2:$AY$76,4,FALSE))+IF(AF5="",0,VLOOKUP(AF5,Bausteine!$A$2:$AY$76,4,FALSE))+IF(AG5="",0,VLOOKUP(AG5,Bausteine!$A$2:$AY$76,4,FALSE))+IF(AH5="",0,VLOOKUP(AH5,Bausteine!$A$2:$AY$76,4,FALSE))+IF(AQ5="",0,VLOOKUP(AQ5,Bausteine!$A$2:$AY$76,4,FALSE)) | N5: =IF(C5="",0,VLOOKUP(C5,Bausteine!$A$2:$AY$76,5,FALSE))+IF(D5="",0,VLOOKUP(D5,Bausteine!$A$2:$AY$76,5,FALSE))+IF(E5="",0,VLOOKUP(E5,Bausteine!$A$2:$AY$76,5,FALSE))+IF(F5="",0,VLOOKUP(F5,Bausteine!$A$2:$AY$76,5,FALSE))+IF(G5="",0,VLOOKUP(G5,Bausteine!$A$2:$AY$76,5,FALSE))+IF(H5="",0,VLOOKUP(H5,Bausteine!$A$2:$AY$76,5,FALSE))+IF(I5="",0,VLOOKUP(I5,Bausteine!$A$2:$AY$76,5,FALSE))+IF(J5="",0,VLOOKUP(J5,Bausteine!$A$2:$AY$76,5,FALSE))+IF(K5="",0,VLOOKUP(K5,Bausteine!$A$2:$AY$76,5,FALSE))+IF(L5="",0,VLOOKUP(L5,Bausteine!$A$2:$AY$76,5,FALSE))+IF(AC5="",0,VLOOKUP(AC5,Bausteine!$A$2:$AY$76,5,FALSE))+IF(AF5="",0,VLOOKUP(AF5,Bausteine!$A$2:$AY$76,5,FALSE))+IF(AG5="",0,VLOOKUP(AG5,Bausteine!$A$2:$AY$76,5,FALSE))+IF(AH5="",0,VLOOKUP(AH5,Bausteine!$A$2:$AY$76,5,FALSE))+IF(AQ5="",0,VLOOKUP(AQ5,Bausteine!$A$2:$AY$76,5,FALSE)) | O5: =MAX(IF(C5="",0,VLOOKUP(C5,Bausteine!$A$2:$AY$76,6,FALSE)),IF(D5="",0,VLOOKUP(D5,Bausteine!$A$2:$AY$76,6,FALSE)),IF(E5="",0,VLOOKUP(E5,Bausteine!$A$2:$AY$76,6,FALSE)),IF(F5="",0,VLOOKUP(F5,Bausteine!$A$2:$AY$76,6,FALSE)),IF(G5="",0,VLOOKUP(G5,Bausteine!$A$2:$AY$76,6,FALSE)),IF(H5="",0,VLOOKUP(H5,Bausteine!$A$2:$AY$76,6,FALSE)),IF(I5="",0,VLOOKUP(I5,Bausteine!$A$2:$AY$76,6,FALSE)),IF(J5="",0,VLOOKUP(J5,Bausteine!$A$2:$AY$76,6,FALSE)),IF(K5="",0,VLOOKUP(K5,Bausteine!$A$2:$AY$76,6,FALSE)),IF(L5="",0,VLOOKUP(L5,Bausteine!$A$2:$AY$76,6,FALSE)),IF(AC5="",0,VLOOKUP(AC5,Bausteine!$A$2:$AY$76,6,FALSE)),IF(AF5="",0,VLOOKUP(AF5,Bausteine!$A$2:$AY$76,6,FALSE)),IF(AG5="",0,VLOOKUP(AG5,Bausteine!$A$2:$AY$76,6,FALSE)),IF(AH5="",0,VLOOKUP(AH5,Bausteine!$A$2:$AY$76,6,FALSE)),IF(AQ5="",0,VLOOKUP(AQ5,Bausteine!$A$2:$AY$76,6,FALSE)),AK5) | P5: =IF(C5="",0,VLOOKUP(C5,Bausteine!$A$2:$AY$76,7,FALSE))*IF(F5="",0,VLOOKUP(F5,Bausteine!$A$2:$AY$76,17,FALSE))/100+IF(D5="",0,VLOOKUP(D5,Bausteine!$A$2:$AY$76,7,FALSE))+IF(E5="",0,VLOOKUP(E5,Bausteine!$A$2:$AY$76,7,FALSE))+IF(G5="",0,VLOOKUP(G5,Bausteine!$A$2:$AY$76,7,FALSE))+IF(H5="",0,VLOOKUP(H5,Bausteine!$A$2:$AY$76,7,FALSE))+IF(I5="",0,VLOOKUP(I5,Bausteine!$A$2:$AY$76,7,FALSE))+IF(J5="",0,VLOOKUP(J5,Bausteine!$A$2:$AY$76,7,FALSE))+IF(K5="",0,VLOOKUP(K5,Bausteine!$A$2:$AY$76,7,FALSE))+IF(L5="",0,VLOOKUP(L5,Bausteine!$A$2:$AY$76,7,FALSE))+IF(AC5="",0,VLOOKUP(AC5,Bausteine!$A$2:$AY$76,7,FALSE))+IF(AF5="",0,VLOOKUP(AF5,Bausteine!$A$2:$AY$76,7,FALSE))+IF(AG5="",0,VLOOKUP(AG5,Bausteine!$A$2:$AY$76,7,FALSE))+IF(AH5="",0,VLOOKUP(AH5,Bausteine!$A$2:$AY$76,7,FALSE))+IF(AQ5="",0,VLOOKUP(AQ5,Bausteine!$A$2:$AY$76,7,FALSE))+AI5 | Q5: =N5*Parameter!$B$2 | R5: =AE5-Q5 | S5: =IF(C5="",0,VLOOKUP(C5,Bausteine!$A$2:$AY$76,13,FALSE))*IF(F5="",0,VLOOKUP(F5,Bausteine!$A$2:$AY$76,16,FALSE))/100 | T5: =IF(C5="",0,VLOOKUP(C5,Bausteine!$A$2:$AY$76,8,FALSE))*IF(F5="",0,VLOOKUP(F5,Bausteine!$A$2:$AY$76,15,FALSE))/100+IF(D5="",0,VLOOKUP(D5,Bausteine!$A$2:$AY$76,8,FALSE))+IF(E5="",0,VLOOKUP(E5,Bausteine!$A$2:$AY$76,8,FALSE))+IF(G5="",0,VLOOKUP(G5,Bausteine!$A$2:$AY$76,8,FALSE))+IF(H5="",0,VLOOKUP(H5,Bausteine!$A$2:$AY$76,8,FALSE))+IF(I5="",0,VLOOKUP(I5,Bausteine!$A$2:$AY$76,8,FALSE))+IF(J5="",0,VLOOKUP(J5,Bausteine!$A$2:$AY$76,8,FALSE))+IF(K5="",0,VLOOKUP(K5,Bausteine!$A$2:$AY$76,8,FALSE))+IF(L5="",0,VLOOKUP(L5,Bausteine!$A$2:$AY$76,8,FALSE))+IF(AC5="",0,VLOOKUP(AC5,Bausteine!$A$2:$AY$76,8,FALSE))+IF(AF5="",0,VLOOKUP(AF5,Bausteine!$A$2:$AY$76,8,FALSE))+IF(AG5="",0,VLOOKUP(AG5,Bausteine!$A$2:$AY$76,8,FALSE))+IF(AH5="",0,VLOOKUP(AH5,Bausteine!$A$2:$AY$76,8,FALSE))+IF(AQ5="",0,VLOOKUP(AQ5,Bausteine!$A$2:$AY$76,8,FALSE))+AJ5 | U5: =IF(C5="",0,VLOOKUP(C5,Bausteine!$A$2:$AY$76,9,FALSE))+IF(D5="",0,VLOOKUP(D5,Bausteine!$A$2:$AY$76,9,FALSE))+IF(E5="",0,VLOOKUP(E5,Bausteine!$A$2:$AY$76,9,FALSE))+IF(F5="",0,VLOOKUP(F5,Bausteine!$A$2:$AY$76,9,FALSE))+IF(G5="",0,VLOOKUP(G5,Bausteine!$A$2:$AY$76,9,FALSE))+IF(H5="",0,VLOOKUP(H5,Bausteine!$A$2:$AY$76,9,FALSE))+IF(I5="",0,VLOOKUP(I5,Bausteine!$A$2:$AY$76,9,FALSE))+IF(J5="",0,VLOOKUP(J5,Bausteine!$A$2:$AY$76,9,FALSE))+IF(K5="",0,VLOOKUP(K5,Bausteine!$A$2:$AY$76,9,FALSE))+IF(L5="",0,VLOOKUP(L5,Bausteine!$A$2:$AY$76,9,FALSE))+IF(AC5="",0,VLOOKUP(AC5,Bausteine!$A$2:$AY$76,9,FALSE))+IF(AF5="",0,VLOOKUP(AF5,Bausteine!$A$2:$AY$76,9,FALSE))+IF(AG5="",0,VLOOKUP(AG5,Bausteine!$A$2:$AY$76,9,FALSE))+IF(AH5="",0,VLOOKUP(AH5,Bausteine!$A$2:$AY$76,9,FALSE))+IF(AQ5="",0,VLOOKUP(AQ5,Bausteine!$A$2:$AY$76,9,FALSE)) | V5: =IF(D5="",0,VLOOKUP(D5,Bausteine!$A$2:$AY$76,10,FALSE))-U5/IF(E5="",0,VLOOKUP(E5,Bausteine!$A$2:$AY$76,11,FALSE)) | W5: =IF(Y5<>"OK","",ROUND(MIN(IF(C5="",0,VLOOKUP(C5,Bausteine!$A$2:$AY$76,21,FALSE)),IF(AQ5="",0,VLOOKUP(AQ5,Bausteine!$A$2:$AY$76,21,FALSE)),IF(C5="",0,VLOOKUP(C5,Bausteine!$A$2:$AY$76,20,FALSE))*(V5/T5/(IF(C5="",0,VLOOKUP(C5,Bausteine!$A$2:$AY$76,19,FALSE))/IF(C5="",0,VLOOKUP(C5,Bausteine!$A$2:$AY$76,18,FALSE))))^Parameter!$B$3),0)) | X5: =IF(F5="",0,VLOOKUP(F5,Bausteine!$A$2:$AY$76,14,FALSE)) | Y5: =IFERROR(IF(OR(AD5<=0,AD5>1,R5<=0,T5<=0,V5<=0,U5>IF(E5="",0,VLOOKUP(E5,Bausteine!$A$2:$AY$76,12,FALSE)),T5>MIN(IF(C5="",0,VLOOKUP(C5,Bausteine!$A$2:$AY$76,22,FALSE)),IF(AQ5="",0,VLOOKUP(AQ5,Bausteine!$A$2:$AY$76,22,FALSE))),IF(E5="",0,VLOOKUP(E5,Bausteine!$A$2:$AY$76,11,FALSE))<=0,IF(E5="",0,VLOOKUP(E5,Bausteine!$A$2:$AY$76,11,FALSE))>1),"UNGUELTIG","OK"),"FEHLER") | Z5: 600 | AA5: 100 | AB5: Cluster upgrade excluded; Soviet base-faction availability is proposed, legacy unit is North Korea. Initial hull price fit, not independent balance validation. | AD5: =IF(AC5="",1,IF(AC5="",0,VLOOKUP(AC5,Bausteine!$A$2:$AY$76,37,FALSE))/100) | AE5: =P5*AD5 | AI5: =SUMIF(Startbesatzung!$A$2:$A$7,A5,Startbesatzung!$D$2:$D$7) | AJ5: =SUMIF(Startbesatzung!$A$2:$A$7,A5,Startbesatzung!$E$2:$E$7) | AK5: =MAX(0,IF(Startbesatzung!A2=A5,Startbesatzung!G2,0),IF(Startbesatzung!A3=A5,Startbesatzung!G3,0),IF(Startbesatzung!A4=A5,Startbesatzung!G4,0),IF(Startbesatzung!A5=A5,Startbesatzung!G5,0),IF(Startbesatzung!A6=A5,Startbesatzung!G6,0),IF(Startbesatzung!A7=A5,Startbesatzung!G7,0)) | AL5: =IF(AF5="","",IF(IF(AH5="",0,VLOOKUP(AH5,Bausteine!$A$2:$AY$76,38,FALSE))>0,IF(AH5="",0,VLOOKUP(AH5,Bausteine!$A$2:$AY$76,38,FALSE)),IF(AG5="",0,VLOOKUP(AG5,Bausteine!$A$2:$AY$76,28,FALSE)))) | AM5: =IF(AF5="","",IF(AG5="",0,VLOOKUP(AG5,Bausteine!$A$2:$AY$76,44,FALSE))) | AN5: =IF(AF5="","",IF(AF5="",0,VLOOKUP(AF5,Bausteine!$A$2:$AY$76,27,FALSE))) | AO5: =IF(AF5="","",IF(AF5="",0,VLOOKUP(AF5,Bausteine!$A$2:$AY$76,25,FALSE))) | AP5: =IF(AF5="","",IF(AH5="",0,VLOOKUP(AH5,Bausteine!$A$2:$AY$76,29,FALSE))) | AQ5: tracks-standard | AR5: =IF(AQ5="",0,VLOOKUP(AQ5,Bausteine!$A$2:$AY$76,48,FALSE)) | AS5: =MIN(IF(AQ5="",0,VLOOKUP(AQ5,Bausteine!$A$2:$AY$76,50,FALSE)),IF(C5="",0,VLOOKUP(C5,Bausteine!$A$2:$AY$76,51,FALSE)))
